Workbook

Sheet 26-03-15
A1: SODECOTON
H2: TABLEAU DE SAISI
A3: PLUVIOMETRIE JOURNALIERE ET PAR PENTADE | H3: STATION | I3: RELEVES
H4: MAROUA | I4: 0
B5: JOURNEE DU : | D5: =I15 -> 42089 | H5: KAELE | I5: 0
H6: TCHATIBALI | I6: 0
A7: STATION | B7: RELEVES | D7: STATION | E7: RELEVES | H7: GUIDER | I7: 0
B8: JOURNALIER | C8: CUMUL | E8: JOURNALIER | F8: CUMUL | H8: GAROUA | I8: 0
A9: MAROUA | B9: =I4 -> 0 | C9: =B9 -> 0 | D9: NGONG | E9: =I9 -> 0 | F9: =E9 -> 0 | H9: NGONG | I9: 0
A10: KAELE | B10: =I5 -> 0 | C10: =B10 -> 0 | D10: POLI | E10: =I10 -> 0 | F10: =E10 -> 0 | H10: POLI | I10: 0
A11: TCHATIBALI | B11: =I6 -> 0 | C11: =B11 -> 0 | D11: MAYO-GALKE | E11: =I11 -> 0 | F11: =E11 -> 0 | H11: MAYO-GALKE | I11: 0
A12: GUIDER | B12: =I7 -> 0 | C12: =B12 -> 0 | D12: TOUBOURO | E12: =I12 -> 0 | F12: =E12 -> 0 | H12: TOUBOURO | I12: 0
A13: GAROUA | B13: =I8 -> 0 | C13: =B13 -> 0 | D13: HOME | E13: =I13 -> 0 | F13: =E13 -> 0 | H13: HOME | I13: 0
A15: TOTAL JOURNALIER = | C15: =SUM(B9:B13)+SUM(E9:E13) -> 0 | D15: CUMUL GENERAL = | F15: =SUM(C9:C13)+SUM(F9:F13) -> 0 | H15: JOURNEE | I15: 42089
H16: TRANSMISSION | I16: =I15+1 -> 42090
A20: Transmis le : | B20: =I16 -> 42090

Sheet 27-03-15
A1: SODECOTON
H2: TABLEAU DE SAISI
A3: PLUVIOMETRIE JOURNALIERE ET PAR PENTADE | H3: STATION | I3: RELEVES
H4: MAROUA | I4: 0
B5: JOURNEE DU : | D5: =I15 -> 42090 | H5: KAELE | I5: 0
H6: TCHATIBALI | I6: 0
A7: STATION | B7: RELEVES | D7: STATION | E7: RELEVES | H7: GUIDER | I7: 0
B8: JOURNALIER | C8: CUMUL | E8: JOURNALIER | F8: CUMUL | H8: GAROUA | I8: 0
A9: MAROUA | B9: =I4 -> 0 | C9: ='26-03-15'!C9+B9 -> 0 | D9: NGONG | E9: =I9 -> 0 | F9: ='26-03-15'!F9+E9 -> 0 | H9: NGONG | I9: 0
A10: KAELE | B10: =I5 -> 0 | C10: ='26-03-15'!C10+B10 -> 0 | D10: POLI | E10: =I10 -> 0 | F10: ='26-03-15'!F10+E10 -> 0 | H10: POLI | I10: 0
A11: TCHATIBALI | B11: =I6 -> 0 | C11: ='26-03-15'!C11+B11 -> 0 | D11: MAYO-GALKE | E11: =I11 -> 0 | F11: ='26-03-15'!F11+E11 -> 0 | H11: MAYO-GALKE | I11: 0
A12: GUIDER | B12: =I7 -> 0 | C12: ='26-03-15'!C12+B12 -> 0 | D12: TOUBOURO | E12: =I12 -> 0 | F12: ='26-03-15'!F12+E12 -> 0 | H12: TOUBOURO | I12: 0
A13: GAROUA | B13: =I8 -> 0 | C13: ='26-03-15'!C13+B13 -> 0 | D13: HOME | E13: =I13 -> 0 | F13: ='26-03-15'!F13+E13 -> 0 | H13: HOME | I13: 0
A15: TOTAL JOURNALIER = | C15: =SUM(B9:B13)+SUM(E9:E13) -> 0 | D15: CUMUL GENERAL = | F15: =SUM(C9:C13)+SUM(F9:F13) -> 0 | H15: JOURNEE | I15: 42090
H16: TRANSMISSION | I16: =I15+1 -> 42091
A20: Transmis le : | B20: =I16 -> 42091

Sheet 28-03-15
A1: SODECOTON
H2: TABLEAU DE SAISI
A3: PLUVIOMETRIE JOURNALIERE ET PAR PENTADE | H3: STATION | I3: RELEVES
H4: MAROUA | I4: 0
B5: JOURNEE DU : | D5: =I15 -> 42091 | H5: KAELE | I5: 0
H6: TCHATIBALI | I6: 0
A7: STATION | B7: RELEVES | D7: STATION | E7: RELEVES | H7: GUIDER | I7: 0
B8: JOURNALIER | C8: CUMUL | E8: JOURNALIER | F8: CUMUL | H8: GAROUA | I8: 0
A9: MAROUA | B9: =I4 -> 0 | C9: ='27-03-15'!C9+B9 -> 0 | D9: NGONG | E9: =I9 -> 0 | F9: ='27-03-15'!F9+E9 -> 0 | H9: NGONG | I9: 0
A10: KAELE | B10: =I5 -> 0 | C10: ='27-03-15'!C10+B10 -> 0 | D10: POLI | E10: =I10 -> 0 | F10: ='27-03-15'!F10+E10 -> 0 | H10: POLI | I10: 0
A11: TCHATIBALI | B11: =I6 -> 0 | C11: ='27-03-15'!C11+B11 -> 0 | D11: MAYO-GALKE | E11: =I11 -> 0 | F11: ='27-03-15'!F11+E11 -> 0 | H11: MAYO-GALKE | I11: 0
A12: GUIDER | B12: =I7 -> 0 | C12: ='27-03-15'!C12+B12 -> 0 | D12: TOUBOURO | E12: =I12 -> 0 | F12: ='27-03-15'!F12+E12 -> 0 | H12: TOUBOURO | I12: 0
A13: GAROUA | B13: =I8 -> 0 | C13: ='27-03-15'!C13+B13 -> 0 | D13: HOME | E13: =I13 -> 0 | F13: ='27-03-15'!F13+E13 -> 0 | H13: HOME | I13: 0
A15: TOTAL JOURNALIER = | C15: =SUM(B9:B13)+SUM(E9:E13) -> 0 | D15: CUMUL GENERAL = | F15: =SUM(C9:C13)+SUM(F9:F13) -> 0 | H15: JOURNEE | I15: 42091
H16: TRANSMISSION | I16: =I15+1 -> 42092
A20: Transmis le : | B20: =I16 -> 42092

Sheet 29-03-15
A1: SODECOTON
H2: TABLEAU DE SAISI
A3: PLUVIOMETRIE JOURNALIERE ET PAR PENTADE | H3: STATION | I3: RELEVES
H4: MAROUA | I4: 0
B5: JOURNEE DU : | D5: =I15 -> 42092 | H5: KAELE | I5: 0
H6: TCHATIBALI | I6: 0
A7: STATION | B7: RELEVES | D7: STATION | E7: RELEVES | H7: GUIDER | I7: 0
B8: JOURNALIER | C8: CUMUL | E8: JOURNALIER | F8: CUMUL | H8: GAROUA | I8: 0
A9: MAROUA | B9: =I4 -> 0 | C9: ='28-03-15'!C9+B9 -> 0 | D9: NGONG | E9: =I9 -> 0 | F9: ='28-03-15'!F9+E9 -> 0 | H9: NGONG | I9: 0
A10: KAELE | B10: =I5 -> 0 | C10: ='28-03-15'!C10+B10 -> 0 | D10: POLI | E10: =I10 -> 0 | F10: ='28-03-15'!F10+E10 -> 0 | H10: POLI | I10: 0
A11: TCHATIBALI | B11: =I6 -> 0 | C11: ='28-03-15'!C11+B11 -> 0 | D11: MAYO-GALKE | E11: =I11 -> 0 | F11: ='28-03-15'!F11+E11 -> 0 | H11: MAYO-GALKE | I11: 0
A12: GUIDER | B12: =I7 -> 0 | C12: ='28-03-15'!C12+B12 -> 0 | D12: TOUBOURO | E12: =I12 -> 0 | F12: ='28-03-15'!F12+E12 -> 0 | H12: TOUBOURO | I12: 0
A13: GAROUA | B13: =I8 -> 0 | C13: ='28-03-15'!C13+B13 -> 0 | D13: HOME | E13: =I13 -> 0 | F13: ='28-03-15'!F13+E13 -> 0 | H13: HOME | I13: 0
A15: TOTAL JOURNALIER = | C15: =SUM(B9:B13)+SUM(E9:E13) -> 0 | D15: CUMUL GENERAL = | F15: =SUM(C9:C13)+SUM(F9:F13) -> 0 | H15: JOURNEE | I15: 42092
H16: TRANSMISSION | I16: =I15+1 -> 42093
A20: Transmis le : | B20: =I16 -> 42093

Sheet 30-03-15
A1: SODECOTON
H2: TABLEAU DE SAISI
A3: PLUVIOMETRIE JOURNALIERE ET PAR PENTADE | H3: STATION | I3: RELEVES
H4: MAROUA | I4: 0
B5: JOURNEE DU : | D5: =I15 -> 42093 | H5: KAELE | I5: 0
H6: TCHATIBALI | I6: 0
A7: STATION | B7: RELEVES | D7: STATION | E7: RELEVES | H7: GUIDER | I7: 0
B8: JOURNALIER | C8: CUMUL | E8: JOURNALIER | F8: CUMUL | H8: GAROUA | I8: 0
A9: MAROUA | B9: =I4 -> 0 | C9: ='29-03-15'!C9+B9 -> 0 | D9: NGONG | E9: =I9 -> 0 | F9: ='29-03-15'!F9+E9 -> 0 | H9: NGONG | I9: 0
A10: KAELE | B10: =I5 -> 0 | C10: ='29-03-15'!C10+B10 -> 0 | D10: POLI | E10: =I10 -> 0 | F10: ='29-03-15'!F10+E10 -> 0 | H10: POLI | I10: 0
A11: TCHATIBALI | B11: =I6 -> 0 | C11: ='29-03-15'!C11+B11 -> 0 | D11: MAYO-GALKE | E11: =I11 -> 0 | F11: ='29-03-15'!F11+E11 -> 0 | H11: MAYO-GALKE | I11: 0
A12: GUIDER | B12: =I7 -> 0 | C12: ='29-03-15'!C12+B12 -> 0 | D12: TOUBOURO | E12: =I12 -> 0 | F12: ='29-03-15'!F12+E12 -> 0 | H12: TOUBOURO | I12: 0
A13: GAROUA | B13: =I8 -> 0 | C13: ='29-03-15'!C13+B13 -> 0 | D13: HOME | E13: =I13 -> 0 | F13: ='29-03-15'!F13+E13 -> 0 | H13: HOME | I13: 0
A15: TOTAL JOURNALIER = | C15: =SUM(B9:B13)+SUM(E9:E13) -> 0 | D15: CUMUL GENERAL = | F15: =SUM(C9:C13)+SUM(F9:F13) -> 0 | H15: JOURNEE | I15: 42093
H16: TRANSMISSION | I16: =I15+1 -> 42094
A20: Transmis le : | B20: =I16 -> 42094

Sheet 31-03-15
A1: SODECOTON
H2: TABLEAU DE SAISI
A3: PLUVIOMETRIE JOURNALIERE ET PAR PENTADE | H3: STATION | I3: RELEVES
H4: MAROUA | I4: 0
B5: JOURNEE DU : | D5: =I15 -> 42094 | H5: KAELE | I5: 0
H6: TCHATIBALI | I6: 0
A7: STATION | B7: RELEVES | D7: STATION | E7: RELEVES | H7: GUIDER | I7: 0
B8: JOURNALIER | C8: CUMUL | E8: JOURNALIER | F8: CUMUL | H8: GAROUA | I8: 0
A9: MAROUA | B9: =I4 -> 0 | C9: ='30-03-15'!C9+B9 -> 0 | D9: NGONG | E9: =I9 -> 0 | F9: ='30-03-15'!F9+E9 -> 0 | H9: NGONG | I9: 0
A10: KAELE | B10: =I5 -> 0 | C10: ='30-03-15'!C10+B10 -> 0 | D10: POLI | E10: =I10 -> 0 | F10: ='30-03-15'!F10+E10 -> 0 | H10: POLI | I10: 0
A11: TCHATIBALI | B11: =I6 -> 0 | C11: ='30-03-15'!C11+B11 -> 0 | D11: MAYO-GALKE | E11: =I11 -> 0 | F11: ='30-03-15'!F11+E11 -> 0 | H11: MAYO-GALKE | I11: 0
A12: GUIDER | B12: =I7 -> 0 | C12: ='30-03-15'!C12+B12 -> 0 | D12: TOUBOURO | E12: =I12 -> 0 | F12: ='30-03-15'!F12+E12 -> 0 | H12: TOUBOURO | I12: 0
A13: GAROUA | B13: =I8 -> 0 | C13: ='30-03-15'!C13+B13 -> 0 | D13: HOME | E13: =I13 -> 0 | F13: ='30-03-15'!F13+E13 -> 0 | H13: HOME | I13: 0
A15: TOTAL JOURNALIER = | C15: =SUM(B9:B13)+SUM(E9:E13) -> 0 | D15: CUMUL GENERAL = | F15: =SUM(C9:C13)+SUM(F9:F13) -> 0 | H15: JOURNEE | I15: 42094
H16: TRANSMISSION | I16: =I15+1 -> 42095
A20: Transmis le : | B20: =I16 -> 42095

Sheet 01-04-15
A1: SODECOTON
H2: TABLEAU DE SAISI
A3: PLUVIOMETRIE JOURNALIERE ET PAR PENTADE | H3: STATION | I3: RELEVES
H4: MAROUA | I4: 0
B5: JOURNEE DU : | D5: =I15 -> 42095 | H5: KAELE | I5: 0
H6: TCHATIBALI | I6: 0
A7: STATION | B7: RELEVES | D7: STATION | E7: RELEVES | H7: GUIDER | I7: 0
B8: JOURNALIER | C8: CUMUL | E8: JOURNALIER | F8: CUMUL | H8: GAROUA | I8: 0
A9: MAROUA | B9: =I4 -> 0 | C9: ='31-03-15'!C9+B9 -> 0 | D9: NGONG | E9: =I9 -> 0 | F9: ='31-03-15'!F9+E9 -> 0 | H9: NGONG | I9: 0
A10: KAELE | B10: =I5 -> 0 | C10: ='31-03-15'!C10+B10 -> 0 | D10: POLI | E10: =I10 -> 0 | F10: ='31-03-15'!F10+E10 -> 0 | H10: POLI | I10: 0
A11: TCHATIBALI | B11: =I6 -> 0 | C11: ='31-03-15'!C11+B11 -> 0 | D11: MAYO-GALKE | E11: =I11 -> 0 | F11: ='31-03-15'!F11+E11 -> 0 | H11: MAYO-GALKE | I11: 0
A12: GUIDER | B12: =I7 -> 0 | C12: ='31-03-15'!C12+B12 -> 0 | D12: TOUBOURO | E12: =I12 -> 0 | F12: ='31-03-15'!F12+E12 -> 0 | H12: TOUBOURO | I12: 0
A13: GAROUA | B13: =I8 -> 0 | C13: ='31-03-15'!C13+B13 -> 0 | D13: HOME | E13: =I13 -> 0 | F13: ='31-03-15'!F13+E13 -> 0 | H13: HOME | I13: 0
A15: TOTAL JOURNALIER = | C15: =SUM(B9:B13)+SUM(E9:E13) -> 0 | D15: CUMUL GENERAL = | F15: =SUM(C9:C13)+SUM(F9:F13) -> 0 | H15: JOURNEE | I15: 42095
H16: TRANSMISSION | I16: =I15+1 -> 42096
A20: Transmis le : | B20: =I16 -> 42096

Sheet 02-04-15
A1: SODECOTON
H2: TABLEAU DE SAISI
A3: PLUVIOMETRIE JOURNALIERE ET PAR PENTADE | H3: STATION | I3: RELEVES
H4: MAROUA | I4: 0
B5: JOURNEE DU : | D5: =I15 -> 42096 | H5: KAELE | I5: 0
H6: TCHATIBALI | I6: 0
A7: STATION | B7: RELEVES | D7: STATION | E7: RELEVES | H7: GUIDER | I7: 0
B8: JOURNALIER | C8: CUMUL | E8: JOURNALIER | F8: CUMUL | H8: GAROUA | I8: 0
A9: MAROUA | B9: =I4 -> 0 | C9: ='01-04-15'!C9+B9 -> 0 | D9: NGONG | E9: =I9 -> 0 | F9: ='01-04-15'!F9+E9 -> 0 | H9: NGONG | I9: 0
A10: KAELE | B10: =I5 -> 0 | C10: ='01-04-15'!C10+B10 -> 0 | D10: POLI | E10: =I10 -> 0 | F10: ='01-04-15'!F10+E10 -> 0 | H10: POLI | I10: 0
A11: TCHATIBALI | B11: =I6 -> 0 | C11: ='01-04-15'!C11+B11 -> 0 | D11: MAYO-GALKE | E11: =I11 -> 0 | F11: ='01-04-15'!F11+E11 -> 0 | H11: MAYO-GALKE | I11: 0
A12: GUIDER | B12: =I7 -> 0 | C12: ='01-04-15'!C12+B12 -> 0 | D12: TOUBOURO | E12: =I12 -> 0 | F12: ='01-04-15'!F12+E12 -> 0 | H12: TOUBOURO | I12: 0
A13: GAROUA | B13: =I8 -> 0 | C13: ='01-04-15'!C13+B13 -> 0 | D13: HOME | E13: =I13 -> 0 | F13: ='01-04-15'!F13+E13 -> 0 | H13: HOME | I13: 0
A15: TOTAL JOURNALIER = | C15: =SUM(B9:B13)+SUM(E9:E13) -> 0 | D15: CUMUL GENERAL = | F15: =SUM(C9:C13)+SUM(F9:F13) -> 0 | H15: JOURNEE | I15: 42096
H16: TRANSMISSION | I16: =I15+1 -> 42097
A20: Transmis le : | B20: =I16 -> 42097

Sheet 03-04-15
A1: SODECOTON
H2: TABLEAU DE SAISI
A3: PLUVIOMETRIE JOURNALIERE ET PAR PENTADE | H3: STATION | I3: RELEVES
H4: MAROUA | I4: 0
B5: JOURNEE DU : | D5: =I15 -> 42097 | H5: KAELE | I5: 0
H6: TCHATIBALI | I6: 0
A7: STATION | B7: RELEVES | D7: STATION | E7: RELEVES | H7: GUIDER | I7: 0
B8: JOURNALIER | C8: CUMUL | E8: JOURNALIER | F8: CUMUL | H8: GAROUA | I8: 0
A9: MAROUA | B9: =I4 -> 0 | C9: ='02-04-15'!C9+B9 -> 0 | D9: NGONG | E9: =I9 -> 0 | F9: ='02-04-15'!F9+E9 -> 0 | H9: NGONG | I9: 0
A10: KAELE | B10: =I5 -> 0 | C10: ='02-04-15'!C10+B10 -> 0 | D10: POLI | E10: =I10 -> 0 | F10: ='02-04-15'!F10+E10 -> 0 | H10: POLI | I10: 0
A11: TCHATIBALI | B11: =I6 -> 0 | C11: ='02-04-15'!C11+B11 -> 0 | D11: MAYO-GALKE | E11: =I11 -> 0 | F11: ='02-04-15'!F11+E11 -> 0 | H11: MAYO-GALKE | I11: 0
A12: GUIDER | B12: =I7 -> 0 | C12: ='02-04-15'!C12+B12 -> 0 | D12: TOUBOURO | E12: =I12 -> 0 | F12: ='02-04-15'!F12+E12 -> 0 | H12: TOUBOURO | I12: 0
A13: GAROUA | B13: =I8 -> 0 | C13: ='02-04-15'!C13+B13 -> 0 | D13: HOME | E13: =I13 -> 0 | F13: ='02-04-15'!F13+E13 -> 0 | H13: HOME | I13: 0
A15: TOTAL JOURNALIER = | C15: =SUM(B9:B13)+SUM(E9:E13) -> 0 | D15: CUMUL GENERAL = | F15: =SUM(C9:C13)+SUM(F9:F13) -> 0 | H15: JOURNEE | I15: 42097
H16: TRANSMISSION | I16: =I15+1 -> 42098
A20: Transmis le : | B20: =I16 -> 42098

Sheet 04-04-15
A1: SODECOTON
H2: TABLEAU DE SAISI
A3: PLUVIOMETRIE JOURNALIERE ET PAR PENTADE | H3: STATION | I3: RELEVES
H4: MAROUA | I4: 0
B5: JOURNEE DU : | D5: =I15 -> 42098 | H5: KAELE | I5: 0
H6: TCHATIBALI | I6: 0
A7: STATION | B7: RELEVES | D7: STATION | E7: RELEVES | H7: GUIDER | I7: 0
B8: JOURNALIER | C8: CUMUL | E8: JOURNALIER | F8: CUMUL | H8: GAROUA | I8: 0
A9: MAROUA | B9: =I4 -> 0 | C9: ='03-04-15'!C9+B9 -> 0 | D9: NGONG | E9: =I9 -> 0 | F9: ='03-04-15'!F9+E9 -> 0 | H9: NGONG | I9: 0
A10: KAELE | B10: =I5 -> 0 | C10: ='03-04-15'!C10+B10 -> 0 | D10: POLI | E10: =I10 -> 0 | F10: ='03-04-15'!F10+E10 -> 0 | H10: POLI | I10: 0
A11: TCHATIBALI | B11: =I6 -> 0 | C11: ='03-04-15'!C11+B11 -> 0 | D11: MAYO-GALKE | E11: =I11 -> 0 | F11: ='03-04-15'!F11+E11 -> 0 | H11: MAYO-GALKE | I11: 0
A12: GUIDER | B12: =I7 -> 0 | C12: ='03-04-15'!C12+B12 -> 0 | D12: TOUBOURO | E12: =I12 -> 0 | F12: ='03-04-15'!F12+E12 -> 0 | H12: TOUBOURO | I12: 0
A13: GAROUA | B13: =I8 -> 0 | C13: ='03-04-15'!C13+B13 -> 0 | D13: HOME | E13: =I13 -> 0 | F13: ='03-04-15'!F13+E13 -> 0 | H13: HOME | I13: 0
A15: TOTAL JOURNALIER = | C15: =SUM(B9:B13)+SUM(E9:E13) -> 0 | D15: CUMUL GENERAL = | F15: =SUM(C9:C13)+SUM(F9:F13) -> 0 | H15: JOURNEE | I15: 42098
H16: TRANSMISSION | I16: =I15+1 -> 42099
A20: Transmis le : | B20: =I16 -> 42099

Sheet 05-04-15
A1: SODECOTON
H2: TABLEAU DE SAISI
A3: PLUVIOMETRIE JOURNALIERE ET PAR PENTADE | H3: STATION | I3: RELEVES
H4: MAROUA | I4: 0
B5: JOURNEE DU : | D5: =I15 -> 42099 | H5: KAELE | I5: 0
H6: TCHATIBALI | I6: 0
A7: STATION | B7: RELEVES | D7: STATION | E7: RELEVES | H7: GUIDER | I7: 0
B8: JOURNALIER | C8: CUMUL | E8: JOURNALIER | F8: CUMUL | H8: GAROUA | I8: 0
A9: MAROUA | B9: =I4 -> 0 | C9: ='04-04-15'!C9+B9 -> 0 | D9: NGONG | E9: =I9 -> 0 | F9: ='04-04-15'!F9+E9 -> 0 | H9: NGONG | I9: 0
A10: KAELE | B10: =I5 -> 0 | C10: ='04-04-15'!C10+B10 -> 0 | D10: POLI | E10: =I10 -> 0 | F10: ='04-04-15'!F10+E10 -> 0 | H10: POLI | I10: 0
A11: TCHATIBALI | B11: =I6 -> 0 | C11: ='04-04-15'!C11+B11 -> 0 | D11: MAYO-GALKE | E11: =I11 -> 0 | F11: ='04-04-15'!F11+E11 -> 0 | H11: MAYO-GALKE | I11: 0
A12: GUIDER | B12: =I7 -> 0 | C12: ='04-04-15'!C12+B12 -> 0 | D12: TOUBOURO | E12: =I12 -> 0 | F12: ='04-04-15'!F12+E12 -> 0 | H12: TOUBOURO | I12: 0
A13: GAROUA | B13: =I8 -> 0 | C13: ='04-04-15'!C13+B13 -> 0 | D13: HOME | E13: =I13 -> 0 | F13: ='04-04-15'!F13+E13 -> 0 | H13: HOME | I13: 0
A15: TOTAL JOURNALIER = | C15: =SUM(B9:B13)+SUM(E9:E13) -> 0 | D15: CUMUL GENERAL = | F15: =SUM(C9:C13)+SUM(F9:F13) -> 0 | H15: JOURNEE | I15: 42099
H16: TRANSMISSION | I16: =I15+1 -> 42100
A20: Transmis le : | B20: =I16 -> 42100

Sheet 06-04-15
A1: SODECOTON
H2: TABLEAU DE SAISI
A3: PLUVIOMETRIE JOURNALIERE ET PAR PENTADE | H3: STATION | I3: RELEVES
H4: MAROUA | I4: 0
B5: JOURNEE DU : | D5: =I15 -> 42100 | H5: KAELE | I5: 0
H6: TCHATIBALI | I6: 0
A7: STATION | B7: RELEVES | D7: STATION | E7: RELEVES | H7: GUIDER | I7: 0
B8: JOURNALIER | C8: CUMUL | E8: JOURNALIER | F8: CUMUL | H8: GAROUA | I8: 0
A9: MAROUA | B9: =I4 -> 0 | C9: ='05-04-15'!C9+B9 -> 0 | D9: NGONG | E9: =I9 -> 0 | F9: ='05-04-15'!F9+E9 -> 0 | H9: NGONG | I9: 0
A10: KAELE | B10: =I5 -> 0 | C10: ='05-04-15'!C10+B10 -> 0 | D10: POLI | E10: =I10 -> 0 | F10: ='05-04-15'!F10+E10 -> 0 | H10: POLI | I10: 0
A11: TCHATIBALI | B11: =I6 -> 0 | C11: ='05-04-15'!C11+B11 -> 0 | D11: MAYO-GALKE | E11: =I11 -> 0 | F11: ='05-04-15'!F11+E11 -> 0 | H11: MAYO-GALKE | I11: 0
A12: GUIDER | B12: =I7 -> 0 | C12: ='05-04-15'!C12+B12 -> 0 | D12: TOUBOURO | E12: =I12 -> 0 | F12: ='05-04-15'!F12+E12 -> 0 | H12: TOUBOURO | I12: 0
A13: GAROUA | B13: =I8 -> 0 | C13: ='05-04-15'!C13+B13 -> 0 | D13: HOME | E13: =I13 -> 0 | F13: ='05-04-15'!F13+E13 -> 0 | H13: HOME | I13: 0
A15: TOTAL JOURNALIER = | C15: =SUM(B9:B13)+SUM(E9:E13) -> 0 | D15: CUMUL GENERAL = | F15: =SUM(C9:C13)+SUM(F9:F13) -> 0 | H15: JOURNEE | I15: 42100
H16: TRANSMISSION | I16: =I15+1 -> 42101
A20: Transmis le : | B20: =I16 -> 42101

Sheet 07-04-15
A1: SODECOTON
H2: TABLEAU DE SAISI
A3: PLUVIOMETRIE JOURNALIERE ET PAR PENTADE | H3: STATION | I3: RELEVES
H4: MAROUA | I4: 0
B5: JOURNEE DU : | D5: =I15 -> 42101 | H5: KAELE | I5: 0
H6: TCHATIBALI | I6: 0
A7: STATION | B7: RELEVES | D7: STATION | E7: RELEVES | H7: GUIDER | I7: 0
B8: JOURNALIER | C8: CUMUL | E8: JOURNALIER | F8: CUMUL | H8: GAROUA | I8: 0
A9: MAROUA | B9: =I4 -> 0 | C9: ='06-04-15'!C9+B9 -> 0 | D9: NGONG | E9: =I9 -> 0 | F9: ='06-04-15'!F9+E9 -> 0 | H9: NGONG | I9: 0
A10: KAELE | B10: =I5 -> 0 | C10: ='06-04-15'!C10+B10 -> 0 | D10: POLI | E10: =I10 -> 0 | F10: ='06-04-15'!F10+E10 -> 0 | H10: POLI | I10: 0
A11: TCHATIBALI | B11: =I6 -> 0 | C11: ='06-04-15'!C11+B11 -> 0 | D11: MAYO-GALKE | E11: =I11 -> 0 | F11: ='06-04-15'!F11+E11 -> 0 | H11: MAYO-GALKE | I11: 0
A12: GUIDER | B12: =I7 -> 0 | C12: ='06-04-15'!C12+B12 -> 0 | D12: TOUBOURO | E12: =I12 -> 0 | F12: ='06-04-15'!F12+E12 -> 0 | H12: TOUBOURO | I12: 0
A13: GAROUA | B13: =I8 -> 0 | C13: ='06-04-15'!C13+B13 -> 0 | D13: HOME | E13: =I13 -> 0 | F13: ='06-04-15'!F13+E13 -> 0 | H13: HOME | I13: 0
A15: TOTAL JOURNALIER = | C15: =SUM(B9:B13)+SUM(E9:E13) -> 0 | D15: CUMUL GENERAL = | F15: =SUM(C9:C13)+SUM(F9:F13) -> 0 | H15: JOURNEE | I15: 42101
H16: TRANSMISSION | I16: =I15+1 -> 42102
A20: Transmis le : | B20: =I16 -> 42102

Sheet 08-04-15
A1: SODECOTON
H2: TABLEAU DE SAISI
A3: PLUVIOMETRIE JOURNALIERE ET PAR PENTADE | H3: STATION | I3: RELEVES
H4: MAROUA | I4: 0
B5: JOURNEE DU : | D5: =I15 -> 42102 | H5: KAELE | I5: 0
H6: TCHATIBALI | I6: 0
A7: STATION | B7: RELEVES | D7: STATION | E7: RELEVES | H7: GUIDER | I7: 0
B8: JOURNALIER | C8: CUMUL | E8: JOURNALIER | F8: CUMUL | H8: GAROUA | I8: 0
A9: MAROUA | B9: =I4 -> 0 | C9: ='07-04-15'!C9+B9 -> 0 | D9: NGONG | E9: =I9 -> 0 | F9: ='07-04-15'!F9+E9 -> 0 | H9: NGONG | I9: 0
A10: KAELE | B10: =I5 -> 0 | C10: ='07-04-15'!C10+B10 -> 0 | D10: POLI | E10: =I10 -> 0 | F10: ='07-04-15'!F10+E10 -> 0 | H10: POLI | I10: 0
A11: TCHATIBALI | B11: =I6 -> 0 | C11: ='07-04-15'!C11+B11 -> 0 | D11: MAYO-GALKE | E11: =I11 -> 0 | F11: ='07-04-15'!F11+E11 -> 0 | H11: MAYO-GALKE | I11: 0
A12: GUIDER | B12: =I7 -> 0 | C12: ='07-04-15'!C12+B12 -> 0 | D12: TOUBOURO | E12: =I12 -> 0 | F12: ='07-04-15'!F12+E12 -> 0 | H12: TOUBOURO | I12: 0
A13: GAROUA | B13: =I8 -> 0 | C13: ='07-04-15'!C13+B13 -> 0 | D13: HOME | E13: =I13 -> 0 | F13: ='07-04-15'!F13+E13 -> 0 | H13: HOME | I13: 0
A15: TOTAL JOURNALIER = | C15: =SUM(B9:B13)+SUM(E9:E13) -> 0 | D15: CUMUL GENERAL = | F15: =SUM(C9:C13)+SUM(F9:F13) -> 0 | H15: JOURNEE | I15: 42102
H16: TRANSMISSION | I16: =I15+1 -> 42103
A20: Transmis le : | B20: =I16 -> 42103

Sheet 09-04-15
A1: SODECOTON
H2: TABLEAU DE SAISI
A3: PLUVIOMETRIE JOURNALIERE ET PAR PENTADE | H3: STATION | I3: RELEVES
H4: MAROUA | I4: 0
B5: JOURNEE DU : | D5: =I15 -> 42103 | H5: KAELE | I5: 0
H6: TCHATIBALI | I6: 0
A7: STATION | B7: RELEVES | D7: STATION | E7: RELEVES | H7: GUIDER | I7: 0
B8: JOURNALIER | C8: CUMUL | E8: JOURNALIER | F8: CUMUL | H8: GAROUA | I8: 0
A9: MAROUA | B9: =I4 -> 0 | C9: ='08-04-15'!C9+B9 -> 0 | D9: NGONG | E9: =I9 -> 0 | F9: ='08-04-15'!F9+E9 -> 0 | H9: NGONG | I9: 0
A10: KAELE | B10: =I5 -> 0 | C10: ='08-04-15'!C10+B10 -> 0 | D10: POLI | E10: =I10 -> 0 | F10: ='08-04-15'!F10+E10 -> 0 | H10: POLI | I10: 0
A11: TCHATIBALI | B11: =I6 -> 0 | C11: ='08-04-15'!C11+B11 -> 0 | D11: MAYO-GALKE | E11: =I11 -> 0 | F11: ='08-04-15'!F11+E11 -> 0 | H11: MAYO-GALKE | I11: 0
A12: GUIDER | B12: =I7 -> 0 | C12: ='08-04-15'!C12+B12 -> 0 | D12: TOUBOURO | E12: =I12 -> 0 | F12: ='08-04-15'!F12+E12 -> 0 | H12: TOUBOURO | I12: 0
A13: GAROUA | B13: =I8 -> 0 | C13: ='08-04-15'!C13+B13 -> 0 | D13: HOME | E13: =I13 -> 0 | F13: ='08-04-15'!F13+E13 -> 0 | H13: HOME | I13: 0
A15: TOTAL JOURNALIER = | C15: =SUM(B9:B13)+SUM(E9:E13) -> 0 | D15: CUMUL GENERAL = | F15: =SUM(C9:C13)+SUM(F9:F13) -> 0 | H15: JOURNEE | I15: 42103
H16: TRANSMISSION | I16: =I15+1 -> 42104
A20: Transmis le : | B20: =I16 -> 42104

Sheet 10-04-15
A1: SODECOTON
H2: TABLEAU DE SAISI
A3: PLUVIOMETRIE JOURNALIERE ET PAR PENTADE | H3: STATION | I3: RELEVES
H4: MAROUA | I4: 0
B5: JOURNEE DU : | D5: =I15 -> 42104 | H5: KAELE | I5: 0
H6: TCHATIBALI | I6: 0
A7: STATION | B7: RELEVES | D7: STATION | E7: RELEVES | H7: GUIDER | I7: 0
B8: JOURNALIER | C8: CUMUL | E8: JOURNALIER | F8: CUMUL | H8: GAROUA | I8: 0
A9: MAROUA | B9: =I4 -> 0 | C9: ='09-04-15'!C9+B9 -> 0 | D9: NGONG | E9: =I9 -> 0 | F9: ='09-04-15'!F9+E9 -> 0 | H9: NGONG | I9: 0
A10: KAELE | B10: =I5 -> 0 | C10: ='09-04-15'!C10+B10 -> 0 | D10: POLI | E10: =I10 -> 0 | F10: ='09-04-15'!F10+E10 -> 0 | H10: POLI | I10: 0
A11: TCHATIBALI | B11: =I6 -> 0 | C11: ='09-04-15'!C11+B11 -> 0 | D11: MAYO-GALKE | E11: =I11 -> 0 | F11: ='09-04-15'!F11+E11 -> 0 | H11: MAYO-GALKE | I11: 0
A12: GUIDER | B12: =I7 -> 0 | C12: ='09-04-15'!C12+B12 -> 0 | D12: TOUBOURO | E12: =I12 -> 0 | F12: ='09-04-15'!F12+E12 -> 0 | H12: TOUBOURO | I12: 0
A13: GAROUA | B13: =I8 -> 0 | C13: ='09-04-15'!C13+B13 -> 0 | D13: HOME | E13: =I13 -> 0 | F13: ='09-04-15'!F13+E13 -> 0 | H13: HOME | I13: 0
A15: TOTAL JOURNALIER = | C15: =SUM(B9:B13)+SUM(E9:E13) -> 0 | D15: CUMUL GENERAL = | F15: =SUM(C9:C13)+SUM(F9:F13) -> 0 | H15: JOURNEE | I15: 42104
H16: TRANSMISSION | I16: =I15+1 -> 42105
A20: Transmis le : | B20: =I16 -> 42105

Sheet 11-04-15
A1: SODECOTON
H2: TABLEAU DE SAISI
A3: PLUVIOMETRIE JOURNALIERE ET PAR PENTADE | H3: STATION | I3: RELEVES
H4: MAROUA | I4: 0
B5: JOURNEE DU : | D5: =I15 -> 42105 | H5: KAELE | I5: 0
H6: TCHATIBALI | I6: 0
A7: STATION | B7: RELEVES | D7: STATION | E7: RELEVES | H7: GUIDER | I7: 0
B8: JOURNALIER | C8: CUMUL | E8: JOURNALIER | F8: CUMUL | H8: GAROUA | I8: 0
A9: MAROUA | B9: =I4 -> 0 | C9: ='10-04-15'!C9+B9 -> 0 | D9: NGONG | E9: =I9 -> 0 | F9: ='10-04-15'!F9+E9 -> 0 | H9: NGONG | I9: 0
A10: KAELE | B10: =I5 -> 0 | C10: ='10-04-15'!C10+B10 -> 0 | D10: POLI | E10: =I10 -> 0 | F10: ='10-04-15'!F10+E10 -> 0 | H10: POLI | I10: 0
A11: TCHATIBALI | B11: =I6 -> 0 | C11: ='10-04-15'!C11+B11 -> 0 | D11: MAYO-GALKE | E11: =I11 -> 0 | F11: ='10-04-15'!F11+E11 -> 0 | H11: MAYO-GALKE | I11: 0
A12: GUIDER | B12: =I7 -> 0 | C12: ='10-04-15'!C12+B12 -> 0 | D12: TOUBOURO | E12: =I12 -> 0 | F12: ='10-04-15'!F12+E12 -> 0 | H12: TOUBOURO | I12: 0
A13: GAROUA | B13: =I8 -> 0 | C13: ='10-04-15'!C13+B13 -> 0 | D13: HOME | E13: =I13 -> 0 | F13: ='10-04-15'!F13+E13 -> 0 | H13: HOME | I13: 0
A15: TOTAL JOURNALIER = | C15: =SUM(B9:B13)+SUM(E9:E13) -> 0 | D15: CUMUL GENERAL = | F15: =SUM(C9:C13)+SUM(F9:F13) -> 0 | H15: JOURNEE | I15: 42105
H16: TRANSMISSION | I16: =I15+1 -> 42106
A20: Transmis le : | B20: =I16 -> 42106

Sheet 12-04-15
A1: SODECOTON
H2: TABLEAU DE SAISI
A3: PLUVIOMETRIE JOURNALIERE ET PAR PENTADE | H3: STATION | I3: RELEVES
H4: MAROUA | I4: 0
B5: JOURNEE DU : | D5: =I15 -> 42106 | H5: KAELE | I5: 0
H6: TCHATIBALI | I6: 0
A7: STATION | B7: RELEVES | D7: STATION | E7: RELEVES | H7: GUIDER | I7: 0
B8: JOURNALIER | C8: CUMUL | E8: JOURNALIER | F8: CUMUL | H8: GAROUA | I8: 0
A9: MAROUA | B9: =I4 -> 0 | C9: ='11-04-15'!C9+B9 -> 0 | D9: NGONG | E9: =I9 -> 0 | F9: ='11-04-15'!F9+E9 -> 0 | H9: NGONG | I9: 0
A10: KAELE | B10: =I5 -> 0 | C10: ='11-04-15'!C10+B10 -> 0 | D10: POLI | E10: =I10 -> 0 | F10: ='11-04-15'!F10+E10 -> 0 | H10: POLI | I10: 0
A11: TCHATIBALI | B11: =I6 -> 0 | C11: ='11-04-15'!C11+B11 -> 0 | D11: MAYO-GALKE | E11: =I11 -> 0 | F11: ='11-04-15'!F11+E11 -> 0 | H11: MAYO-GALKE | I11: 0
A12: GUIDER | B12: =I7 -> 0 | C12: ='11-04-15'!C12+B12 -> 0 | D12: TOUBOURO | E12: =I12 -> 0 | F12: ='11-04-15'!F12+E12 -> 0 | H12: TOUBOURO | I12: 0
A13: GAROUA | B13: =I8 -> 0 | C13: ='11-04-15'!C13+B13 -> 0 | D13: HOME | E13: =I13 -> 0 | F13: ='11-04-15'!F13+E13 -> 0 | H13: HOME | I13: 0
A15: TOTAL JOURNALIER = | C15: =SUM(B9:B13)+SUM(E9:E13) -> 0 | D15: CUMUL GENERAL = | F15: =SUM(C9:C13)+SUM(F9:F13) -> 0 | H15: JOURNEE | I15: 42106
H16: TRANSMISSION | I16: =I15+1 -> 42107
A20: Transmis le : | B20: =I16 -> 42107

Sheet 13-04-15
A1: SODECOTON
H2: TABLEAU DE SAISI
A3: PLUVIOMETRIE JOURNALIERE ET PAR PENTADE | H3: STATION | I3: RELEVES
H4: MAROUA | I4: 0
B5: JOURNEE DU : | D5: =I15 -> 42107 | H5: KAELE | I5: 0
H6: TCHATIBALI | I6: 0
A7: STATION | B7: RELEVES | D7: STATION | E7: RELEVES | H7: GUIDER | I7: 0
B8: JOURNALIER | C8: CUMUL | E8: JOURNALIER | F8: CUMUL | H8: GAROUA | I8: 0
A9: MAROUA | B9: =I4 -> 0 | C9: ='12-04-15'!C9+B9 -> 0 | D9: NGONG | E9: =I9 -> 0 | F9: ='12-04-15'!F9+E9 -> 0 | H9: NGONG | I9: 0
A10: KAELE | B10: =I5 -> 0 | C10: ='12-04-15'!C10+B10 -> 0 | D10: POLI | E10: =I10 -> 0 | F10: ='12-04-15'!F10+E10 -> 0 | H10: POLI | I10: 0
A11: TCHATIBALI | B11: =I6 -> 0 | C11: ='12-04-15'!C11+B11 -> 0 | D11: MAYO-GALKE | E11: =I11 -> 0 | F11: ='12-04-15'!F11+E11 -> 0 | H11: MAYO-GALKE | I11: 0
A12: GUIDER | B12: =I7 -> 0 | C12: ='12-04-15'!C12+B12 -> 0 | D12: TOUBOURO | E12: =I12 -> 0 | F12: ='12-04-15'!F12+E12 -> 0 | H12: TOUBOURO | I12: 0
A13: GAROUA | B13: =I8 -> 0 | C13: ='12-04-15'!C13+B13 -> 0 | D13: HOME | E13: =I13 -> 0 | F13: ='12-04-15'!F13+E13 -> 0 | H13: HOME | I13: 0
A15: TOTAL JOURNALIER = | C15: =SUM(B9:B13)+SUM(E9:E13) -> 0 | D15: CUMUL GENERAL = | F15: =SUM(C9:C13)+SUM(F9:F13) -> 0 | H15: JOURNEE | I15: 42107
H16: TRANSMISSION | I16: =I15+1 -> 42108
A20: Transmis le : | B20: =I16 -> 42108

Sheet 14-04-15
A1: SODECOTON
H2: TABLEAU DE SAISI
A3: PLUVIOMETRIE JOURNALIERE ET PAR PENTADE | H3: STATION | I3: RELEVES
H4: MAROUA | I4: 0
B5: JOURNEE DU : | D5: =I15 -> 42108 | H5: KAELE | I5: 0
H6: TCHATIBALI | I6: 0
A7: STATION | B7: RELEVES | D7: STATION | E7: RELEVES | H7: GUIDER | I7: 0
B8: JOURNALIER | C8: CUMUL | E8: JOURNALIER | F8: CUMUL | H8: GAROUA | I8: 0
A9: MAROUA | B9: =I4 -> 0 | C9: ='13-04-15'!C9+B9 -> 0 | D9: NGONG | E9: =I9 -> 0 | F9: ='13-04-15'!F9+E9 -> 0 | H9: NGONG | I9: 0
A10: KAELE | B10: =I5 -> 0 | C10: ='13-04-15'!C10+B10 -> 0 | D10: POLI | E10: =I10 -> 0 | F10: ='13-04-15'!F10+E10 -> 0 | H10: POLI | I10: 0
A11: TCHATIBALI | B11: =I6 -> 0 | C11: ='13-04-15'!C11+B11 -> 0 | D11: MAYO-GALKE | E11: =I11 -> 0 | F11: ='13-04-15'!F11+E11 -> 0 | H11: MAYO-GALKE | I11: 0
A12: GUIDER | B12: =I7 -> 0 | C12: ='13-04-15'!C12+B12 -> 0 | D12: TOUBOURO | E12: =I12 -> 0 | F12: ='13-04-15'!F12+E12 -> 0 | H12: TOUBOURO | I12: 0
A13: GAROUA | B13: =I8 -> 0 | C13: ='13-04-15'!C13+B13 -> 0 | D13: HOME | E13: =I13 -> 0 | F13: ='13-04-15'!F13+E13 -> 0 | H13: HOME | I13: 0
A15: TOTAL JOURNALIER = | C15: =SUM(B9:B13)+SUM(E9:E13) -> 0 | D15: CUMUL GENERAL = | F15: =SUM(C9:C13)+SUM(F9:F13) -> 0 | H15: JOURNEE | I15: 42108
H16: TRANSMISSION | I16: =I15+1 -> 42109
A20: Transmis le : | B20: =I16 -> 42109

Sheet 15-04-15
A1: SODECOTON
H2: TABLEAU DE SAISI
A3: PLUVIOMETRIE JOURNALIERE ET PAR PENTADE | H3: STATION | I3: RELEVES
H4: MAROUA | I4: 0
B5: JOURNEE DU : | D5: =I15 -> 42109 | H5: KAELE | I5: 0
H6: TCHATIBALI | I6: 0
A7: STATION | B7: RELEVES | D7: STATION | E7: RELEVES | H7: GUIDER | I7: 0
B8: JOURNALIER | C8: CUMUL | E8: JOURNALIER | F8: CUMUL | H8: GAROUA | I8: 0
A9: MAROUA | B9: =I4 -> 0 | C9: ='14-04-15'!C9+B9 -> 0 | D9: NGONG | E9: =I9 -> 0 | F9: ='14-04-15'!F9+E9 -> 0 | H9: NGONG | I9: 0
A10: KAELE | B10: =I5 -> 0 | C10: ='14-04-15'!C10+B10 -> 0 | D10: POLI | E10: =I10 -> 0 | F10: ='14-04-15'!F10+E10 -> 0 | H10: POLI | I10: 0
A11: TCHATIBALI | B11: =I6 -> 0 | C11: ='14-04-15'!C11+B11 -> 0 | D11: MAYO-GALKE | E11: =I11 -> 0 | F11: ='14-04-15'!F11+E11 -> 0 | H11: MAYO-GALKE | I11: 0
A12: GUIDER | B12: =I7 -> 0 | C12: ='14-04-15'!C12+B12 -> 0 | D12: TOUBOURO | E12: =I12 -> 0 | F12: ='14-04-15'!F12+E12 -> 0 | H12: TOUBOURO | I12: 0
A13: GAROUA | B13: =I8 -> 0 | C13: ='14-04-15'!C13+B13 -> 0 | D13: HOME | E13: =I13 -> 0 | F13: ='14-04-15'!F13+E13 -> 0 | H13: HOME | I13: 0
A15: TOTAL JOURNALIER = | C15: =SUM(B9:B13)+SUM(E9:E13) -> 0 | D15: CUMUL GENERAL = | F15: =SUM(C9:C13)+SUM(F9:F13) -> 0 | H15: JOURNEE | I15: 42109
H16: TRANSMISSION | I16: =I15+1 -> 42110
A20: Transmis le : | B20: =I16 -> 42110

Sheet 16-04-15
A1: SODECOTON
H2: TABLEAU DE SAISI
A3: PLUVIOMETRIE JOURNALIERE ET PAR PENTADE | H3: STATION | I3: RELEVES
H4: MAROUA | I4: 0
B5: JOURNEE DU : | D5: =I15 -> 42110 | H5: KAELE | I5: 0
H6: TCHATIBALI | I6: 0
A7: STATION | B7: RELEVES | D7: STATION | E7: RELEVES | H7: GUIDER | I7: 0
B8: JOURNALIER | C8: CUMUL | E8: JOURNALIER | F8: CUMUL | H8: GAROUA | I8: 0
A9: MAROUA | B9: =I4 -> 0 | C9: ='15-04-15'!C9+B9 -> 0 | D9: NGONG | E9: =I9 -> 0 | F9: ='15-04-15'!F9+E9 -> 0 | H9: NGONG | I9: 0
A10: KAELE | B10: =I5 -> 0 | C10: ='15-04-15'!C10+B10 -> 0 | D10: POLI | E10: =I10 -> 0 | F10: ='15-04-15'!F10+E10 -> 0 | H10: POLI | I10: 0
A11: TCHATIBALI | B11: =I6 -> 0 | C11: ='15-04-15'!C11+B11 -> 0 | D11: MAYO-GALKE | E11: =I11 -> 0 | F11: ='15-04-15'!F11+E11 -> 0 | H11: MAYO-GALKE | I11: 0
A12: GUIDER | B12: =I7 -> 0 | C12: ='15-04-15'!C12+B12 -> 0 | D12: TOUBOURO | E12: =I12 -> 0 | F12: ='15-04-15'!F12+E12 -> 0 | H12: TOUBOURO | I12: 0
A13: GAROUA | B13: =I8 -> 0 | C13: ='15-04-15'!C13+B13 -> 0 | D13: HOME | E13: =I13 -> 0 | F13: ='15-04-15'!F13+E13 -> 0 | H13: HOME | I13: 0
A15: TOTAL JOURNALIER = | C15: =SUM(B9:B13)+SUM(E9:E13) -> 0 | D15: CUMUL GENERAL = | F15: =SUM(C9:C13)+SUM(F9:F13) -> 0 | H15: JOURNEE | I15: 42110
H16: TRANSMISSION | I16: =I15+1 -> 42111
A20: Transmis le : | B20: =I16 -> 42111

Sheet 17-04-15
A1: SODECOTON
H2: TABLEAU DE SAISI
A3: PLUVIOMETRIE JOURNALIERE ET PAR PENTADE | H3: STATION | I3: RELEVES
H4: MAROUA | I4: 0
B5: JOURNEE DU : | D5: =I15 -> 42111 | H5: KAELE | I5: 0
H6: TCHATIBALI | I6: 0
A7: STATION | B7: RELEVES | D7: STATION | E7: RELEVES | H7: GUIDER | I7: 0
B8: JOURNALIER | C8: CUMUL | E8: JOURNALIER | F8: CUMUL | H8: GAROUA | I8: 0
A9: MAROUA | B9: =I4 -> 0 | C9: ='16-04-15'!C9+B9 -> 0 | D9: NGONG | E9: =I9 -> 0 | F9: ='16-04-15'!F9+E9 -> 0 | H9: NGONG | I9: 0
A10: KAELE | B10: =I5 -> 0 | C10: ='16-04-15'!C10+B10 -> 0 | D10: POLI | E10: =I10 -> 0 | F10: ='16-04-15'!F10+E10 -> 0 | H10: POLI | I10: 0
A11: TCHATIBALI | B11: =I6 -> 0 | C11: ='16-04-15'!C11+B11 -> 0 | D11: MAYO-GALKE | E11: =I11 -> 0 | F11: ='16-04-15'!F11+E11 -> 0 | H11: MAYO-GALKE | I11: 0
A12: GUIDER | B12: =I7 -> 0 | C12: ='16-04-15'!C12+B12 -> 0 | D12: TOUBOURO | E12: =I12 -> 0 | F12: ='16-04-15'!F12+E12 -> 0 | H12: TOUBOURO | I12: 0
A13: GAROUA | B13: =I8 -> 0 | C13: ='16-04-15'!C13+B13 -> 0 | D13: HOME | E13: =I13 -> 0 | F13: ='16-04-15'!F13+E13 -> 0 | H13: HOME | I13: 0
A15: TOTAL JOURNALIER = | C15: =SUM(B9:B13)+SUM(E9:E13) -> 0 | D15: CUMUL GENERAL = | F15: =SUM(C9:C13)+SUM(F9:F13) -> 0 | H15: JOURNEE | I15: 42111
H16: TRANSMISSION | I16: =I15+1 -> 42112
A20: Transmis le : | B20: =I16 -> 42112

Sheet 18-04-15
A1: SODECOTON
H2: TABLEAU DE SAISI
A3: PLUVIOMETRIE JOURNALIERE ET PAR PENTADE | H3: STATION | I3: RELEVES
H4: MAROUA | I4: 0
B5: JOURNEE DU : | D5: =I15 -> 42112 | H5: KAELE | I5: 0
H6: TCHATIBALI | I6: 0
A7: STATION | B7: RELEVES | D7: STATION | E7: RELEVES | H7: GUIDER | I7: 0
B8: JOURNALIER | C8: CUMUL | E8: JOURNALIER | F8: CUMUL | H8: GAROUA | I8: 0
A9: MAROUA | B9: =I4 -> 0 | C9: ='17-04-15'!C9+B9 -> 0 | D9: NGONG | E9: =I9 -> 0 | F9: ='17-04-15'!F9+E9 -> 0 | H9: NGONG | I9: 0
A10: KAELE | B10: =I5 -> 0 | C10: ='17-04-15'!C10+B10 -> 0 | D10: POLI | E10: =I10 -> 0 | F10: ='17-04-15'!F10+E10 -> 0 | H10: POLI | I10: 0
A11: TCHATIBALI | B11: =I6 -> 0 | C11: ='17-04-15'!C11+B11 -> 0 | D11: MAYO-GALKE | E11: =I11 -> 0 | F11: ='17-04-15'!F11+E11 -> 0 | H11: MAYO-GALKE | I11: 0
A12: GUIDER | B12: =I7 -> 0 | C12: ='17-04-15'!C12+B12 -> 0 | D12: TOUBOURO | E12: =I12 -> 0 | F12: ='17-04-15'!F12+E12 -> 0 | H12: TOUBOURO | I12: 0
A13: GAROUA | B13: =I8 -> 0 | C13: ='17-04-15'!C13+B13 -> 0 | D13: HOME | E13: =I13 -> 0 | F13: ='17-04-15'!F13+E13 -> 0 | H13: HOME | I13: 0
A15: TOTAL JOURNALIER = | C15: =SUM(B9:B13)+SUM(E9:E13) -> 0 | D15: CUMUL GENERAL = | F15: =SUM(C9:C13)+SUM(F9:F13) -> 0 | H15: JOURNEE | I15: 42112
H16: TRANSMISSION | I16: =I15+1 -> 42113
A20: Transmis le : | B20: =I16 -> 42113

Sheet 19-04-15
A1: SODECOTON
H2: TABLEAU DE SAISI
A3: PLUVIOMETRIE JOURNALIERE ET PAR PENTADE | H3: STATION | I3: RELEVES
H4: MAROUA | I4: 0
B5: JOURNEE DU : | D5: =I15 -> 42113 | H5: KAELE | I5: 0
H6: TCHATIBALI | I6: 0
A7: STATION | B7: RELEVES | D7: STATION | E7: RELEVES | H7: GUIDER | I7: 0
B8: JOURNALIER | C8: CUMUL | E8: JOURNALIER | F8: CUMUL | H8: GAROUA | I8: 0
A9: MAROUA | B9: =I4 -> 0 | C9: ='18-04-15'!C9+B9 -> 0 | D9: NGONG | E9: =I9 -> 0 | F9: ='18-04-15'!F9+E9 -> 0 | H9: NGONG | I9: 0
A10: KAELE | B10: =I5 -> 0 | C10: ='18-04-15'!C10+B10 -> 0 | D10: POLI | E10: =I10 -> 0 | F10: ='18-04-15'!F10+E10 -> 0 | H10: POLI | I10: 0
A11: TCHATIBALI | B11: =I6 -> 0 | C11: ='18-04-15'!C11+B11 -> 0 | D11: MAYO-GALKE | E11: =I11 -> 0 | F11: ='18-04-15'!F11+E11 -> 0 | H11: MAYO-GALKE | I11: 0
A12: GUIDER | B12: =I7 -> 0 | C12: ='18-04-15'!C12+B12 -> 0 | D12: TOUBOURO | E12: =I12 -> 0 | F12: ='18-04-15'!F12+E12 -> 0 | H12: TOUBOURO | I12: 0
A13: GAROUA | B13: =I8 -> 0 | C13: ='18-04-15'!C13+B13 -> 0 | D13: HOME | E13: =I13 -> 0 | F13: ='18-04-15'!F13+E13 -> 0 | H13: HOME | I13: 0
A15: TOTAL JOURNALIER = | C15: =SUM(B9:B13)+SUM(E9:E13) -> 0 | D15: CUMUL GENERAL = | F15: =SUM(C9:C13)+SUM(F9:F13) -> 0 | H15: JOURNEE | I15: 42113
H16: TRANSMISSION | I16: =I15+1 -> 42114
A20: Transmis le : | B20: =I16 -> 42114

Sheet 20-04-15
A1: SODECOTON
H2: TABLEAU DE SAISI
A3: PLUVIOMETRIE JOURNALIERE ET PAR PENTADE | H3: STATION | I3: RELEVES
H4: MAROUA | I4: 0
B5: JOURNEE DU : | D5: =I15 -> 42114 | H5: KAELE | I5: 0
H6: TCHATIBALI | I6: 0
A7: STATION | B7: RELEVES | D7: STATION | E7: RELEVES | H7: GUIDER | I7: 0
B8: JOURNALIER | C8: CUMUL | E8: JOURNALIER | F8: CUMUL | H8: GAROUA | I8: 0
A9: MAROUA | B9: =I4 -> 0 | C9: ='19-04-15'!C9+B9 -> 0 | D9: NGONG | E9: =I9 -> 0 | F9: ='19-04-15'!F9+E9 -> 0 | H9: NGONG | I9: 0
A10: KAELE | B10: =I5 -> 0 | C10: ='19-04-15'!C10+B10 -> 0 | D10: POLI | E10: =I10 -> 0 | F10: ='19-04-15'!F10+E10 -> 0 | H10: POLI | I10: 0
A11: TCHATIBALI | B11: =I6 -> 0 | C11: ='19-04-15'!C11+B11 -> 0 | D11: MAYO-GALKE | E11: =I11 -> 0 | F11: ='19-04-15'!F11+E11 -> 0 | H11: MAYO-GALKE | I11: 0
A12: GUIDER | B12: =I7 -> 0 | C12: ='19-04-15'!C12+B12 -> 0 | D12: TOUBOURO | E12: =I12 -> 0 | F12: ='19-04-15'!F12+E12 -> 0 | H12: TOUBOURO | I12: 0
A13: GAROUA | B13: =I8 -> 0 | C13: ='19-04-15'!C13+B13 -> 0 | D13: HOME | E13: =I13 -> 0 | F13: ='19-04-15'!F13+E13 -> 0 | H13: HOME | I13: 0
A15: TOTAL JOURNALIER = | C15: =SUM(B9:B13)+SUM(E9:E13) -> 0 | D15: CUMUL GENERAL = | F15: =SUM(C9:C13)+SUM(F9:F13) -> 0 | H15: JOURNEE | I15: 42114
H16: TRANSMISSION | I16: =I15+1 -> 42115
A20: Transmis le : | B20: =I16 -> 42115

Sheet 21-04-15
A1: SODECOTON
H2: TABLEAU DE SAISI
A3: PLUVIOMETRIE JOURNALIERE ET PAR PENTADE | H3: STATION | I3: RELEVES
H4: MAROUA | I4: 0
B5: JOURNEE DU : | D5: =I15 -> 42115 | H5: KAELE | I5: 0
H6: TCHATIBALI | I6: 0
A7: STATION | B7: RELEVES | D7: STATION | E7: RELEVES | H7: GUIDER | I7: 0
B8: JOURNALIER | C8: CUMUL | E8: JOURNALIER | F8: CUMUL | H8: GAROUA | I8: 0
A9: MAROUA | B9: =I4 -> 0 | C9: ='20-04-15'!C9+B9 -> 0 | D9: NGONG | E9: =I9 -> 0 | F9: ='20-04-15'!F9+E9 -> 0 | H9: NGONG | I9: 0
A10: KAELE | B10: =I5 -> 0 | C10: ='20-04-15'!C10+B10 -> 0 | D10: POLI | E10: =I10 -> 0 | F10: ='20-04-15'!F10+E10 -> 0 | H10: POLI | I10: 0
A11: TCHATIBALI | B11: =I6 -> 0 | C11: ='20-04-15'!C11+B11 -> 0 | D11: MAYO-GALKE | E11: =I11 -> 0 | F11: ='20-04-15'!F11+E11 -> 0 | H11: MAYO-GALKE | I11: 0
A12: GUIDER | B12: =I7 -> 0 | C12: ='20-04-15'!C12+B12 -> 0 | D12: TOUBOURO | E12: =I12 -> 0 | F12: ='20-04-15'!F12+E12 -> 0 | H12: TOUBOURO | I12: 0
A13: GAROUA | B13: =I8 -> 0 | C13: ='20-04-15'!C13+B13 -> 0 | D13: HOME | E13: =I13 -> 0 | F13: ='20-04-15'!F13+E13 -> 0 | H13: HOME | I13: 0
A15: TOTAL JOURNALIER = | C15: =SUM(B9:B13)+SUM(E9:E13) -> 0 | D15: CUMUL GENERAL = | F15: =SUM(C9:C13)+SUM(F9:F13) -> 0 | H15: JOURNEE | I15: 42115
H16: TRANSMISSION | I16: =I15+1 -> 42116
A20: Transmis le : | B20: =I16 -> 42116

Sheet 22-04-15
A1: SODECOTON
H2: TABLEAU DE SAISI
A3: PLUVIOMETRIE JOURNALIERE ET PAR PENTADE | H3: STATION | I3: RELEVES
H4: MAROUA | I4: 0
B5: JOURNEE DU : | D5: =I15 -> 42116 | H5: KAELE | I5: 0
H6: TCHATIBALI | I6: 0
A7: STATION | B7: RELEVES | D7: STATION | E7: RELEVES | H7: GUIDER | I7: 0
B8: JOURNALIER | C8: CUMUL | E8: JOURNALIER | F8: CUMUL | H8: GAROUA | I8: 0
A9: MAROUA | B9: =I4 -> 0 | C9: ='21-04-15'!C9+B9 -> 0 | D9: NGONG | E9: =I9 -> 0 | F9: ='21-04-15'!F9+E9 -> 0 | H9: NGONG | I9: 0
A10: KAELE | B10: =I5 -> 0 | C10: ='21-04-15'!C10+B10 -> 0 | D10: POLI | E10: =I10 -> 0 | F10: ='21-04-15'!F10+E10 -> 0 | H10: POLI | I10: 0
A11: TCHATIBALI | B11: =I6 -> 0 | C11: ='21-04-15'!C11+B11 -> 0 | D11: MAYO-GALKE | E11: =I11 -> 0 | F11: ='21-04-15'!F11+E11 -> 0 | H11: MAYO-GALKE | I11: 0
A12: GUIDER | B12: =I7 -> 0 | C12: ='21-04-15'!C12+B12 -> 0 | D12: TOUBOURO | E12: =I12 -> 0 | F12: ='21-04-15'!F12+E12 -> 0 | H12: TOUBOURO | I12: 0
A13: GAROUA | B13: =I8 -> 0 | C13: ='21-04-15'!C13+B13 -> 0 | D13: HOME | E13: =I13 -> 0 | F13: ='21-04-15'!F13+E13 -> 0 | H13: HOME | I13: 0
A15: TOTAL JOURNALIER = | C15: =SUM(B9:B13)+SUM(E9:E13) -> 0 | D15: CUMUL GENERAL = | F15: =SUM(C9:C13)+SUM(F9:F13) -> 0 | H15: JOURNEE | I15: 42116
H16: TRANSMISSION | I16: =I15+1 -> 42117
A20: Transmis le : | B20: =I16 -> 42117

Sheet 23-04-15
A1: SODECOTON
H2: TABLEAU DE SAISI
A3: PLUVIOMETRIE JOURNALIERE ET PAR PENTADE | H3: STATION | I3: RELEVES
H4: MAROUA | I4: 0
B5: JOURNEE DU : | D5: =I15 -> 42117 | H5: KAELE | I5: 0
H6: TCHATIBALI | I6: 0
A7: STATION | B7: RELEVES | D7: STATION | E7: RELEVES | H7: GUIDER | I7: 0
B8: JOURNALIER | C8: CUMUL | E8: JOURNALIER | F8: CUMUL | H8: GAROUA | I8: 0
A9: MAROUA | B9: =I4 -> 0 | C9: ='22-04-15'!C9+B9 -> 0 | D9: NGONG | E9: =I9 -> 0 | F9: ='22-04-15'!F9+E9 -> 0 | H9: NGONG | I9: 0
A10: KAELE | B10: =I5 -> 0 | C10: ='22-04-15'!C10+B10 -> 0 | D10: POLI | E10: =I10 -> 0 | F10: ='22-04-15'!F10+E10 -> 0 | H10: POLI | I10: 0
A11: TCHATIBALI | B11: =I6 -> 0 | C11: ='22-04-15'!C11+B11 -> 0 | D11: MAYO-GALKE | E11: =I11 -> 0 | F11: ='22-04-15'!F11+E11 -> 0 | H11: MAYO-GALKE | I11: 0
A12: GUIDER | B12: =I7 -> 0 | C12: ='22-04-15'!C12+B12 -> 0 | D12: TOUBOURO | E12: =I12 -> 0 | F12: ='22-04-15'!F12+E12 -> 0 | H12: TOUBOURO | I12: 0
A13: GAROUA | B13: =I8 -> 0 | C13: ='22-04-15'!C13+B13 -> 0 | D13: HOME | E13: =I13 -> 0 | F13: ='22-04-15'!F13+E13 -> 0 | H13: HOME | I13: 0
A15: TOTAL JOURNALIER = | C15: =SUM(B9:B13)+SUM(E9:E13) -> 0 | D15: CUMUL GENERAL = | F15: =SUM(C9:C13)+SUM(F9:F13) -> 0 | H15: JOURNEE | I15: 42117
H16: TRANSMISSION | I16: =I15+1 -> 42118
A20: Transmis le : | B20: =I16 -> 42118

Sheet 24-04-15
A1: SODECOTON
H2: TABLEAU DE SAISI
A3: PLUVIOMETRIE JOURNALIERE ET PAR PENTADE | H3: STATION | I3: RELEVES
H4: MAROUA | I4: 0
B5: JOURNEE DU : | D5: =I15 -> 42118 | H5: KAELE | I5: 0
H6: TCHATIBALI | I6: 0
A7: STATION | B7: RELEVES | D7: STATION | E7: RELEVES | H7: GUIDER | I7: 0
B8: JOURNALIER | C8: CUMUL | E8: JOURNALIER | F8: CUMUL | H8: GAROUA | I8: 0
A9: MAROUA | B9: =I4 -> 0 | C9: ='23-04-15'!C9+B9 -> 0 | D9: NGONG | E9: =I9 -> 0 | F9: ='23-04-15'!F9+E9 -> 0 | H9: NGONG | I9: 0
A10: KAELE | B10: =I5 -> 0 | C10: ='23-04-15'!C10+B10 -> 0 | D10: POLI | E10: =I10 -> 0 | F10: ='23-04-15'!F10+E10 -> 0 | H10: POLI | I10: 0
A11: TCHATIBALI | B11: =I6 -> 0 | C11: ='23-04-15'!C11+B11 -> 0 | D11: MAYO-GALKE | E11: =I11 -> 0 | F11: ='23-04-15'!F11+E11 -> 0 | H11: MAYO-GALKE | I11: 0
A12: GUIDER | B12: =I7 -> 0 | C12: ='23-04-15'!C12+B12 -> 0 | D12: TOUBOURO | E12: =I12 -> 0 | F12: ='23-04-15'!F12+E12 -> 0 | H12: TOUBOURO | I12: 0
A13: GAROUA | B13: =I8 -> 0 | C13: ='23-04-15'!C13+B13 -> 0 | D13: HOME | E13: =I13 -> 0 | F13: ='23-04-15'!F13+E13 -> 0 | H13: HOME | I13: 0
A15: TOTAL JOURNALIER = | C15: =SUM(B9:B13)+SUM(E9:E13) -> 0 | D15: CUMUL GENERAL = | F15: =SUM(C9:C13)+SUM(F9:F13) -> 0 | H15: JOURNEE | I15: 42118
H16: TRANSMISSION | I16: =I15+1 -> 42119
A20: Transmis le : | B20: =I16 -> 42119

Sheet 25-04-15
A1: SODECOTON
H2: TABLEAU DE SAISI
A3: PLUVIOMETRIE JOURNALIERE ET PAR PENTADE | H3: STATION | I3: RELEVES
H4: MAROUA | I4: 0
B5: JOURNEE DU : | D5: =I15 -> 42119 | H5: KAELE | I5: 0
H6: TCHATIBALI | I6: 0
A7: STATION | B7: RELEVES | D7: STATION | E7: RELEVES | H7: GUIDER | I7: 0
B8: JOURNALIER | C8: CUMUL | E8: JOURNALIER | F8: CUMUL | H8: GAROUA | I8: 0
A9: MAROUA | B9: =I4 -> 0 | C9: ='24-04-15'!C9+B9 -> 0 | D9: NGONG | E9: =I9 -> 0 | F9: ='24-04-15'!F9+E9 -> 0 | H9: NGONG | I9: 0
A10: KAELE | B10: =I5 -> 0 | C10: ='24-04-15'!C10+B10 -> 0 | D10: POLI | E10: =I10 -> 0 | F10: ='24-04-15'!F10+E10 -> 0 | H10: POLI | I10: 0
A11: TCHATIBALI | B11: =I6 -> 0 | C11: ='24-04-15'!C11+B11 -> 0 | D11: MAYO-GALKE | E11: =I11 -> 0 | F11: ='24-04-15'!F11+E11 -> 0 | H11: MAYO-GALKE | I11: 0
A12: GUIDER | B12: =I7 -> 0 | C12: ='24-04-15'!C12+B12 -> 0 | D12: TOUBOURO | E12: =I12 -> 0 | F12: ='24-04-15'!F12+E12 -> 0 | H12: TOUBOURO | I12: 0
A13: GAROUA | B13: =I8 -> 0 | C13: ='24-04-15'!C13+B13 -> 0 | D13: HOME | E13: =I13 -> 0 | F13: ='24-04-15'!F13+E13 -> 0 | H13: HOME | I13: 0
A15: TOTAL JOURNALIER = | C15: =SUM(B9:B13)+SUM(E9:E13) -> 0 | D15: CUMUL GENERAL = | F15: =SUM(C9:C13)+SUM(F9:F13) -> 0 | H15: JOURNEE | I15: 42119
H16: TRANSMISSION | I16: =I15+1 -> 42120
A20: Transmis le : | B20: =I16 -> 42120

Sheet 26-04-15
A1: SODECOTON
H2: TABLEAU DE SAISI
A3: PLUVIOMETRIE JOURNALIERE ET PAR PENTADE | H3: STATION | I3: RELEVES
H4: MAROUA | I4: 0
B5: JOURNEE DU : | D5: =I15 -> 42120 | H5: KAELE | I5: 0
H6: TCHATIBALI | I6: 0
A7: STATION | B7: RELEVES | D7: STATION | E7: RELEVES | H7: GUIDER | I7: 0
B8: JOURNALIER | C8: CUMUL | E8: JOURNALIER | F8: CUMUL | H8: GAROUA | I8: 0
A9: MAROUA | B9: =I4 -> 0 | C9: ='25-04-15'!C9+B9 -> 0 | D9: NGONG | E9: =I9 -> 0 | F9: ='25-04-15'!F9+E9 -> 0 | H9: NGONG | I9: 0
A10: KAELE | B10: =I5 -> 0 | C10: ='25-04-15'!C10+B10 -> 0 | D10: POLI | E10: =I10 -> 0 | F10: ='25-04-15'!F10+E10 -> 0 | H10: POLI | I10: 0
A11: TCHATIBALI | B11: =I6 -> 0 | C11: ='25-04-15'!C11+B11 -> 0 | D11: MAYO-GALKE | E11: =I11 -> 0 | F11: ='25-04-15'!F11+E11 -> 0 | H11: MAYO-GALKE | I11: 0
A12: GUIDER | B12: =I7 -> 0 | C12: ='25-04-15'!C12+B12 -> 0 | D12: TOUBOURO | E12: =I12 -> 0 | F12: ='25-04-15'!F12+E12 -> 0 | H12: TOUBOURO | I12: 0
A13: GAROUA | B13: =I8 -> 0 | C13: ='25-04-15'!C13+B13 -> 0 | D13: HOME | E13: =I13 -> 0 | F13: ='25-04-15'!F13+E13 -> 0 | H13: HOME | I13: 0
A15: TOTAL JOURNALIER = | C15: =SUM(B9:B13)+SUM(E9:E13) -> 0 | D15: CUMUL GENERAL = | F15: =SUM(C9:C13)+SUM(F9:F13) -> 0 | H15: JOURNEE | I15: 42120
H16: TRANSMISSION | I16: =I15+1 -> 42121
A20: Transmis le : | B20: =I16 -> 42121

Sheet 27-04-15
A1: SODECOTON
H2: TABLEAU DE SAISI
A3: PLUVIOMETRIE JOURNALIERE ET PAR PENTADE | H3: STATION | I3: RELEVES
H4: MAROUA | I4: 0
B5: JOURNEE DU : | D5: =I15 -> 42121 | H5: KAELE | I5: 0
H6: TCHATIBALI | I6: 0
A7: STATION | B7: RELEVES | D7: STATION | E7: RELEVES | H7: GUIDER | I7: 0
B8: JOURNALIER | C8: CUMUL | E8: JOURNALIER | F8: CUMUL | H8: GAROUA | I8: 0
A9: MAROUA | B9: =I4 -> 0 | C9: ='26-04-15'!C9+B9 -> 0 | D9: NGONG | E9: =I9 -> 0 | F9: ='26-04-15'!F9+E9 -> 0 | H9: NGONG | I9: 0
A10: KAELE | B10: =I5 -> 0 | C10: ='26-04-15'!C10+B10 -> 0 | D10: POLI | E10: =I10 -> 0 | F10: ='26-04-15'!F10+E10 -> 0 | H10: POLI | I10: 0
A11: TCHATIBALI | B11: =I6 -> 0 | C11: ='26-04-15'!C11+B11 -> 0 | D11: MAYO-GALKE | E11: =I11 -> 0 | F11: ='26-04-15'!F11+E11 -> 0 | H11: MAYO-GALKE | I11: 0
A12: GUIDER | B12: =I7 -> 0 | C12: ='26-04-15'!C12+B12 -> 0 | D12: TOUBOURO | E12: =I12 -> 0 | F12: ='26-04-15'!F12+E12 -> 0 | H12: TOUBOURO | I12: 0
A13: GAROUA | B13: =I8 -> 0 | C13: ='26-04-15'!C13+B13 -> 0 | D13: HOME | E13: =I13 -> 0 | F13: ='26-04-15'!F13+E13 -> 0 | H13: HOME | I13: 0
A15: TOTAL JOURNALIER = | C15: =SUM(B9:B13)+SUM(E9:E13) -> 0 | D15: CUMUL GENERAL = | F15: =SUM(C9:C13)+SUM(F9:F13) -> 0 | H15: JOURNEE | I15: 42121
H16: TRANSMISSION | I16: =I15+1 -> 42122
A20: Transmis le : | B20: =I16 -> 42122

Sheet 28-04-15
A1: SODECOTON
H2: TABLEAU DE SAISI
A3: PLUVIOMETRIE JOURNALIERE ET PAR PENTADE | H3: STATION | I3: RELEVES
H4: MAROUA | I4: 0
B5: JOURNEE DU : | D5: =I15 -> 42122 | H5: KAELE | I5: 0
H6: TCHATIBALI | I6: 0
A7: STATION | B7: RELEVES | D7: STATION | E7: RELEVES | H7: GUIDER | I7: 0
B8: JOURNALIER | C8: CUMUL | E8: JOURNALIER | F8: CUMUL | H8: GAROUA | I8: 0
A9: MAROUA | B9: =I4 -> 0 | C9: ='27-04-15'!C9+B9 -> 0 | D9: NGONG | E9: =I9 -> 0 | F9: ='27-04-15'!F9+E9 -> 0 | H9: NGONG | I9: 0
A10: KAELE | B10: =I5 -> 0 | C10: ='27-04-15'!C10+B10 -> 0 | D10: POLI | E10: =I10 -> 0 | F10: ='27-04-15'!F10+E10 -> 0 | H10: POLI | I10: 0
A11: TCHATIBALI | B11: =I6 -> 0 | C11: ='27-04-15'!C11+B11 -> 0 | D11: MAYO-GALKE | E11: =I11 -> 0 | F11: ='27-04-15'!F11+E11 -> 0 | H11: MAYO-GALKE | I11: 0
A12: GUIDER | B12: =I7 -> 0 | C12: ='27-04-15'!C12+B12 -> 0 | D12: TOUBOURO | E12: =I12 -> 0 | F12: ='27-04-15'!F12+E12 -> 0 | H12: TOUBOURO | I12: 0
A13: GAROUA | B13: =I8 -> 0 | C13: ='27-04-15'!C13+B13 -> 0 | D13: HOME | E13: =I13 -> 0 | F13: ='27-04-15'!F13+E13 -> 0 | H13: HOME | I13: 0
A15: TOTAL JOURNALIER = | C15: =SUM(B9:B13)+SUM(E9:E13) -> 0 | D15: CUMUL GENERAL = | F15: =SUM(C9:C13)+SUM(F9:F13) -> 0 | H15: JOURNEE | I15: 42122
H16: TRANSMISSION | I16: =I15+1 -> 42123
A20: Transmis le : | B20: =I16 -> 42123

Sheet 29-04-15
A1: SODECOTON
H2: TABLEAU DE SAISI
A3: PLUVIOMETRIE JOURNALIERE ET PAR PENTADE | H3: STATION | I3: RELEVES
H4: MAROUA | I4: 0
B5: JOURNEE DU : | D5: =I15 -> 42123 | H5: KAELE | I5: 0
H6: TCHATIBALI | I6: 0
A7: STATION | B7: RELEVES | D7: STATION | E7: RELEVES | H7: GUIDER | I7: 0
B8: JOURNALIER | C8: CUMUL | E8: JOURNALIER | F8: CUMUL | H8: GAROUA | I8: 0
A9: MAROUA | B9: =I4 -> 0 | C9: ='28-04-15'!C9+B9 -> 0 | D9: NGONG | E9: =I9 -> 0 | F9: ='28-04-15'!F9+E9 -> 0 | H9: NGONG | I9: 0
A10: KAELE | B10: =I5 -> 0 | C10: ='28-04-15'!C10+B10 -> 0 | D10: POLI | E10: =I10 -> 0 | F10: ='28-04-15'!F10+E10 -> 0 | H10: POLI | I10: 0
A11: TCHATIBALI | B11: =I6 -> 0 | C11: ='28-04-15'!C11+B11 -> 0 | D11: MAYO-GALKE | E11: =I11 -> 0 | F11: ='28-04-15'!F11+E11 -> 0 | H11: MAYO-GALKE | I11: 0
A12: GUIDER | B12: =I7 -> 0 | C12: ='28-04-15'!C12+B12 -> 0 | D12: TOUBOURO | E12: =I12 -> 0 | F12: ='28-04-15'!F12+E12 -> 0 | H12: TOUBOURO | I12: 0
A13: GAROUA | B13: =I8 -> 0 | C13: ='28-04-15'!C13+B13 -> 0 | D13: HOME | E13: =I13 -> 0 | F13: ='28-04-15'!F13+E13 -> 0 | H13: HOME | I13: 0
A15: TOTAL JOURNALIER = | C15: =SUM(B9:B13)+SUM(E9:E13) -> 0 | D15: CUMUL GENERAL = | F15: =SUM(C9:C13)+SUM(F9:F13) -> 0 | H15: JOURNEE | I15: 42123
H16: TRANSMISSION | I16: =I15+1 -> 42124
A20: Transmis le : | B20: =I16 -> 42124

Sheet 30-04-15
A1: SODECOTON
H2: TABLEAU DE SAISI
A3: PLUVIOMETRIE JOURNALIERE ET PAR PENTADE | H3: STATION | I3: RELEVES
H4: MAROUA | I4: 0
B5: JOURNEE DU : | D5: =I15 -> 42124 | H5: KAELE | I5: 0
H6: TCHATIBALI | I6: 0
A7: STATION | B7: RELEVES | D7: STATION | E7: RELEVES | H7: GUIDER | I7: 0
B8: JOURNALIER | C8: CUMUL | E8: JOURNALIER | F8: CUMUL | H8: GAROUA | I8: 0
A9: MAROUA | B9: =I4 -> 0 | C9: ='29-04-15'!C9+B9 -> 0 | D9: NGONG | E9: =I9 -> 0 | F9: ='29-04-15'!F9+E9 -> 0 | H9: NGONG | I9: 0
A10: KAELE | B10: =I5 -> 0 | C10: ='29-04-15'!C10+B10 -> 0 | D10: POLI | E10: =I10 -> 0 | F10: ='29-04-15'!F10+E10 -> 0 | H10: POLI | I10: 0
A11: TCHATIBALI | B11: =I6 -> 0 | C11: ='29-04-15'!C11+B11 -> 0 | D11: MAYO-GALKE | E11: =I11 -> 0 | F11: ='29-04-15'!F11+E11 -> 0 | H11: MAYO-GALKE | I11: 0
A12: GUIDER | B12: =I7 -> 0 | C12: ='29-04-15'!C12+B12 -> 0 | D12: TOUBOURO | E12: =I12 -> 0 | F12: ='29-04-15'!F12+E12 -> 0 | H12: TOUBOURO | I12: 0
A13: GAROUA | B13: =I8 -> 0 | C13: ='29-04-15'!C13+B13 -> 0 | D13: HOME | E13: =I13 -> 0 | F13: ='29-04-15'!F13+E13 -> 0 | H13: HOME | I13: 0
A15: TOTAL JOURNALIER = | C15: =SUM(B9:B13)+SUM(E9:E13) -> 0 | D15: CUMUL GENERAL = | F15: =SUM(C9:C13)+SUM(F9:F13) -> 0 | H15: JOURNEE | I15: 42124
H16: TRANSMISSION | I16: =I15+1 -> 42125
A20: Transmis le : | B20: =I16 -> 42125

Sheet 01-05-15
A1: SODECOTON
H2: TABLEAU DE SAISI
A3: PLUVIOMETRIE JOURNALIERE ET PAR PENTADE | H3: STATION | I3: RELEVES
H4: MAROUA | I4: 0
B5: JOURNEE DU : | D5: =I15 -> 42125 | H5: KAELE | I5: 0
H6: TCHATIBALI | I6: 0
A7: STATION | B7: RELEVES | D7: STATION | E7: RELEVES | H7: GUIDER | I7: 0
B8: JOURNALIER | C8: CUMUL | E8: JOURNALIER | F8: CUMUL | H8: GAROUA | I8: 0
A9: MAROUA | B9: =I4 -> 0 | C9: ='30-04-15'!C9+B9 -> 0 | D9: NGONG | E9: =I9 -> 0 | F9: ='30-04-15'!F9+E9 -> 0 | H9: NGONG | I9: 0
A10: KAELE | B10: =I5 -> 0 | C10: ='30-04-15'!C10+B10 -> 0 | D10: POLI | E10: =I10 -> 0 | F10: ='30-04-15'!F10+E10 -> 0 | H10: POLI | I10: 0
A11: TCHATIBALI | B11: =I6 -> 0 | C11: ='30-04-15'!C11+B11 -> 0 | D11: MAYO-GALKE | E11: =I11 -> 0 | F11: ='30-04-15'!F11+E11 -> 0 | H11: MAYO-GALKE | I11: 0
A12: GUIDER | B12: =I7 -> 0 | C12: ='30-04-15'!C12+B12 -> 0 | D12: TOUBOURO | E12: =I12 -> 0 | F12: ='30-04-15'!F12+E12 -> 0 | H12: TOUBOURO | I12: 0
A13: GAROUA | B13: =I8 -> 0 | C13: ='30-04-15'!C13+B13 -> 0 | D13: HOME | E13: =I13 -> 0 | F13: ='30-04-15'!F13+E13 -> 0 | H13: HOME | I13: 0
A15: TOTAL JOURNALIER = | C15: =SUM(B9:B13)+SUM(E9:E13) -> 0 | D15: CUMUL GENERAL = | F15: =SUM(C9:C13)+SUM(F9:F13) -> 0 | H15: JOURNEE | I15: 42125
H16: TRANSMISSION | I16: =I15+1 -> 42126
A20: Transmis le : | B20: =I16 -> 42126

Sheet 02-05-15
A1: SODECOTON
H2: TABLEAU DE SAISI
A3: PLUVIOMETRIE JOURNALIERE ET PAR PENTADE | H3: STATION | I3: RELEVES
H4: MAROUA | I4: 0
B5: JOURNEE DU : | D5: =I15 -> 42126 | H5: KAELE | I5: 0
H6: TCHATIBALI | I6: 0
A7: STATION | B7: RELEVES | D7: STATION | E7: RELEVES | H7: GUIDER | I7: 0
B8: JOURNALIER | C8: CUMUL | E8: JOURNALIER | F8: CUMUL | H8: GAROUA | I8: 0
A9: MAROUA | B9: =I4 -> 0 | C9: ='01-05-15'!C9+B9 -> 0 | D9: NGONG | E9: =I9 -> 0 | F9: ='01-05-15'!F9+E9 -> 0 | H9: NGONG | I9: 0
A10: KAELE | B10: =I5 -> 0 | C10: ='01-05-15'!C10+B10 -> 0 | D10: POLI | E10: =I10 -> 0 | F10: ='01-05-15'!F10+E10 -> 0 | H10: POLI | I10: 0
A11: TCHATIBALI | B11: =I6 -> 0 | C11: ='01-05-15'!C11+B11 -> 0 | D11: MAYO-GALKE | E11: =I11 -> 0 | F11: ='01-05-15'!F11+E11 -> 0 | H11: MAYO-GALKE | I11: 0
A12: GUIDER | B12: =I7 -> 0 | C12: ='01-05-15'!C12+B12 -> 0 | D12: TOUBOURO | E12: =I12 -> 0 | F12: ='01-05-15'!F12+E12 -> 0 | H12: TOUBOURO | I12: 0
A13: GAROUA | B13: =I8 -> 0 | C13: ='01-05-15'!C13+B13 -> 0 | D13: HOME | E13: =I13 -> 0 | F13: ='01-05-15'!F13+E13 -> 0 | H13: HOME | I13: 0
A15: TOTAL JOURNALIER = | C15: =SUM(B9:B13)+SUM(E9:E13) -> 0 | D15: CUMUL GENERAL = | F15: =SUM(C9:C13)+SUM(F9:F13) -> 0 | H15: JOURNEE | I15: 42126
H16: TRANSMISSION | I16: =I15+1 -> 42127
A20: Transmis le : | B20: =I16 -> 42127

Sheet 03-05-15
A1: SODECOTON
H2: TABLEAU DE SAISI
A3: PLUVIOMETRIE JOURNALIERE ET PAR PENTADE | H3: STATION | I3: RELEVES
H4: MAROUA | I4: 0
B5: JOURNEE DU : | D5: =I15 -> 42127 | H5: KAELE | I5: 0
H6: TCHATIBALI | I6: 0
A7: STATION | B7: RELEVES | D7: STATION | E7: RELEVES | H7: GUIDER | I7: 0
B8: JOURNALIER | C8: CUMUL | E8: JOURNALIER | F8: CUMUL | H8: GAROUA | I8: 0
A9: MAROUA | B9: =I4 -> 0 | C9: ='02-05-15'!C9+B9 -> 0 | D9: NGONG | E9: =I9 -> 0 | F9: ='02-05-15'!F9+E9 -> 0 | H9: NGONG | I9: 0
A10: KAELE | B10: =I5 -> 0 | C10: ='02-05-15'!C10+B10 -> 0 | D10: POLI | E10: =I10 -> 0 | F10: ='02-05-15'!F10+E10 -> 0 | H10: POLI | I10: 0
A11: TCHATIBALI | B11: =I6 -> 0 | C11: ='02-05-15'!C11+B11 -> 0 | D11: MAYO-GALKE | E11: =I11 -> 0 | F11: ='02-05-15'!F11+E11 -> 0 | H11: MAYO-GALKE | I11: 0
A12: GUIDER | B12: =I7 -> 0 | C12: ='02-05-15'!C12+B12 -> 0 | D12: TOUBOURO | E12: =I12 -> 0 | F12: ='02-05-15'!F12+E12 -> 0 | H12: TOUBOURO | I12: 0
A13: GAROUA | B13: =I8 -> 0 | C13: ='02-05-15'!C13+B13 -> 0 | D13: HOME | E13: =I13 -> 0 | F13: ='02-05-15'!F13+E13 -> 0 | H13: HOME | I13: 0
A15: TOTAL JOURNALIER = | C15: =SUM(B9:B13)+SUM(E9:E13) -> 0 | D15: CUMUL GENERAL = | F15: =SUM(C9:C13)+SUM(F9:F13) -> 0 | H15: JOURNEE | I15: 42127
H16: TRANSMISSION | I16: =I15+1 -> 42128
A20: Transmis le : | B20: =I16 -> 42128

Sheet 04-05-15
A1: SODECOTON
H2: TABLEAU DE SAISI
A3: PLUVIOMETRIE JOURNALIERE ET PAR PENTADE | H3: STATION | I3: RELEVES
H4: MAROUA | I4: 0
B5: JOURNEE DU : | D5: =I15 -> 42128 | H5: KAELE | I5: 0
H6: TCHATIBALI | I6: 0
A7: STATION | B7: RELEVES | D7: STATION | E7: RELEVES | H7: GUIDER | I7: 0
B8: JOURNALIER | C8: CUMUL | E8: JOURNALIER | F8: CUMUL | H8: GAROUA | I8: 0
A9: MAROUA | B9: =I4 -> 0 | C9: ='03-05-15'!C9+B9 -> 0 | D9: NGONG | E9: =I9 -> 0 | F9: ='03-05-15'!F9+E9 -> 0 | H9: NGONG | I9: 0
A10: KAELE | B10: =I5 -> 0 | C10: ='03-05-15'!C10+B10 -> 0 | D10: POLI | E10: =I10 -> 0 | F10: ='03-05-15'!F10+E10 -> 0 | H10: POLI | I10: 0
A11: TCHATIBALI | B11: =I6 -> 0 | C11: ='03-05-15'!C11+B11 -> 0 | D11: MAYO-GALKE | E11: =I11 -> 0 | F11: ='03-05-15'!F11+E11 -> 0 | H11: MAYO-GALKE | I11: 0
A12: GUIDER | B12: =I7 -> 0 | C12: ='03-05-15'!C12+B12 -> 0 | D12: TOUBOURO | E12: =I12 -> 0 | F12: ='03-05-15'!F12+E12 -> 0 | H12: TOUBOURO | I12: 0
A13: GAROUA | B13: =I8 -> 0 | C13: ='03-05-15'!C13+B13 -> 0 | D13: HOME | E13: =I13 -> 0 | F13: ='03-05-15'!F13+E13 -> 0 | H13: HOME | I13: 0
A15: TOTAL JOURNALIER = | C15: =SUM(B9:B13)+SUM(E9:E13) -> 0 | D15: CUMUL GENERAL = | F15: =SUM(C9:C13)+SUM(F9:F13) -> 0 | H15: JOURNEE | I15: 42128
H16: TRANSMISSION | I16: =I15+1 -> 42129
A20: Transmis le : | B20: =I16 -> 42129

Sheet 05-05-15
A1: SODECOTON
H2: TABLEAU DE SAISI
A3: PLUVIOMETRIE JOURNALIERE ET PAR PENTADE | H3: STATION | I3: RELEVES
H4: MAROUA | I4: 0
B5: JOURNEE DU : | D5: =I15 -> 42129 | H5: KAELE | I5: 0
H6: TCHATIBALI | I6: 0
A7: STATION | B7: RELEVES | D7: STATION | E7: RELEVES | H7: GUIDER | I7: 0
B8: JOURNALIER | C8: CUMUL | E8: JOURNALIER | F8: CUMUL | H8: GAROUA | I8: 0
A9: MAROUA | B9: =I4 -> 0 | C9: ='04-05-15'!C9+B9 -> 0 | D9: NGONG | E9: =I9 -> 0 | F9: ='04-05-15'!F9+E9 -> 0 | H9: NGONG | I9: 0
A10: KAELE | B10: =I5 -> 0 | C10: ='04-05-15'!C10+B10 -> 0 | D10: POLI | E10: =I10 -> 0 | F10: ='04-05-15'!F10+E10 -> 0 | H10: POLI | I10: 0
A11: TCHATIBALI | B11: =I6 -> 0 | C11: ='04-05-15'!C11+B11 -> 0 | D11: MAYO-GALKE | E11: =I11 -> 0 | F11: ='04-05-15'!F11+E11 -> 0 | H11: MAYO-GALKE | I11: 0
A12: GUIDER | B12: =I7 -> 0 | C12: ='04-05-15'!C12+B12 -> 0 | D12: TOUBOURO | E12: =I12 -> 0 | F12: ='04-05-15'!F12+E12 -> 0 | H12: TOUBOURO | I12: 0
A13: GAROUA | B13: =I8 -> 0 | C13: ='04-05-15'!C13+B13 -> 0 | D13: HOME | E13: =I13 -> 0 | F13: ='04-05-15'!F13+E13 -> 0 | H13: HOME | I13: 0
A15: TOTAL JOURNALIER = | C15: =SUM(B9:B13)+SUM(E9:E13) -> 0 | D15: CUMUL GENERAL = | F15: =SUM(C9:C13)+SUM(F9:F13) -> 0 | H15: JOURNEE | I15: 42129
H16: TRANSMISSION | I16: =I15+1 -> 42130
A20: Transmis le : | B20: =I16 -> 42130

Sheet 06-05-15
A1: SODECOTON
H2: TABLEAU DE SAISI
A3: PLUVIOMETRIE JOURNALIERE ET PAR PENTADE | H3: STATION | I3: RELEVES
H4: MAROUA | I4: 0
B5: JOURNEE DU : | D5: =I15 -> 42130 | H5: KAELE | I5: 0
H6: TCHATIBALI | I6: 0
A7: STATION | B7: RELEVES | D7: STATION | E7: RELEVES | H7: GUIDER | I7: 0
B8: JOURNALIER | C8: CUMUL | E8: JOURNALIER | F8: CUMUL | H8: GAROUA | I8: 0
A9: MAROUA | B9: =I4 -> 0 | C9: ='05-05-15'!C9+B9 -> 0 | D9: NGONG | E9: =I9 -> 0 | F9: ='05-05-15'!F9+E9 -> 0 | H9: NGONG | I9: 0
A10: KAELE | B10: =I5 -> 0 | C10: ='05-05-15'!C10+B10 -> 0 | D10: POLI | E10: =I10 -> 0 | F10: ='05-05-15'!F10+E10 -> 0 | H10: POLI | I10: 0
A11: TCHATIBALI | B11: =I6 -> 0 | C11: ='05-05-15'!C11+B11 -> 0 | D11: MAYO-GALKE | E11: =I11 -> 0 | F11: ='05-05-15'!F11+E11 -> 0 | H11: MAYO-GALKE | I11: 0
A12: GUIDER | B12: =I7 -> 0 | C12: ='05-05-15'!C12+B12 -> 0 | D12: TOUBOURO | E12: =I12 -> 0 | F12: ='05-05-15'!F12+E12 -> 0 | H12: TOUBOURO | I12: 0
A13: GAROUA | B13: =I8 -> 0 | C13: ='05-05-15'!C13+B13 -> 0 | D13: HOME | E13: =I13 -> 0 | F13: ='05-05-15'!F13+E13 -> 0 | H13: HOME | I13: 0
A15: TOTAL JOURNALIER = | C15: =SUM(B9:B13)+SUM(E9:E13) -> 0 | D15: CUMUL GENERAL = | F15: =SUM(C9:C13)+SUM(F9:F13) -> 0 | H15: JOURNEE | I15: 42130
H16: TRANSMISSION | I16: =I15+1 -> 42131
A20: Transmis le : | B20: =I16 -> 42131

Sheet 07-05-15
A1: SODECOTON
H2: TABLEAU DE SAISI
A3: PLUVIOMETRIE JOURNALIERE ET PAR PENTADE | H3: STATION | I3: RELEVES
H4: MAROUA | I4: 0
B5: JOURNEE DU : | D5: =I15 -> 42131 | H5: KAELE | I5: 0
H6: TCHATIBALI | I6: 0
A7: STATION | B7: RELEVES | D7: STATION | E7: RELEVES | H7: GUIDER | I7: 0
B8: JOURNALIER | C8: CUMUL | E8: JOURNALIER | F8: CUMUL | H8: GAROUA | I8: 0
A9: MAROUA | B9: =I4 -> 0 | C9: ='06-05-15'!C9+B9 -> 0 | D9: NGONG | E9: =I9 -> 0 | F9: ='06-05-15'!F9+E9 -> 0 | H9: NGONG | I9: 0
A10: KAELE | B10: =I5 -> 0 | C10: ='06-05-15'!C10+B10 -> 0 | D10: POLI | E10: =I10 -> 0 | F10: ='06-05-15'!F10+E10 -> 0 | H10: POLI | I10: 0
A11: TCHATIBALI | B11: =I6 -> 0 | C11: ='06-05-15'!C11+B11 -> 0 | D11: MAYO-GALKE | E11: =I11 -> 0 | F11: ='06-05-15'!F11+E11 -> 0 | H11: MAYO-GALKE | I11: 0
A12: GUIDER | B12: =I7 -> 0 | C12: ='06-05-15'!C12+B12 -> 0 | D12: TOUBOURO | E12: =I12 -> 0 | F12: ='06-05-15'!F12+E12 -> 0 | H12: TOUBOURO | I12: 0
A13: GAROUA | B13: =I8 -> 0 | C13: ='06-05-15'!C13+B13 -> 0 | D13: HOME | E13: =I13 -> 0 | F13: ='06-05-15'!F13+E13 -> 0 | H13: HOME | I13: 0
A15: TOTAL JOURNALIER = | C15: =SUM(B9:B13)+SUM(E9:E13) -> 0 | D15: CUMUL GENERAL = | F15: =SUM(C9:C13)+SUM(F9:F13) -> 0 | H15: JOURNEE | I15: 42131
H16: TRANSMISSION | I16: =I15+1 -> 42132
A20: Transmis le : | B20: =I16 -> 42132

Sheet 08-05-15
A1: SODECOTON
H2: TABLEAU DE SAISI
A3: PLUVIOMETRIE JOURNALIERE ET PAR PENTADE | H3: STATION | I3: RELEVES
H4: MAROUA | I4: 0
B5: JOURNEE DU : | D5: =I15 -> 42132 | H5: KAELE | I5: 0
H6: TCHATIBALI | I6: 0
A7: STATION | B7: RELEVES | D7: STATION | E7: RELEVES | H7: GUIDER | I7: 0
B8: JOURNALIER | C8: CUMUL | E8: JOURNALIER | F8: CUMUL | H8: GAROUA | I8: 0
A9: MAROUA | B9: =I4 -> 0 | C9: ='07-05-15'!C9+B9 -> 0 | D9: NGONG | E9: =I9 -> 0 | F9: ='07-05-15'!F9+E9 -> 0 | H9: NGONG | I9: 0
A10: KAELE | B10: =I5 -> 0 | C10: ='07-05-15'!C10+B10 -> 0 | D10: POLI | E10: =I10 -> 0 | F10: ='07-05-15'!F10+E10 -> 0 | H10: POLI | I10: 0
A11: TCHATIBALI | B11: =I6 -> 0 | C11: ='07-05-15'!C11+B11 -> 0 | D11: MAYO-GALKE | E11: =I11 -> 0 | F11: ='07-05-15'!F11+E11 -> 0 | H11: MAYO-GALKE | I11: 0
A12: GUIDER | B12: =I7 -> 0 | C12: ='07-05-15'!C12+B12 -> 0 | D12: TOUBOURO | E12: =I12 -> 0 | F12: ='07-05-15'!F12+E12 -> 0 | H12: TOUBOURO | I12: 0
A13: GAROUA | B13: =I8 -> 0 | C13: ='07-05-15'!C13+B13 -> 0 | D13: HOME | E13: =I13 -> 0 | F13: ='07-05-15'!F13+E13 -> 0 | H13: HOME | I13: 0
A15: TOTAL JOURNALIER = | C15: =SUM(B9:B13)+SUM(E9:E13) -> 0 | D15: CUMUL GENERAL = | F15: =SUM(C9:C13)+SUM(F9:F13) -> 0 | H15: JOURNEE | I15: 42132
H16: TRANSMISSION | I16: =I15+1 -> 42133
A20: Transmis le : | B20: =I16 -> 42133

Sheet 09-05-15
A1: SODECOTON
H2: TABLEAU DE SAISI
A3: PLUVIOMETRIE JOURNALIERE ET PAR PENTADE | H3: STATION | I3: RELEVES
H4: MAROUA | I4: 0
B5: JOURNEE DU : | D5: =I15 -> 42133 | H5: KAELE | I5: 0
H6: TCHATIBALI | I6: 0
A7: STATION | B7: RELEVES | D7: STATION | E7: RELEVES | H7: GUIDER | I7: 0
B8: JOURNALIER | C8: CUMUL | E8: JOURNALIER | F8: CUMUL | H8: GAROUA | I8: 0
A9: MAROUA | B9: =I4 -> 0 | C9: ='08-05-15'!C9+B9 -> 0 | D9: NGONG | E9: =I9 -> 0 | F9: ='08-05-15'!F9+E9 -> 0 | H9: NGONG | I9: 0
A10: KAELE | B10: =I5 -> 0 | C10: ='08-05-15'!C10+B10 -> 0 | D10: POLI | E10: =I10 -> 0 | F10: ='08-05-15'!F10+E10 -> 0 | H10: POLI | I10: 0
A11: TCHATIBALI | B11: =I6 -> 0 | C11: ='08-05-15'!C11+B11 -> 0 | D11: MAYO-GALKE | E11: =I11 -> 0 | F11: ='08-05-15'!F11+E11 -> 0 | H11: MAYO-GALKE | I11: 0
A12: GUIDER | B12: =I7 -> 0 | C12: ='08-05-15'!C12+B12 -> 0 | D12: TOUBOURO | E12: =I12 -> 0 | F12: ='08-05-15'!F12+E12 -> 0 | H12: TOUBOURO | I12: 0
A13: GAROUA | B13: =I8 -> 0 | C13: ='08-05-15'!C13+B13 -> 0 | D13: HOME | E13: =I13 -> 0 | F13: ='08-05-15'!F13+E13 -> 0 | H13: HOME | I13: 0
A15: TOTAL JOURNALIER = | C15: =SUM(B9:B13)+SUM(E9:E13) -> 0 | D15: CUMUL GENERAL = | F15: =SUM(C9:C13)+SUM(F9:F13) -> 0 | H15: JOURNEE | I15: 42133
H16: TRANSMISSION | I16: =I15+1 -> 42134
A20: Transmis le : | B20: =I16 -> 42134

Sheet 10-05-15
A1: SODECOTON
H2: TABLEAU DE SAISI
A3: PLUVIOMETRIE JOURNALIERE ET PAR PENTADE | H3: STATION | I3: RELEVES
H4: MAROUA | I4: 0
B5: JOURNEE DU : | D5: =I15 -> 42134 | H5: KAELE | I5: 0
H6: TCHATIBALI | I6: 0
A7: STATION | B7: RELEVES | D7: STATION | E7: RELEVES | H7: GUIDER | I7: 0
B8: JOURNALIER | C8: CUMUL | E8: JOURNALIER | F8: CUMUL | H8: GAROUA | I8: 0
