Workbook

Sheet PLUV_1
A1: SODECOTON
H2: JOURNEE | I2: 43914
A3: PLUVIOMETRIE JOURNALIERE ET PAR PENTADE
H4: TABLEAU DE SAISI
B5: JOURNEE DU : | D5: =I2 -> 43914 | H5: STATION | I5: RELEVES
H6: MAROUA | I6: 0
A7: STATION | B7: RELEVES | D7: STATION | E7: RELEVES | H7: KAELE | I7: 0
B8: JOURNALIER | C8: CUMUL | E8: JOURNALIER | F8: CUMUL | H8: TCHATIBALI | I8: 0
A9: MAROUA | B9: =I6 -> 0 | C9: =B9 -> 0 | D9: NGONG | E9: =I11 -> 0 | F9: =E9 -> 0 | H9: GUIDER | I9: 0
A10: KAELE | B10: =I7 -> 0 | C10: =B10 -> 0 | D10: POLI | E10: =I12 -> 5 | F10: =E10 -> 5 | H10: GAROUA | I10: 0
A11: TCHATIBALI | B11: =I8 -> 0 | C11: =B11 -> 0 | D11: MAYO-GALKE | E11: =I13 -> 2 | F11: =E11 -> 2 | H11: NGONG | I11: 0
A12: GUIDER | B12: =I9 -> 0 | C12: =B12 -> 0 | D12: TOUBORO | E12: =I16 -> 0 | F12: =E12 -> 0 | H12: POLI | I12: 5
A13: GAROUA | B13: =I10 -> 0 | C13: =B13 -> 0 | D13: HOME | E13: =I17 -> 1 | F13: =E13 -> 1 | H13: MAYO-GALKE | I13: 2
A15: TOTAL JOURNALIER = | C15: =SUM(B9:B13)+SUM(E9:E13) -> 8 | D15: CUMUL GENERAL = | F15: =SUM(C9:C13)+SUM(F9:F13) -> 8
H16: TOUBORO | I16: 0
H17: HOME | I17: 1
A18: Transmis le : | B18: =IFERROR(+I2+1,0) -> 43915

Sheet PLUV_2
A1: SODECOTON
H2: JOURNEE | I2: 43915
A3: PLUVIOMETRIE JOURNALIERE ET PAR PENTADE
H4: TABLEAU DE SAISI
B5: JOURNEE DU : | D5: =I2 -> 43915 | H5: STATION | I5: RELEVES
H6: MAROUA | I6: 17
A7: STATION | B7: RELEVES | D7: STATION | E7: RELEVES | H7: KAELE | I7: 1
B8: JOURNALIER | C8: CUMUL | E8: JOURNALIER | F8: CUMUL | H8: TCHATIBALI | I8: 3
A9: MAROUA | B9: =I6 -> 17 | C9: =PLUV_1!C9+B9 -> 17 | D9: NGONG | E9: =I11 -> 0 | F9: =PLUV_1!F9+E9 -> 0 | H9: GUIDER | I9: 0
A10: KAELE | B10: =I7 -> 1 | C10: =PLUV_1!C10+B10 -> 1 | D10: POLI | E10: =I12 -> 0 | F10: =PLUV_1!F10+E10 -> 5 | H10: GAROUA | I10: 0
A11: TCHATIBALI | B11: =I8 -> 3 | C11: =PLUV_1!C11+B11 -> 3 | D11: MAYO-GALKE | E11: =I13 -> 0 | F11: =PLUV_1!F11+E11 -> 2 | H11: NGONG | I11: 0
A12: GUIDER | B12: =I9 -> 0 | C12: =PLUV_1!C12+B12 -> 0 | D12: TOUBORO | E12: =I16 -> 0 | F12: =PLUV_1!F12+E12 -> 0 | H12: POLI | I12: 0
A13: GAROUA | B13: =I10 -> 0 | C13: =PLUV_1!C13+B13 -> 0 | D13: HOME | E13: =I17 -> 2 | F13: =PLUV_1!F13+E13 -> 3 | H13: MAYO-GALKE | I13: 0
A15: TOTAL JOURNALIER = | C15: =SUM(B9:B13)+SUM(E9:E13) -> 23 | D15: CUMUL GENERAL = | F15: =SUM(C9:C13)+SUM(F9:F13) -> 31
H16: TOUBORO | I16: 0
H17: HOME | I17: 2
A18: Transmis le : | B18: =IFERROR(+I2+1,0) -> 43916

Sheet PLUV_3
A1: SODECOTON
H2: JOURNEE | I2: 43916
A3: PLUVIOMETRIE JOURNALIERE ET PAR PENTADE
H4: TABLEAU DE SAISI
B5: JOURNEE DU : | D5: =I2 -> 43916 | H5: STATION | I5: RELEVES
H6: MAROUA | I6: 0
A7: STATION | B7: RELEVES | D7: STATION | E7: RELEVES | H7: KAELE | I7: 0
B8: JOURNALIER | C8: CUMUL | E8: JOURNALIER | F8: CUMUL | H8: TCHATIBALI | I8: 0
A9: MAROUA | B9: =I6 -> 0 | C9: =PLUV_2!C9+B9 -> 17 | D9: NGONG | E9: =I11 -> 0 | F9: =PLUV_2!F9+E9 -> 0 | H9: GUIDER | I9: 0
A10: KAELE | B10: =I7 -> 0 | C10: =PLUV_2!C10+B10 -> 1 | D10: POLI | E10: =I12 -> 0 | F10: =PLUV_2!F10+E10 -> 5 | H10: GAROUA | I10: 0
A11: TCHATIBALI | B11: =I8 -> 0 | C11: =PLUV_2!C11+B11 -> 3 | D11: MAYO-GALKE | E11: =I13 -> 11 | F11: =PLUV_2!F11+E11 -> 13 | H11: NGONG | I11: 0
A12: GUIDER | B12: =I9 -> 0 | C12: =PLUV_2!C12+B12 -> 0 | D12: TOUBORO | E12: =I16 -> 1 | F12: =PLUV_2!F12+E12 -> 1 | H12: POLI | I12: 0
A13: GAROUA | B13: =I10 -> 0 | C13: =PLUV_2!C13+B13 -> 0 | D13: HOME | E13: =I17 -> 0 | F13: =PLUV_2!F13+E13 -> 3 | H13: MAYO-GALKE | I13: 11
A15: TOTAL JOURNALIER = | C15: =SUM(B9:B13)+SUM(E9:E13) -> 12 | D15: CUMUL GENERAL = | F15: =SUM(C9:C13)+SUM(F9:F13) -> 43
H16: TOUBORO | I16: 1
H17: HOME | I17: 0
A18: Transmis le : | B18: =IFERROR(+I2+1,0) -> 43917

Sheet PLUV_4
A1: SODECOTON
H2: JOURNEE | I2: 43921
A3: PLUVIOMETRIE JOURNALIERE ET PAR PENTADE
H4: TABLEAU DE SAISI
B5: JOURNEE DU : | D5: =I2 -> 43921 | H5: STATION | I5: RELEVES
H6: MAROUA | I6: 0
A7: STATION | B7: RELEVES | D7: STATION | E7: RELEVES | H7: KAELE | I7: 0
B8: JOURNALIER | C8: CUMUL | E8: JOURNALIER | F8: CUMUL | H8: TCHATIBALI | I8: 0
A9: MAROUA | B9: =I6 -> 0 | C9: =PLUV_3!C9+B9 -> 17 | D9: NGONG | E9: =I11 -> 0 | F9: =PLUV_3!F9+E9 -> 0 | H9: GUIDER | I9: 0
A10: KAELE | B10: =I7 -> 0 | C10: =PLUV_3!C10+B10 -> 1 | D10: POLI | E10: =I12 -> 0 | F10: =PLUV_3!F10+E10 -> 5 | H10: GAROUA | I10: 0
A11: TCHATIBALI | B11: =I8 -> 0 | C11: =PLUV_3!C11+B11 -> 3 | D11: MAYO-GALKE | E11: =I13 -> 0 | F11: =PLUV_3!F11+E11 -> 13 | H11: NGONG | I11: 0
A12: GUIDER | B12: =I9 -> 0 | C12: =PLUV_3!C12+B12 -> 0 | D12: TOUBORO | E12: =I16 -> 0 | F12: =PLUV_3!F12+E12 -> 1 | H12: POLI | I12: 0
A13: GAROUA | B13: =I10 -> 0 | C13: =PLUV_3!C13+B13 -> 0 | D13: HOME | E13: =I17 -> 2 | F13: =PLUV_3!F13+E13 -> 5 | H13: MAYO-GALKE | I13: 0
A15: TOTAL JOURNALIER = | C15: =SUM(B9:B13)+SUM(E9:E13) -> 2 | D15: CUMUL GENERAL = | F15: =SUM(C9:C13)+SUM(F9:F13) -> 45
H16: TOUBORO | I16: 0
H17: HOME | I17: 2
A18: Transmis le : | B18: =IFERROR(+I2+1,0) -> 43922

Sheet PLUV_5
A1: SODECOTON
H2: JOURNEE | I2: 43924
A3: PLUVIOMETRIE JOURNALIERE ET PAR PENTADE
H4: TABLEAU DE SAISI
B5: JOURNEE DU : | D5: =I2 -> 43924 | H5: STATION | I5: RELEVES
H6: MAROUA | I6: 0
A7: STATION | B7: RELEVES | D7: STATION | E7: RELEVES | H7: KAELE | I7: 0
B8: JOURNALIER | C8: CUMUL | E8: JOURNALIER | F8: CUMUL | H8: TCHATIBALI | I8: 0
A9: MAROUA | B9: =I6 -> 0 | C9: =PLUV_4!C9+B9 -> 17 | D9: NGONG | E9: =I11 -> 0 | F9: =PLUV_4!F9+E9 -> 0 | H9: GUIDER | I9: 0
A10: KAELE | B10: =I7 -> 0 | C10: =PLUV_4!C10+B10 -> 1 | D10: POLI | E10: =I12 -> 0 | F10: =PLUV_4!F10+E10 -> 5 | H10: GAROUA | I10: 0
A11: TCHATIBALI | B11: =I8 -> 0 | C11: =PLUV_4!C11+B11 -> 3 | D11: MAYO-GALKE | E11: =I13 -> 0 | F11: =PLUV_4!F11+E11 -> 13 | H11: NGONG | I11: 0
A12: GUIDER | B12: =I9 -> 0 | C12: =PLUV_4!C12+B12 -> 0 | D12: TOUBORO | E12: =I16 -> 1 | F12: =PLUV_4!F12+E12 -> 2 | H12: POLI | I12: 0
A13: GAROUA | B13: =I10 -> 0 | C13: =PLUV_4!C13+B13 -> 0 | D13: HOME | E13: =I17 -> 2 | F13: =PLUV_4!F13+E13 -> 7 | H13: MAYO-GALKE | I13: 0
A15: TOTAL JOURNALIER = | C15: =SUM(B9:B13)+SUM(E9:E13) -> 3 | D15: CUMUL GENERAL = | F15: =SUM(C9:C13)+SUM(F9:F13) -> 48
H16: TOUBORO | I16: 1
H17: HOME | I17: 2
A18: Transmis le : | B18: =IFERROR(+I2+1,0) -> 43925

Sheet PLUV_6
A1: SODECOTON
H2: JOURNEE | I2: 43926
A3: PLUVIOMETRIE JOURNALIERE ET PAR PENTADE
H4: TABLEAU DE SAISI
B5: JOURNEE DU : | D5: =I2 -> 43926 | H5: STATION | I5: RELEVES
H6: MAROUA | I6: 0
A7: STATION | B7: RELEVES | D7: STATION | E7: RELEVES | H7: KAELE | I7: 0
B8: JOURNALIER | C8: CUMUL | E8: JOURNALIER | F8: CUMUL | H8: TCHATIBALI | I8: 0
A9: MAROUA | B9: =I6 -> 0 | C9: =PLUV_5!C9+B9 -> 17 | D9: NGONG | E9: =I11 -> 3 | F9: =PLUV_5!F9+E9 -> 3 | H9: GUIDER | I9: 0
A10: KAELE | B10: =I7 -> 0 | C10: =PLUV_5!C10+B10 -> 1 | D10: POLI | E10: =I12 -> 19 | F10: =PLUV_5!F10+E10 -> 24 | H10: GAROUA | I10: 0
A11: TCHATIBALI | B11: =I8 -> 0 | C11: =PLUV_5!C11+B11 -> 3 | D11: MAYO-GALKE | E11: =I13 -> 1 | F11: =PLUV_5!F11+E11 -> 14 | H11: NGONG | I11: 3
A12: GUIDER | B12: =I9 -> 0 | C12: =PLUV_5!C12+B12 -> 0 | D12: TOUBORO | E12: =I16 -> 0 | F12: =PLUV_5!F12+E12 -> 2 | H12: POLI | I12: 19
A13: GAROUA | B13: =I10 -> 0 | C13: =PLUV_5!C13+B13 -> 0 | D13: HOME | E13: =I17 -> 0 | F13: =PLUV_5!F13+E13 -> 7 | H13: MAYO-GALKE | I13: 1
A15: TOTAL JOURNALIER = | C15: =SUM(B9:B13)+SUM(E9:E13) -> 23 | D15: CUMUL GENERAL = | F15: =SUM(C9:C13)+SUM(F9:F13) -> 71
H16: TOUBORO | I16: 0
H17: HOME | I17: 0
A18: Transmis le : | B18: =IFERROR(+I2+1,0) -> 43927

Sheet PLUV_7
A1: SODECOTON
H2: JOURNEE | I2: 43927
A3: PLUVIOMETRIE JOURNALIERE ET PAR PENTADE
H4: TABLEAU DE SAISI
B5: JOURNEE DU : | D5: =I2 -> 43927 | H5: STATION | I5: RELEVES
H6: MAROUA | I6: 1
A7: STATION | B7: RELEVES | D7: STATION | E7: RELEVES | H7: KAELE | I7: 0
B8: JOURNALIER | C8: CUMUL | E8: JOURNALIER | F8: CUMUL | H8: TCHATIBALI | I8: 0
A9: MAROUA | B9: =I6 -> 1 | C9: =PLUV_6!C9+B9 -> 18 | D9: NGONG | E9: =I11 -> 0 | F9: =PLUV_6!F9+E9 -> 3 | H9: GUIDER | I9: 0
A10: KAELE | B10: =I7 -> 0 | C10: =PLUV_6!C10+B10 -> 1 | D10: POLI | E10: =I12 -> 0 | F10: =PLUV_6!F10+E10 -> 24 | H10: GAROUA | I10: 0
A11: TCHATIBALI | B11: =I8 -> 0 | C11: =PLUV_6!C11+B11 -> 3 | D11: MAYO-GALKE | E11: =I13 -> 26 | F11: =PLUV_6!F11+E11 -> 40 | H11: NGONG | I11: 0
A12: GUIDER | B12: =I9 -> 0 | C12: =PLUV_6!C12+B12 -> 0 | D12: TOUBORO | E12: =I16 -> 20 | F12: =PLUV_6!F12+E12 -> 22 | H12: POLI | I12: 0
A13: GAROUA | B13: =I10 -> 0 | C13: =PLUV_6!C13+B13 -> 0 | D13: HOME | E13: =I17 -> 8 | F13: =PLUV_6!F13+E13 -> 15 | H13: MAYO-GALKE | I13: 26
A15: TOTAL JOURNALIER = | C15: =SUM(B9:B13)+SUM(E9:E13) -> 55 | D15: CUMUL GENERAL = | F15: =SUM(C9:C13)+SUM(F9:F13) -> 126
H16: TOUBORO | I16: 20
H17: HOME | I17: 8
A18: Transmis le : | B18: =IFERROR(+I2+1,0) -> 43928

Sheet PLUV_8
A1: SODECOTON
H2: JOURNEE | I2: 43929
A3: PLUVIOMETRIE JOURNALIERE ET PAR PENTADE
H4: TABLEAU DE SAISI
B5: JOURNEE DU : | D5: =I2 -> 43929 | H5: STATION | I5: RELEVES
H6: MAROUA | I6: 0
A7: STATION | B7: RELEVES | D7: STATION | E7: RELEVES | H7: KAELE | I7: 0
B8: JOURNALIER | C8: CUMUL | E8: JOURNALIER | F8: CUMUL | H8: TCHATIBALI | I8: 0
A9: MAROUA | B9: =I6 -> 0 | C9: =PLUV_7!C9+B9 -> 18 | D9: NGONG | E9: =I11 -> 0 | F9: =PLUV_7!F9+E9 -> 3 | H9: GUIDER | I9: 0
A10: KAELE | B10: =I7 -> 0 | C10: =PLUV_7!C10+B10 -> 1 | D10: POLI | E10: =I12 -> 0 | F10: =PLUV_7!F10+E10 -> 24 | H10: GAROUA | I10: 0
A11: TCHATIBALI | B11: =I8 -> 0 | C11: =PLUV_7!C11+B11 -> 3 | D11: MAYO-GALKE | E11: =I13 -> 7 | F11: =PLUV_7!F11+E11 -> 47 | H11: NGONG | I11: 0
A12: GUIDER | B12: =I9 -> 0 | C12: =PLUV_7!C12+B12 -> 0 | D12: TOUBORO | E12: =I16 -> 6 | F12: =PLUV_7!F12+E12 -> 28 | H12: POLI | I12: 0
A13: GAROUA | B13: =I10 -> 0 | C13: =PLUV_7!C13+B13 -> 0 | D13: HOME | E13: =I17 -> 35 | F13: =PLUV_7!F13+E13 -> 50 | H13: MAYO-GALKE | I13: 7
A15: TOTAL JOURNALIER = | C15: =SUM(B9:B13)+SUM(E9:E13) -> 48 | D15: CUMUL GENERAL = | F15: =SUM(C9:C13)+SUM(F9:F13) -> 174
H16: TOUBORO | I16: 6
H17: HOME | I17: 35
A18: Transmis le : | B18: =IFERROR(+I2+1,0) -> 43930

Sheet PLUV_9
A1: SODECOTON
H2: JOURNEE | I2: 43930
A3: PLUVIOMETRIE JOURNALIERE ET PAR PENTADE
H4: TABLEAU DE SAISI
B5: JOURNEE DU : | D5: =I2 -> 43930 | H5: STATION | I5: RELEVES
H6: MAROUA | I6: 0
A7: STATION | B7: RELEVES | D7: STATION | E7: RELEVES | H7: KAELE | I7: 0
B8: JOURNALIER | C8: CUMUL | E8: JOURNALIER | F8: CUMUL | H8: TCHATIBALI | I8: 0
A9: MAROUA | B9: =I6 -> 0 | C9: =PLUV_8!C9+B9 -> 18 | D9: NGONG | E9: =I11 -> 0 | F9: =PLUV_8!F9+E9 -> 3 | H9: GUIDER | I9: 0
A10: KAELE | B10: =I7 -> 0 | C10: =PLUV_8!C10+B10 -> 1 | D10: POLI | E10: =I12 -> 0 | F10: =PLUV_8!F10+E10 -> 24 | H10: GAROUA | I10: 0
A11: TCHATIBALI | B11: =I8 -> 0 | C11: =PLUV_8!C11+B11 -> 3 | D11: MAYO-GALKE | E11: =I13 -> 0 | F11: =PLUV_8!F11+E11 -> 47 | H11: NGONG | I11: 0
A12: GUIDER | B12: =I9 -> 0 | C12: =PLUV_8!C12+B12 -> 0 | D12: TOUBORO | E12: =I16 -> 0 | F12: =PLUV_8!F12+E12 -> 28 | H12: POLI | I12: 0
A13: GAROUA | B13: =I10 -> 0 | C13: =PLUV_8!C13+B13 -> 0 | D13: HOME | E13: =I17 -> 1 | F13: =PLUV_8!F13+E13 -> 51 | H13: MAYO-GALKE | I13: 0
A15: TOTAL JOURNALIER = | C15: =SUM(B9:B13)+SUM(E9:E13) -> 1 | D15: CUMUL GENERAL = | F15: =SUM(C9:C13)+SUM(F9:F13) -> 175
H16: TOUBORO | I16: 0
H17: HOME | I17: 1
A18: Transmis le : | B18: =IFERROR(+I2+1,0) -> 43931

Sheet PLUV_10
A1: SODECOTON
H2: JOURNEE | I2: 43931
A3: PLUVIOMETRIE JOURNALIERE ET PAR PENTADE
H4: TABLEAU DE SAISI
B5: JOURNEE DU : | D5: =I2 -> 43931 | H5: STATION | I5: RELEVES
H6: MAROUA | I6: 0
A7: STATION | B7: RELEVES | D7: STATION | E7: RELEVES | H7: KAELE | I7: 0
B8: JOURNALIER | C8: CUMUL | E8: JOURNALIER | F8: CUMUL | H8: TCHATIBALI | I8: 0
A9: MAROUA | B9: =I6 -> 0 | C9: =PLUV_9!C9+B9 -> 18 | D9: NGONG | E9: =I11 -> 0 | F9: =PLUV_9!F9+E9 -> 3 | H9: GUIDER | I9: 0
A10: KAELE | B10: =I7 -> 0 | C10: =PLUV_9!C10+B10 -> 1 | D10: POLI | E10: =I12 -> 0 | F10: =PLUV_9!F10+E10 -> 24 | H10: GAROUA | I10: 0
A11: TCHATIBALI | B11: =I8 -> 0 | C11: =PLUV_9!C11+B11 -> 3 | D11: MAYO-GALKE | E11: =I13 -> 0 | F11: =PLUV_9!F11+E11 -> 47 | H11: NGONG | I11: 0
A12: GUIDER | B12: =I9 -> 0 | C12: =PLUV_9!C12+B12 -> 0 | D12: TOUBORO | E12: =I16 -> 3 | F12: =PLUV_9!F12+E12 -> 31 | H12: POLI | I12: 0
A13: GAROUA | B13: =I10 -> 0 | C13: =PLUV_9!C13+B13 -> 0 | D13: HOME | E13: =I17 -> 3 | F13: =PLUV_9!F13+E13 -> 54 | H13: MAYO-GALKE | I13: 0
A15: TOTAL JOURNALIER = | C15: =SUM(B9:B13)+SUM(E9:E13) -> 6 | D15: CUMUL GENERAL = | F15: =SUM(C9:C13)+SUM(F9:F13) -> 181
H16: TOUBORO | I16: 3
H17: HOME | I17: 3
A18: Transmis le : | B18: =IFERROR(+I2+1,0) -> 43932

Sheet PLUV_11
A1: SODECOTON
H2: JOURNEE | I2: 43932
A3: PLUVIOMETRIE JOURNALIERE ET PAR PENTADE
H4: TABLEAU DE SAISI
B5: JOURNEE DU : | D5: =I2 -> 43932 | H5: STATION | I5: RELEVES
H6: MAROUA | I6: 0
A7: STATION | B7: RELEVES | D7: STATION | E7: RELEVES | H7: KAELE | I7: 0
B8: JOURNALIER | C8: CUMUL | E8: JOURNALIER | F8: CUMUL | H8: TCHATIBALI | I8: 0
A9: MAROUA | B9: =I6 -> 0 | C9: =PLUV_10!C9+B9 -> 18 | D9: NGONG | E9: =I11 -> 0 | F9: =PLUV_10!F9+E9 -> 3 | H9: GUIDER | I9: 0
A10: KAELE | B10: =I7 -> 0 | C10: =PLUV_10!C10+B10 -> 1 | D10: POLI | E10: =I12 -> 0 | F10: =PLUV_10!F10+E10 -> 24 | H10: GAROUA | I10: 0
A11: TCHATIBALI | B11: =I8 -> 0 | C11: =PLUV_10!C11+B11 -> 3 | D11: MAYO-GALKE | E11: =I13 -> 0 | F11: =PLUV_10!F11+E11 -> 47 | H11: NGONG | I11: 0
A12: GUIDER | B12: =I9 -> 0 | C12: =PLUV_10!C12+B12 -> 0 | D12: TOUBORO | E12: =I16 -> 0 | F12: =PLUV_10!F12+E12 -> 31 | H12: POLI | I12: 0
A13: GAROUA | B13: =I10 -> 0 | C13: =PLUV_10!C13+B13 -> 0 | D13: HOME | E13: =I17 -> 1 | F13: =PLUV_10!F13+E13 -> 55 | H13: MAYO-GALKE | I13: 0
A15: TOTAL JOURNALIER = | C15: =SUM(B9:B13)+SUM(E9:E13) -> 1 | D15: CUMUL GENERAL = | F15: =SUM(C9:C13)+SUM(F9:F13) -> 182
H16: TOUBORO | I16: 0
H17: HOME | I17: 1
A18: Transmis le : | B18: =IFERROR(+I2+1,0) -> 43933

Sheet PLUV_12
A1: SODECOTON
H2: JOURNEE | I2: 43935
A3: PLUVIOMETRIE JOURNALIERE ET PAR PENTADE
H4: TABLEAU DE SAISI
B5: JOURNEE DU : | D5: =I2 -> 43935 | H5: STATION | I5: RELEVES
H6: MAROUA | I6: 0
A7: STATION | B7: RELEVES | D7: STATION | E7: RELEVES | H7: KAELE | I7: 0
B8: JOURNALIER | C8: CUMUL | E8: JOURNALIER | F8: CUMUL | H8: TCHATIBALI | I8: 0
A9: MAROUA | B9: =I6 -> 0 | C9: =PLUV_11!C9+B9 -> 18 | D9: NGONG | E9: =I11 -> 0 | F9: =PLUV_11!F9+E9 -> 3 | H9: GUIDER | I9: 0
A10: KAELE | B10: =I7 -> 0 | C10: =PLUV_11!C10+B10 -> 1 | D10: POLI | E10: =I12 -> 0 | F10: =PLUV_11!F10+E10 -> 24 | H10: GAROUA | I10: 0
A11: TCHATIBALI | B11: =I8 -> 0 | C11: =PLUV_11!C11+B11 -> 3 | D11: MAYO-GALKE | E11: =I13 -> 0 | F11: =PLUV_11!F11+E11 -> 47 | H11: NGONG | I11: 0
A12: GUIDER | B12: =I9 -> 0 | C12: =PLUV_11!C12+B12 -> 0 | D12: TOUBORO | E12: =I16 -> 0 | F12: =PLUV_11!F12+E12 -> 31 | H12: POLI | I12: 0
A13: GAROUA | B13: =I10 -> 0 | C13: =PLUV_11!C13+B13 -> 0 | D13: HOME | E13: =I17 -> 1 | F13: =PLUV_11!F13+E13 -> 56 | H13: MAYO-GALKE | I13: 0
A15: TOTAL JOURNALIER = | C15: =SUM(B9:B13)+SUM(E9:E13) -> 1 | D15: CUMUL GENERAL = | F15: =SUM(C9:C13)+SUM(F9:F13) -> 183
H16: TOUBORO | I16: 0
H17: HOME | I17: 1
A18: Transmis le : | B18: =IFERROR(+I2+1,0) -> 43936

Sheet PLUV_13
A1: SODECOTON
H2: JOURNEE | I2: 43940
A3: PLUVIOMETRIE JOURNALIERE ET PAR PENTADE
H4: TABLEAU DE SAISI
B5: JOURNEE DU : | D5: =I2 -> 43940 | H5: STATION | I5: RELEVES
H6: MAROUA | I6: 0
A7: STATION | B7: RELEVES | D7: STATION | E7: RELEVES | H7: KAELE | I7: 0
B8: JOURNALIER | C8: CUMUL | E8: JOURNALIER | F8: CUMUL | H8: TCHATIBALI | I8: 0
A9: MAROUA | B9: =I6 -> 0 | C9: =PLUV_12!C9+B9 -> 18 | D9: NGONG | E9: =I11 -> 0 | F9: =PLUV_12!F9+E9 -> 3 | H9: GUIDER | I9: 0
A10: KAELE | B10: =I7 -> 0 | C10: =PLUV_12!C10+B10 -> 1 | D10: POLI | E10: =I12 -> 0 | F10: =PLUV_12!F10+E10 -> 24 | H10: GAROUA | I10: 0
A11: TCHATIBALI | B11: =I8 -> 0 | C11: =PLUV_12!C11+B11 -> 3 | D11: MAYO-GALKE | E11: =I13 -> 0 | F11: =PLUV_12!F11+E11 -> 47 | H11: NGONG | I11: 0
A12: GUIDER | B12: =I9 -> 0 | C12: =PLUV_12!C12+B12 -> 0 | D12: TOUBORO | E12: =I16 -> 47 | F12: =PLUV_12!F12+E12 -> 78 | H12: POLI | I12: 0
A13: GAROUA | B13: =I10 -> 0 | C13: =PLUV_12!C13+B13 -> 0 | D13: HOME | E13: =I17 -> 0 | F13: =PLUV_12!F13+E13 -> 56 | H13: MAYO-GALKE | I13: 0
A15: TOTAL JOURNALIER = | C15: =SUM(B9:B13)+SUM(E9:E13) -> 47 | D15: CUMUL GENERAL = | F15: =SUM(C9:C13)+SUM(F9:F13) -> 230
H16: TOUBORO | I16: 47
H17: HOME | I17: 0
A18: Transmis le : | B18: =IFERROR(+I2+1,0) -> 43941

Sheet PLUV_14
A1: SODECOTON
H2: JOURNEE | I2: 43941
A3: PLUVIOMETRIE JOURNALIERE ET PAR PENTADE
H4: TABLEAU DE SAISI
B5: JOURNEE DU : | D5: =I2 -> 43941 | H5: STATION | I5: RELEVES
H6: MAROUA | I6: 0
A7: STATION | B7: RELEVES | D7: STATION | E7: RELEVES | H7: KAELE | I7: 0
B8: JOURNALIER | C8: CUMUL | E8: JOURNALIER | F8: CUMUL | H8: TCHATIBALI | I8: 0
A9: MAROUA | B9: =I6 -> 0 | C9: =PLUV_13!C9+B9 -> 18 | D9: NGONG | E9: =I11 -> 0 | F9: =PLUV_13!F9+E9 -> 3 | H9: GUIDER | I9: 0
A10: KAELE | B10: =I7 -> 0 | C10: =PLUV_13!C10+B10 -> 1 | D10: POLI | E10: =I12 -> 0 | F10: =PLUV_13!F10+E10 -> 24 | H10: GAROUA | I10: 0
A11: TCHATIBALI | B11: =I8 -> 0 | C11: =PLUV_13!C11+B11 -> 3 | D11: MAYO-GALKE | E11: =I13 -> 0 | F11: =PLUV_13!F11+E11 -> 47 | H11: NGONG | I11: 0
A12: GUIDER | B12: =I9 -> 0 | C12: =PLUV_13!C12+B12 -> 0 | D12: TOUBORO | E12: =I16 -> 7 | F12: =PLUV_13!F12+E12 -> 85 | H12: POLI | I12: 0
A13: GAROUA | B13: =I10 -> 0 | C13: =PLUV_13!C13+B13 -> 0 | D13: HOME | E13: =I17 -> 0 | F13: =PLUV_13!F13+E13 -> 56 | H13: MAYO-GALKE | I13: 0
A15: TOTAL JOURNALIER = | C15: =SUM(B9:B13)+SUM(E9:E13) -> 7 | D15: CUMUL GENERAL = | F15: =SUM(C9:C13)+SUM(F9:F13) -> 237
H16: TOUBORO | I16: 7
H17: HOME | I17: 0
A18: Transmis le : | B18: =IFERROR(+I2+1,0) -> 43942

Sheet PLUV_15
A1: SODECOTON
H2: JOURNEE | I2: 43942
A3: PLUVIOMETRIE JOURNALIERE ET PAR PENTADE
H4: TABLEAU DE SAISI
B5: JOURNEE DU : | D5: =I2 -> 43942 | H5: STATION | I5: RELEVES
H6: MAROUA | I6: 0
A7: STATION | B7: RELEVES | D7: STATION | E7: RELEVES | H7: KAELE | I7: 0
B8: JOURNALIER | C8: CUMUL | E8: JOURNALIER | F8: CUMUL | H8: TCHATIBALI | I8: 0
A9: MAROUA | B9: =I6 -> 0 | C9: =PLUV_14!C9+B9 -> 18 | D9: NGONG | E9: =I11 -> 0 | F9: =PLUV_14!F9+E9 -> 3 | H9: GUIDER | I9: 0
A10: KAELE | B10: =I7 -> 0 | C10: =PLUV_14!C10+B10 -> 1 | D10: POLI | E10: =I12 -> 0 | F10: =PLUV_14!F10+E10 -> 24 | H10: GAROUA | I10: 0
A11: TCHATIBALI | B11: =I8 -> 0 | C11: =PLUV_14!C11+B11 -> 3 | D11: MAYO-GALKE | E11: =I13 -> 0 | F11: =PLUV_14!F11+E11 -> 47 | H11: NGONG | I11: 0
A12: GUIDER | B12: =I9 -> 0 | C12: =PLUV_14!C12+B12 -> 0 | D12: TOUBORO | E12: =I16 -> 0 | F12: =PLUV_14!F12+E12 -> 85 | H12: POLI | I12: 0
A13: GAROUA | B13: =I10 -> 0 | C13: =PLUV_14!C13+B13 -> 0 | D13: HOME | E13: =I17 -> 1 | F13: =PLUV_14!F13+E13 -> 57 | H13: MAYO-GALKE | I13: 0
A15: TOTAL JOURNALIER = | C15: =SUM(B9:B13)+SUM(E9:E13) -> 1 | D15: CUMUL GENERAL = | F15: =SUM(C9:C13)+SUM(F9:F13) -> 238
H16: TOUBORO | I16: 0
H17: HOME | I17: 1
A18: Transmis le : | B18: =IFERROR(+I2+1,0) -> 43943

Sheet PLUV_16
A1: SODECOTON
H2: JOURNEE | I2: 43944
A3: PLUVIOMETRIE JOURNALIERE ET PAR PENTADE
H4: TABLEAU DE SAISI
B5: JOURNEE DU : | D5: =I2 -> 43944 | H5: STATION | I5: RELEVES
H6: MAROUA | I6: 0
A7: STATION | B7: RELEVES | D7: STATION | E7: RELEVES | H7: KAELE | I7: 0
B8: JOURNALIER | C8: CUMUL | E8: JOURNALIER | F8: CUMUL | H8: TCHATIBALI | I8: 0
A9: MAROUA | B9: =I6 -> 0 | C9: =PLUV_15!C9+B9 -> 18 | D9: NGONG | E9: =I11 -> 0 | F9: =PLUV_15!F9+E9 -> 3 | H9: GUIDER | I9: 0
A10: KAELE | B10: =I7 -> 0 | C10: =PLUV_15!C10+B10 -> 1 | D10: POLI | E10: =I12 -> 0 | F10: =PLUV_15!F10+E10 -> 24 | H10: GAROUA | I10: 0
A11: TCHATIBALI | B11: =I8 -> 0 | C11: =PLUV_15!C11+B11 -> 3 | D11: MAYO-GALKE | E11: =I13 -> 10 | F11: =PLUV_15!F11+E11 -> 57 | H11: NGONG | I11: 0
A12: GUIDER | B12: =I9 -> 0 | C12: =PLUV_15!C12+B12 -> 0 | D12: TOUBORO | E12: =I16 -> 14 | F12: =PLUV_15!F12+E12 -> 99 | H12: POLI | I12: 0
A13: GAROUA | B13: =I10 -> 0 | C13: =PLUV_15!C13+B13 -> 0 | D13: HOME | E13: =I17 -> 2 | F13: =PLUV_15!F13+E13 -> 59 | H13: MAYO-GALKE | I13: 10
A15: TOTAL JOURNALIER = | C15: =SUM(B9:B13)+SUM(E9:E13) -> 26 | D15: CUMUL GENERAL = | F15: =SUM(C9:C13)+SUM(F9:F13) -> 264
H16: TOUBORO | I16: 14
H17: HOME | I17: 2
A18: Transmis le : | B18: =IFERROR(+I2+1,0) -> 43945

Sheet PLUV_17
A1: SODECOTON
H2: JOURNEE | I2: 43945
A3: PLUVIOMETRIE JOURNALIERE ET PAR PENTADE
H4: TABLEAU DE SAISI
B5: JOURNEE DU : | D5: =I2 -> 43945 | H5: STATION | I5: RELEVES
H6: MAROUA | I6: 0
A7: STATION | B7: RELEVES | D7: STATION | E7: RELEVES | H7: KAELE | I7: 0
B8: JOURNALIER | C8: CUMUL | E8: JOURNALIER | F8: CUMUL | H8: TCHATIBALI | I8: 4
A9: MAROUA | B9: =I6 -> 0 | C9: =PLUV_16!C9+B9 -> 18 | D9: NGONG | E9: =I11 -> 1 | F9: =PLUV_16!F9+E9 -> 4 | H9: GUIDER | I9: 3
A10: KAELE | B10: =I7 -> 0 | C10: =PLUV_16!C10+B10 -> 1 | D10: POLI | E10: =I12 -> 28 | F10: =PLUV_16!F10+E10 -> 52 | H10: GAROUA | I10: 0
A11: TCHATIBALI | B11: =I8 -> 4 | C11: =PLUV_16!C11+B11 -> 7 | D11: MAYO-GALKE | E11: =I13 -> 0 | F11: =PLUV_16!F11+E11 -> 57 | H11: NGONG | I11: 1
A12: GUIDER | B12: =I9 -> 3 | C12: =PLUV_16!C12+B12 -> 3 | D12: TOUBORO | E12: =I16 -> 0 | F12: =PLUV_16!F12+E12 -> 99 | H12: POLI | I12: 28
A13: GAROUA | B13: =I10 -> 0 | C13: =PLUV_16!C13+B13 -> 0 | D13: HOME | E13: =I17 -> 0 | F13: =PLUV_16!F13+E13 -> 59 | H13: MAYO-GALKE | I13: 0
A15: TOTAL JOURNALIER = | C15: =SUM(B9:B13)+SUM(E9:E13) -> 36 | D15: CUMUL GENERAL = | F15: =SUM(C9:C13)+SUM(F9:F13) -> 300
H16: TOUBORO | I16: 0
H17: HOME | I17: 0
A18: Transmis le : | B18: =IFERROR(+I2+1,0) -> 43946

Sheet PLUV_18
A1: SODECOTON
H2: JOURNEE | I2: 43946
A3: PLUVIOMETRIE JOURNALIERE ET PAR PENTADE
H4: TABLEAU DE SAISI
B5: JOURNEE DU : | D5: =I2 -> 43946 | H5: STATION | I5: RELEVES
H6: MAROUA | I6: 0
A7: STATION | B7: RELEVES | D7: STATION | E7: RELEVES | H7: KAELE | I7: 0
B8: JOURNALIER | C8: CUMUL | E8: JOURNALIER | F8: CUMUL | H8: TCHATIBALI | I8: 0
A9: MAROUA | B9: =I6 -> 0 | C9: =PLUV_17!C9+B9 -> 18 | D9: NGONG | E9: =I11 -> 0 | F9: =PLUV_17!F9+E9 -> 4 | H9: GUIDER | I9: 0
A10: KAELE | B10: =I7 -> 0 | C10: =PLUV_17!C10+B10 -> 1 | D10: POLI | E10: =I12 -> 3 | F10: =PLUV_17!F10+E10 -> 55 | H10: GAROUA | I10: 0
A11: TCHATIBALI | B11: =I8 -> 0 | C11: =PLUV_17!C11+B11 -> 7 | D11: MAYO-GALKE | E11: =I13 -> 8 | F11: =PLUV_17!F11+E11 -> 65 | H11: NGONG | I11: 0
A12: GUIDER | B12: =I9 -> 0 | C12: =PLUV_17!C12+B12 -> 3 | D12: TOUBORO | E12: =I16 -> 0 | F12: =PLUV_17!F12+E12 -> 99 | H12: POLI | I12: 3
A13: GAROUA | B13: =I10 -> 0 | C13: =PLUV_17!C13+B13 -> 0 | D13: HOME | E13: =I17 -> 2 | F13: =PLUV_17!F13+E13 -> 61 | H13: MAYO-GALKE | I13: 8
A15: TOTAL JOURNALIER = | C15: =SUM(B9:B13)+SUM(E9:E13) -> 13 | D15: CUMUL GENERAL = | F15: =SUM(C9:C13)+SUM(F9:F13) -> 313
H16: TOUBORO | I16: 0
H17: HOME | I17: 2
A18: Transmis le : | B18: =IFERROR(+I2+1,0) -> 43947

Sheet PLUV_19
A1: SODECOTON
H2: JOURNEE | I2: 43947
A3: PLUVIOMETRIE JOURNALIERE ET PAR PENTADE
H4: TABLEAU DE SAISI
B5: JOURNEE DU : | D5: =I2 -> 43947 | H5: STATION | I5: RELEVES
H6: MAROUA | I6: 0
A7: STATION | B7: RELEVES | D7: STATION | E7: RELEVES | H7: KAELE | I7: 0
B8: JOURNALIER | C8: CUMUL | E8: JOURNALIER | F8: CUMUL | H8: TCHATIBALI | I8: 0
A9: MAROUA | B9: =I6 -> 0 | C9: =PLUV_18!C9+B9 -> 18 | D9: NGONG | E9: =I11 -> 0 | F9: =PLUV_18!F9+E9 -> 4 | H9: GUIDER | I9: 0
A10: KAELE | B10: =I7 -> 0 | C10: =PLUV_18!C10+B10 -> 1 | D10: POLI | E10: =I12 -> 3 | F10: =PLUV_18!F10+E10 -> 58 | H10: GAROUA | I10: 0
A11: TCHATIBALI | B11: =I8 -> 0 | C11: =PLUV_18!C11+B11 -> 7 | D11: MAYO-GALKE | E11: =I13 -> 2 | F11: =PLUV_18!F11+E11 -> 67 | H11: NGONG | I11: 0
A12: GUIDER | B12: =I9 -> 0 | C12: =PLUV_18!C12+B12 -> 3 | D12: TOUBORO | E12: =I16 -> 0 | F12: =PLUV_18!F12+E12 -> 99 | H12: POLI | I12: 3
A13: GAROUA | B13: =I10 -> 0 | C13: =PLUV_18!C13+B13 -> 0 | D13: HOME | E13: =I17 -> 2 | F13: =PLUV_18!F13+E13 -> 63 | H13: MAYO-GALKE | I13: 2
A15: TOTAL JOURNALIER = | C15: =SUM(B9:B13)+SUM(E9:E13) -> 7 | D15: CUMUL GENERAL = | F15: =SUM(C9:C13)+SUM(F9:F13) -> 320
H16: TOUBORO | I16: 0
H17: HOME | I17: 2
A18: Transmis le : | B18: =IFERROR(+I2+1,0) -> 43948

Sheet PLUV_20
A1: SODECOTON
H2: JOURNEE | I2: 43948
A3: PLUVIOMETRIE JOURNALIERE ET PAR PENTADE
H4: TABLEAU DE SAISI
B5: JOURNEE DU : | D5: =I2 -> 43948 | H5: STATION | I5: RELEVES
H6: MAROUA | I6: 0
A7: STATION | B7: RELEVES | D7: STATION | E7: RELEVES | H7: KAELE | I7: 0
B8: JOURNALIER | C8: CUMUL | E8: JOURNALIER | F8: CUMUL | H8: TCHATIBALI | I8: 0
A9: MAROUA | B9: =I6 -> 0 | C9: =PLUV_19!C9+B9 -> 18 | D9: NGONG | E9: =I11 -> 0 | F9: =PLUV_19!F9+E9 -> 4 | H9: GUIDER | I9: 0
A10: KAELE | B10: =I7 -> 0 | C10: =PLUV_19!C10+B10 -> 1 | D10: POLI | E10: =I12 -> 0 | F10: =PLUV_19!F10+E10 -> 58 | H10: GAROUA | I10: 0
A11: TCHATIBALI | B11: =I8 -> 0 | C11: =PLUV_19!C11+B11 -> 7 | D11: MAYO-GALKE | E11: =I13 -> 0 | F11: =PLUV_19!F11+E11 -> 67 | H11: NGONG | I11: 0
A12: GUIDER | B12: =I9 -> 0 | C12: =PLUV_19!C12+B12 -> 3 | D12: TOUBORO | E12: =I16 -> 13 | F12: =PLUV_19!F12+E12 -> 112 | H12: POLI | I12: 0
A13: GAROUA | B13: =I10 -> 0 | C13: =PLUV_19!C13+B13 -> 0 | D13: HOME | E13: =I17 -> 2 | F13: =PLUV_19!F13+E13 -> 65 | H13: MAYO-GALKE | I13: 0
A15: TOTAL JOURNALIER = | C15: =SUM(B9:B13)+SUM(E9:E13) -> 15 | D15: CUMUL GENERAL = | F15: =SUM(C9:C13)+SUM(F9:F13) -> 335
H16: TOUBORO | I16: 13
H17: HOME | I17: 2
A18: Transmis le : | B18: =IFERROR(+I2+1,0) -> 43949

Sheet PLUV_21
A1: SODECOTON
H2: JOURNEE | I2: 43951
A3: PLUVIOMETRIE JOURNALIERE ET PAR PENTADE
H4: TABLEAU DE SAISI
B5: JOURNEE DU : | D5: =I2 -> 43951 | H5: STATION | I5: RELEVES
H6: MAROUA | I6: 0
A7: STATION | B7: RELEVES | D7: STATION | E7: RELEVES | H7: KAELE | I7: 0
B8: JOURNALIER | C8: CUMUL | E8: JOURNALIER | F8: CUMUL | H8: TCHATIBALI | I8: 0
A9: MAROUA | B9: =I6 -> 0 | C9: =PLUV_20!C9+B9 -> 18 | D9: NGONG | E9: =I11 -> 8 | F9: =PLUV_20!F9+E9 -> 12 | H9: GUIDER | I9: 1
A10: KAELE | B10: =I7 -> 0 | C10: =PLUV_20!C10+B10 -> 1 | D10: POLI | E10: =I12 -> 5 | F10: =PLUV_20!F10+E10 -> 63 | H10: GAROUA | I10: 0
A11: TCHATIBALI | B11: =I8 -> 0 | C11: =PLUV_20!C11+B11 -> 7 | D11: MAYO-GALKE | E11: =I13 -> 3 | F11: =PLUV_20!F11+E11 -> 70 | H11: NGONG | I11: 8
A12: GUIDER | B12: =I9 -> 1 | C12: =PLUV_20!C12+B12 -> 4 | D12: TOUBORO | E12: =I16 -> 0 | F12: =PLUV_20!F12+E12 -> 112 | H12: POLI | I12: 5
A13: GAROUA | B13: =I10 -> 0 | C13: =PLUV_20!C13+B13 -> 0 | D13: HOME | E13: =I17 -> 0 | F13: =PLUV_20!F13+E13 -> 65 | H13: MAYO-GALKE | I13: 3
A15: TOTAL JOURNALIER = | C15: =SUM(B9:B13)+SUM(E9:E13) -> 17 | D15: CUMUL GENERAL = | F15: =SUM(C9:C13)+SUM(F9:F13) -> 352
H16: TOUBORO | I16: 0
H17: HOME | I17: 0
A18: Transmis le : | B18: =IFERROR(+I2+1,0) -> 43952

Sheet PLUV_22
A1: SODECOTON
H2: JOURNEE | I2: 43952
A3: PLUVIOMETRIE JOURNALIERE ET PAR PENTADE
H4: TABLEAU DE SAISI
B5: JOURNEE DU : | D5: =I2 -> 43952 | H5: STATION | I5: RELEVES
H6: MAROUA | I6: 5
A7: STATION | B7: RELEVES | D7: STATION | E7: RELEVES | H7: KAELE | I7: 0
B8: JOURNALIER | C8: CUMUL | E8: JOURNALIER | F8: CUMUL | H8: TCHATIBALI | I8: 3
A9: MAROUA | B9: =I6 -> 5 | C9: =PLUV_21!C9+B9 -> 23 | D9: NGONG | E9: =I11 -> 0 | F9: =PLUV_21!F9+E9 -> 12 | H9: GUIDER | I9: 0
A10: KAELE | B10: =I7 -> 0 | C10: =PLUV_21!C10+B10 -> 1 | D10: POLI | E10: =I12 -> 0 | F10: =PLUV_21!F10+E10 -> 63 | H10: GAROUA | I10: 0
A11: TCHATIBALI | B11: =I8 -> 3 | C11: =PLUV_21!C11+B11 -> 10 | D11: MAYO-GALKE | E11: =I13 -> 0 | F11: =PLUV_21!F11+E11 -> 70 | H11: NGONG | I11: 0
A12: GUIDER | B12: =I9 -> 0 | C12: =PLUV_21!C12+B12 -> 4 | D12: TOUBORO | E12: =I16 -> 1 | F12: =PLUV_21!F12+E12 -> 113 | H12: POLI | I12: 0
A13: GAROUA | B13: =I10 -> 0 | C13: =PLUV_21!C13+B13 -> 0 | D13: HOME | E13: =I17 -> 0 | F13: =PLUV_21!F13+E13 -> 65 | H13: MAYO-GALKE | I13: 0
A15: TOTAL JOURNALIER = | C15: =SUM(B9:B13)+SUM(E9:E13) -> 9 | D15: CUMUL GENERAL = | F15: =SUM(C9:C13)+SUM(F9:F13) -> 361
H16: TOUBORO | I16: 1
H17: HOME | I17: 0
A18: Transmis le : | B18: =IFERROR(+I2+1,0) -> 43953

Sheet PLUV_23
A1: SODECOTON
H2: JOURNEE | I2: 43953
A3: PLUVIOMETRIE JOURNALIERE ET PAR PENTADE
H4: TABLEAU DE SAISI
B5: JOURNEE DU : | D5: =I2 -> 43953 | H5: STATION | I5: RELEVES
H6: MAROUA | I6: 5
A7: STATION | B7: RELEVES | D7: STATION | E7: RELEVES | H7: KAELE | I7: 0
B8: JOURNALIER | C8: CUMUL | E8: JOURNALIER | F8: CUMUL | H8: TCHATIBALI | I8: 0
A9: MAROUA | B9: =I6 -> 5 | C9: =PLUV_22!C9+B9 -> 28 | D9: NGONG | E9: =I11 -> 0 | F9: =PLUV_22!F9+E9 -> 12 | H9: GUIDER | I9: 4
A10: KAELE | B10: =I7 -> 0 | C10: =PLUV_22!C10+B10 -> 1 | D10: POLI | E10: =I12 -> 0 | F10: =PLUV_22!F10+E10 -> 63 | H10: GAROUA | I10: 0
A11: TCHATIBALI | B11: =I8 -> 0 | C11: =PLUV_22!C11+B11 -> 10 | D11: MAYO-GALKE | E11: =I13 -> 0 | F11: =PLUV_22!F11+E11 -> 70 | H11: NGONG | I11: 0
A12: GUIDER | B12: =I9 -> 4 | C12: =PLUV_22!C12+B12 -> 8 | D12: TOUBORO | E12: =I16 -> 0 | F12: =PLUV_22!F12+E12 -> 113 | H12: POLI | I12: 0
A13: GAROUA | B13: =I10 -> 0 | C13: =PLUV_22!C13+B13 -> 0 | D13: HOME | E13: =I17 -> 0 | F13: =PLUV_22!F13+E13 -> 65 | H13: MAYO-GALKE | I13: 0
A15: TOTAL JOURNALIER = | C15: =SUM(B9:B13)+SUM(E9:E13) -> 9 | D15: CUMUL GENERAL = | F15: =SUM(C9:C13)+SUM(F9:F13) -> 370
H16: TOUBORO | I16: 0
H17: HOME | I17: 0
A18: Transmis le : | B18: =IFERROR(+I2+1,0) -> 43954

Sheet PLUV_24
A1: SODECOTON
H2: JOURNEE | I2: 43954
A3: PLUVIOMETRIE JOURNALIERE ET PAR PENTADE
H4: TABLEAU DE SAISI
B5: JOURNEE DU : | D5: =I2 -> 43954 | H5: STATION | I5: RELEVES
H6: MAROUA | I6: 0
A7: STATION | B7: RELEVES | D7: STATION | E7: RELEVES | H7: KAELE | I7: 0
B8: JOURNALIER | C8: CUMUL | E8: JOURNALIER | F8: CUMUL | H8: TCHATIBALI | I8: 0
A9: MAROUA | B9: =I6 -> 0 | C9: =PLUV_23!C9+B9 -> 28 | D9: NGONG | E9: =I11 -> 3 | F9: =PLUV_23!F9+E9 -> 15 | H9: GUIDER | I9: 1
A10: KAELE | B10: =I7 -> 0 | C10: =PLUV_23!C10+B10 -> 1 | D10: POLI | E10: =I12 -> 86 | F10: =PLUV_23!F10+E10 -> 149 | H10: GAROUA | I10: 0
A11: TCHATIBALI | B11: =I8 -> 0 | C11: =PLUV_23!C11+B11 -> 10 | D11: MAYO-GALKE | E11: =I13 -> 21 | F11: =PLUV_23!F11+E11 -> 91 | H11: NGONG | I11: 3
A12: GUIDER | B12: =I9 -> 1 | C12: =PLUV_23!C12+B12 -> 9 | D12: TOUBORO | E12: =I16 -> 50 | F12: =PLUV_23!F12+E12 -> 163 | H12: POLI | I12: 86
A13: GAROUA | B13: =I10 -> 0 | C13: =PLUV_23!C13+B13 -> 0 | D13: HOME | E13: =I17 -> 3 | F13: =PLUV_23!F13+E13 -> 68 | H13: MAYO-GALKE | I13: 21
A15: TOTAL JOURNALIER = | C15: =SUM(B9:B13)+SUM(E9:E13) -> 164 | D15: CUMUL GENERAL = | F15: =SUM(C9:C13)+SUM(F9:F13) -> 534
H16: TOUBORO | I16: 50
H17: HOME | I17: 3
A18: Transmis le : | B18: =IFERROR(+I2+1,0) -> 43955

Sheet PLUV_25
A1: SODECOTON
H2: JOURNEE | I2: 43955
A3: PLUVIOMETRIE JOURNALIERE ET PAR PENTADE
H4: TABLEAU DE SAISI
B5: JOURNEE DU : | D5: =I2 -> 43955 | H5: STATION | I5: RELEVES
H6: MAROUA | I6: 0
A7: STATION | B7: RELEVES | D7: STATION | E7: RELEVES | H7: KAELE | I7: 0
B8: JOURNALIER | C8: CUMUL | E8: JOURNALIER | F8: CUMUL | H8: TCHATIBALI | I8: 0
A9: MAROUA | B9: =I6 -> 0 | C9: =PLUV_24!C9+B9 -> 28 | D9: NGONG | E9: =I11 -> 0 | F9: =PLUV_24!F9+E9 -> 15 | H9: GUIDER | I9: 0
A10: KAELE | B10: =I7 -> 0 | C10: =PLUV_24!C10+B10 -> 1 | D10: POLI | E10: =I12 -> 0 | F10: =PLUV_24!F10+E10 -> 149 | H10: GAROUA | I10: 0
A11: TCHATIBALI | B11: =I8 -> 0 | C11: =PLUV_24!C11+B11 -> 10 | D11: MAYO-GALKE | E11: =I13 -> 0 | F11: =PLUV_24!F11+E11 -> 91 | H11: NGONG | I11: 0
A12: GUIDER | B12: =I9 -> 0 | C12: =PLUV_24!C12+B12 -> 9 | D12: TOUBORO | E12: =I16 -> 4 | F12: =PLUV_24!F12+E12 -> 167 | H12: POLI | I12: 0
A13: GAROUA | B13: =I10 -> 0 | C13: =PLUV_24!C13+B13 -> 0 | D13: HOME | E13: =I17 -> 0 | F13: =PLUV_24!F13+E13 -> 68 | H13: MAYO-GALKE | I13: 0
A15: TOTAL JOURNALIER = | C15: =SUM(B9:B13)+SUM(E9:E13) -> 4 | D15: CUMUL GENERAL = | F15: =SUM(C9:C13)+SUM(F9:F13) -> 538
H16: TOUBORO | I16: 4
H17: HOME | I17: 0
A18: Transmis le : | B18: =IFERROR(+I2+1,0) -> 43956

Sheet PLUV_26
A1: SODECOTON
H2: JOURNEE | I2: 43958
A3: PLUVIOMETRIE JOURNALIERE ET PAR PENTADE
H4: TABLEAU DE SAISI
B5: JOURNEE DU : | D5: =I2 -> 43958 | H5: STATION | I5: RELEVES
H6: MAROUA | I6: 0
A7: STATION | B7: RELEVES | D7: STATION | E7: RELEVES | H7: KAELE | I7: 0
B8: JOURNALIER | C8: CUMUL | E8: JOURNALIER | F8: CUMUL | H8: TCHATIBALI | I8: 1
A9: MAROUA | B9: =I6 -> 0 | C9: =PLUV_25!C9+B9 -> 28 | D9: NGONG | E9: =I11 -> 0 | F9: =PLUV_25!F9+E9 -> 15 | H9: GUIDER | I9: 0
A10: KAELE | B10: =I7 -> 0 | C10: =PLUV_25!C10+B10 -> 1 | D10: POLI | E10: =I12 -> 0 | F10: =PLUV_25!F10+E10 -> 149 | H10: GAROUA | I10: 0
A11: TCHATIBALI | B11: =I8 -> 1 | C11: =PLUV_25!C11+B11 -> 11 | D11: MAYO-GALKE | E11: =I13 -> 0 | F11: =PLUV_25!F11+E11 -> 91 | H11: NGONG | I11: 0
A12: GUIDER | B12: =I9 -> 0 | C12: =PLUV_25!C12+B12 -> 9 | D12: TOUBORO | E12: =I16 -> 1 | F12: =PLUV_25!F12+E12 -> 168 | H12: POLI | I12: 0
A13: GAROUA | B13: =I10 -> 0 | C13: =PLUV_25!C13+B13 -> 0 | D13: HOME | E13: =I17 -> 4 | F13: =PLUV_25!F13+E13 -> 72 | H13: MAYO-GALKE | I13: 0
A15: TOTAL JOURNALIER = | C15: =SUM(B9:B13)+SUM(E9:E13) -> 6 | D15: CUMUL GENERAL = | F15: =SUM(C9:C13)+SUM(F9:F13) -> 544
H16: TOUBORO | I16: 1
H17: HOME | I17: 4
A18: Transmis le : | B18: =IFERROR(+I2+1,0) -> 43959

Sheet PLUV_27
A1: SODECOTON
H2: JOURNEE | I2: 43960
A3: PLUVIOMETRIE JOURNALIERE ET PAR PENTADE
H4: TABLEAU DE SAISI
B5: JOURNEE DU : | D5: =I2 -> 43960 | H5: STATION | I5: RELEVES
H6: MAROUA | I6: 2
A7: STATION | B7: RELEVES | D7: STATION | E7: RELEVES | H7: KAELE | I7: 5
B8: JOURNALIER | C8: CUMUL | E8: JOURNALIER | F8: CUMUL | H8: TCHATIBALI | I8: 0
A9: MAROUA | B9: =I6 -> 2 | C9: =PLUV_26!C9+B9 -> 30 | D9: NGONG | E9: =I11 -> 0 | F9: =PLUV_26!F9+E9 -> 15 | H9: GUIDER | I9: 10
A10: KAELE | B10: =I7 -> 5 | C10: =PLUV_26!C10+B10 -> 6 | D10: POLI | E10: =I12 -> 7 | F10: =PLUV_26!F10+E10 -> 156 | H10: GAROUA | I10: 0
A11: TCHATIBALI | B11: =I8 -> 0 | C11: =PLUV_26!C11+B11 -> 11 | D11: MAYO-GALKE | E11: =I13 -> 15 | F11: =PLUV_26!F11+E11 -> 106 | H11: NGONG | I11: 0
A12: GUIDER | B12: =I9 -> 10 | C12: =PLUV_26!C12+B12 -> 19 | D12: TOUBORO | E12: =I16 -> 0 | F12: =PLUV_26!F12+E12 -> 168 | H12: POLI | I12: 7
A13: GAROUA | B13: =I10 -> 0 | C13: =PLUV_26!C13+B13 -> 0 | D13: HOME | E13: =I17 -> 0 | F13: =PLUV_26!F13+E13 -> 72 | H13: MAYO-GALKE | I13: 15
A15: TOTAL JOURNALIER = | C15: =SUM(B9:B13)+SUM(E9:E13) -> 39 | D15: CUMUL GENERAL = | F15: =SUM(C9:C13)+SUM(F9:F13) -> 583
H16: TOUBORO | I16: 0
H17: HOME | I17: 0
A18: Transmis le : | B18: =IFERROR(+I2+1,0) -> 43961

Sheet PLUV_28
A1: SODECOTON
H2: JOURNEE | I2: 43961
A3: PLUVIOMETRIE JOURNALIERE ET PAR PENTADE
H4: TABLEAU DE SAISI
B5: JOURNEE DU : | D5: =I2 -> 43961 | H5: STATION | I5: RELEVES
H6: MAROUA | I6: 0
A7: STATION | B7: RELEVES | D7: STATION | E7: RELEVES | H7: KAELE | I7: 0
B8: JOURNALIER | C8: CUMUL | E8: JOURNALIER | F8: CUMUL | H8: TCHATIBALI | I8: 0
A9: MAROUA | B9: =I6 -> 0 | C9: =PLUV_27!C9+B9 -> 30 | D9: NGONG | E9: =I11 -> 0 | F9: =PLUV_27!F9+E9 -> 15 | H9: GUIDER | I9: 1
A10: KAELE | B10: =I7 -> 0 | C10: =PLUV_27!C10+B10 -> 6 | D10: POLI | E10: =I12 -> 0 | F10: =PLUV_27!F10+E10 -> 156 | H10: GAROUA | I10: 0
A11: TCHATIBALI | B11: =I8 -> 0 | C11: =PLUV_27!C11+B11 -> 11 | D11: MAYO-GALKE | E11: =I13 -> 2 | F11: =PLUV_27!F11+E11 -> 108 | H11: NGONG | I11: 0
A12: GUIDER | B12: =I9 -> 1 | C12: =PLUV_27!C12+B12 -> 20 | D12: TOUBORO | E12: =I16 -> 0 | F12: =PLUV_27!F12+E12 -> 168 | H12: POLI | I12: 0
A13: GAROUA | B13: =I10 -> 0 | C13: =PLUV_27!C13+B13 -> 0 | D13: HOME | E13: =I17 -> 0 | F13: =PLUV_27!F13+E13 -> 72 | H13: MAYO-GALKE | I13: 2
A15: TOTAL JOURNALIER = | C15: =SUM(B9:B13)+SUM(E9:E13) -> 3 | D15: CUMUL GENERAL = | F15: =SUM(C9:C13)+SUM(F9:F13) -> 586
H16: TOUBORO | I16: 0
H17: HOME | I17: 0
A18: Transmis le : | B18: =IFERROR(+I2+1,0) -> 43962

Sheet PLUV_29
A1: SODECOTON
H2: JOURNEE | I2: 43963
A3: PLUVIOMETRIE JOURNALIERE ET PAR PENTADE
H4: TABLEAU DE SAISI
B5: JOURNEE DU : | D5: =I2 -> 43963 | H5: STATION | I5: RELEVES
H6: MAROUA | I6: 0
A7: STATION | B7: RELEVES | D7: STATION | E7: RELEVES | H7: KAELE | I7: 0
B8: JOURNALIER | C8: CUMUL | E8: JOURNALIER | F8: CUMUL | H8: TCHATIBALI | I8: 4
A9: MAROUA | B9: =I6 -> 0 | C9: =PLUV_28!C9+B9 -> 30 | D9: NGONG | E9: =I11 -> 0 | F9: =PLUV_28!F9+E9 -> 15 | H9: GUIDER | I9: 5
A10: KAELE | B10: =I7 -> 0 | C10: =PLUV_28!C10+B10 -> 6 | D10: POLI | E10: =I12 -> 0 | F10: =PLUV_28!F10+E10 -> 156 | H10: GAROUA | I10: 0
A11: TCHATIBALI | B11: =I8 -> 4 | C11: =PLUV_28!C11+B11 -> 15 | D11: MAYO-GALKE | E11: =I13 -> 0 | F11: =PLUV_28!F11+E11 -> 108 | H11: NGONG | I11: 0
A12: GUIDER | B12: =I9 -> 5 | C12: =PLUV_28!C12+B12 -> 25 | D12: TOUBORO | E12: =I16 -> 0 | F12: =PLUV_28!F12+E12 -> 168 | H12: POLI | I12: 0
A13: GAROUA | B13: =I10 -> 0 | C13: =PLUV_28!C13+B13 -> 0 | D13: HOME | E13: =I17 -> 8 | F13: =PLUV_28!F13+E13 -> 80 | H13: MAYO-GALKE | I13: 0
A15: TOTAL JOURNALIER = | C15: =SUM(B9:B13)+SUM(E9:E13) -> 17 | D15: CUMUL GENERAL = | F15: =SUM(C9:C13)+SUM(F9:F13) -> 603
H16: TOUBORO | I16: 0
H17: HOME | I17: 8
A18: Transmis le : | B18: =IFERROR(+I2+1,0) -> 43964

Sheet PLUV_30
A1: SODECOTON
H2: JOURNEE | I2: 43964
A3: PLUVIOMETRIE JOURNALIERE ET PAR PENTADE
H4: TABLEAU DE SAISI
B5: JOURNEE DU : | D5: =I2 -> 43964 | H5: STATION | I5: RELEVES
H6: MAROUA | I6: 0
A7: STATION | B7: RELEVES | D7: STATION | E7: RELEVES | H7: KAELE | I7: 19
B8: JOURNALIER | C8: CUMUL | E8: JOURNALIER | F8: CUMUL | H8: TCHATIBALI | I8: 5
A9: MAROUA | B9: =I6 -> 0 | C9: =PLUV_29!C9+B9 -> 30 | D9: NGONG | E9: =I11 -> 0 | F9: =PLUV_29!F9+E9 -> 15 | H9: GUIDER | I9: 9
A10: KAELE | B10: =I7 -> 19 | C10: =PLUV_29!C10+B10 -> 25 | D10: POLI | E10: =I12 -> 0 | F10: =PLUV_29!F10+E10 -> 156 | H10: GAROUA | I10: 20
A11: TCHATIBALI | B11: =I8 -> 5 | C11: =PLUV_29!C11+B11 -> 20 | D11: MAYO-GALKE | E11: =I13 -> 0 | F11: =PLUV_29!F11+E11 -> 108 | H11: NGONG | I11: 0
A12: GUIDER | B12: =I9 -> 9 | C12: =PLUV_29!C12+B12 -> 34 | D12: TOUBORO | E12: =I16 -> 0 | F12: =PLUV_29!F12+E12 -> 168 | H12: POLI | I12: 0
A13: GAROUA | B13: =I10 -> 20 | C13: =PLUV_29!C13+B13 -> 20 | D13: HOME | E13: =I17 -> 0 | F13: =PLUV_29!F13+E13 -> 80 | H13: MAYO-GALKE | I13: 0
A15: TOTAL JOURNALIER = | C15: =SUM(B9:B13)+SUM(E9:E13) -> 53 | D15: CUMUL GENERAL = | F15: =SUM(C9:C13)+SUM(F9:F13) -> 656
H16: TOUBORO | I16: 0
H17: HOME | I17: 0
A18: Transmis le : | B18: =IFERROR(+I2+1,0) -> 43965

Sheet PLUV_31
A1: SODECOTON
H2: JOURNEE | I2: 43965
A3: PLUVIOMETRIE JOURNALIERE ET PAR PENTADE
H4: TABLEAU DE SAISI
B5: JOURNEE DU : | D5: =I2 -> 43965 | H5: STATION | I5: RELEVES
H6: MAROUA | I6: 0
A7: STATION | B7: RELEVES | D7: STATION | E7: RELEVES | H7: KAELE | I7: 0
B8: JOURNALIER | C8: CUMUL | E8: JOURNALIER | F8: CUMUL | H8: TCHATIBALI | I8: 0
A9: MAROUA | B9: =I6 -> 0 | C9: =PLUV_30!C9+B9 -> 30 | D9: NGONG | E9: =I11 -> 0 | F9: =PLUV_30!F9+E9 -> 15 | H9: GUIDER | I9: 0
A10: KAELE | B10: =I7 -> 0 | C10: =PLUV_30!C10+B10 -> 25 | D10: POLI | E10: =I12 -> 0 | F10: =PLUV_30!F10+E10 -> 156 | H10: GAROUA | I10: 0
A11: TCHATIBALI | B11: =I8 -> 0 | C11: =PLUV_30!C11+B11 -> 20 | D11: MAYO-GALKE | E11: =I13 -> 0 | F11: =PLUV_30!F11+E11 -> 108 | H11: NGONG | I11: 0
A12: GUIDER | B12: =I9 -> 0 | C12: =PLUV_30!C12+B12 -> 34 | D12: TOUBORO | E12: =I16 -> 20 | F12: =PLUV_30!F12+E12 -> 188 | H12: POLI | I12: 0
A13: GAROUA | B13: =I10 -> 0 | C13: =PLUV_30!C13+B13 -> 20 | D13: HOME | E13: =I17 -> 3 | F13: =PLUV_30!F13+E13 -> 83 | H13: MAYO-GALKE | I13: 0
A15: TOTAL JOURNALIER = | C15: =SUM(B9:B13)+SUM(E9:E13) -> 23 | D15: CUMUL GENERAL = | F15: =SUM(C9:C13)+SUM(F9:F13) -> 679
H16: TOUBORO | I16: 20
H17: HOME | I17: 3
A18: Transmis le : | B18: =IFERROR(+I2+1,0) -> 43966

Sheet PLUV_32
A1: SODECOTON
H2: JOURNEE | I2: 43966
A3: PLUVIOMETRIE JOURNALIERE ET PAR PENTADE
H4: TABLEAU DE SAISI
B5: JOURNEE DU : | D5: =I2 -> 43966 | H5: STATION | I5: RELEVES
H6: MAROUA | I6: 0
A7: STATION | B7: RELEVES | D7: STATION | E7: RELEVES | H7: KAELE | I7: 0
B8: JOURNALIER | C8: CUMUL | E8: JOURNALIER | F8: CUMUL | H8: TCHATIBALI | I8: 0
A9: MAROUA | B9: =I6 -> 0 | C9: =PLUV_31!C9+B9 -> 30 | D9: NGONG | E9: =I11 -> 0 | F9: =PLUV_31!F9+E9 -> 15 | H9: GUIDER | I9: 0
A10: KAELE | B10: =I7 -> 0 | C10: =PLUV_31!C10+B10 -> 25 | D10: POLI | E10: =I12 -> 18 | F10: =PLUV_31!F10+E10 -> 174 | H10: GAROUA | I10: 0
A11: TCHATIBALI | B11: =I8 -> 0 | C11: =PLUV_31!C11+B11 -> 20 | D11: MAYO-GALKE | E11: =I13 -> 0 | F11: =PLUV_31!F11+E11 -> 108 | H11: NGONG | I11: 0
A12: GUIDER | B12: =I9 -> 0 | C12: =PLUV_31!C12+B12 -> 34 | D12: TOUBORO | E12: =I16 -> 0 | F12: =PLUV_31!F12+E12 -> 188 | H12: POLI | I12: 18
A13: GAROUA | B13: =I10 -> 0 | C13: =PLUV_31!C13+B13 -> 20 | D13: HOME | E13: =I17 -> 5 | F13: =PLUV_31!F13+E13 -> 88 | H13: MAYO-GALKE | I13: 0
A15: TOTAL JOURNALIER = | C15: =SUM(B9:B13)+SUM(E9:E13) -> 23 | D15: CUMUL GENERAL = | F15: =SUM(C9:C13)+SUM(F9:F13) -> 702
H16: TOUBORO | I16: 0
H17: HOME | I17: 5
A18: Transmis le : | B18: =IFERROR(+I2+1,0) -> 43967

Sheet PLUV_33
A1: SODECOTON
H2: JOURNEE | I2: 43968
A3: PLUVIOMETRIE JOURNALIERE ET PAR PENTADE
H4: TABLEAU DE SAISI
B5: JOURNEE DU : | D5: =I2 -> 43968 | H5: STATION | I5: RELEVES
H6: MAROUA | I6: 0
A7: STATION | B7: RELEVES | D7: STATION | E7: RELEVES | H7: KAELE | I7: 0
B8: JOURNALIER | C8: CUMUL | E8: JOURNALIER | F8: CUMUL | H8: TCHATIBALI | I8: 0
A9: MAROUA | B9: =I6 -> 0 | C9: =PLUV_32!C9+B9 -> 30 | D9: NGONG | E9: =I11 -> 0 | F9: =PLUV_32!F9+E9 -> 15 | H9: GUIDER | I9: 0
A10: KAELE | B10: =I7 -> 0 | C10: =PLUV_32!C10+B10 -> 25 | D10: POLI | E10: =I12 -> 18 | F10: =PLUV_32!F10+E10 -> 192 | H10: GAROUA | I10: 0
A11: TCHATIBALI | B11: =I8 -> 0 | C11: =PLUV_32!C11+B11 -> 20 | D11: MAYO-GALKE | E11: =I13 -> 0 | F11: =PLUV_32!F11+E11 -> 108 | H11: NGONG | I11: 0
A12: GUIDER | B12: =I9 -> 0 | C12: =PLUV_32!C12+B12 -> 34 | D12: TOUBORO | E12: =I16 -> 0 | F12: =PLUV_32!F12+E12 -> 188 | H12: POLI | I12: 18
A13: GAROUA | B13: =I10 -> 0 | C13: =PLUV_32!C13+B13 -> 20 | D13: HOME | E13: =I17 -> 3 | F13: =PLUV_32!F13+E13 -> 91 | H13: MAYO-GALKE | I13: 0
A15: TOTAL JOURNALIER = | C15: =SUM(B9:B13)+SUM(E9:E13) -> 21 | D15: CUMUL GENERAL = | F15: =SUM(C9:C13)+SUM(F9:F13) -> 723
H16: TOUBORO | I16: 0
H17: HOME | I17: 3
A18: Transmis le : | B18: =IFERROR(+I2+1,0) -> 43969

Sheet PLUV_34
A1: SODECOTON
H2: JOURNEE | I2: 43969
A3: PLUVIOMETRIE JOURNALIERE ET PAR PENTADE
H4: TABLEAU DE SAISI
B5: JOURNEE DU : | D5: =I2 -> 43969 | H5: STATION | I5: RELEVES
H6: MAROUA | I6: 0
A7: STATION | B7: RELEVES | D7: STATION | E7: RELEVES | H7: KAELE | I7: 0
B8: JOURNALIER | C8: CUMUL | E8: JOURNALIER | F8: CUMUL | H8: TCHATIBALI | I8: 0
A9: MAROUA | B9: =I6 -> 0 | C9: =PLUV_33!C9+B9 -> 30 | D9: NGONG | E9: =I11 -> 34 | F9: =PLUV_33!F9+E9 -> 49 | H9: GUIDER | I9: 0
A10: KAELE | B10: =I7 -> 0 | C10: =PLUV_33!C10+B10 -> 25 | D10: POLI | E10: =I12 -> 32 | F10: =PLUV_33!F10+E10 -> 224 | H10: GAROUA | I10: 10
A11: TCHATIBALI | B11: =I8 -> 0 | C11: =PLUV_33!C11+B11 -> 20 | D11: MAYO-GALKE | E11: =I13 -> 16 | F11: =PLUV_33!F11+E11 -> 124 | H11: NGONG | I11: 34
A12: GUIDER | B12: =I9 -> 0 | C12: =PLUV_33!C12+B12 -> 34 | D12: TOUBORO | E12: =I16 -> 0 | F12: =PLUV_33!F12+E12 -> 188 | H12: POLI | I12: 32
A13: GAROUA | B13: =I10 -> 10 | C13: =PLUV_33!C13+B13 -> 30 | D13: HOME | E13: =I17 -> 2 | F13: =PLUV_33!F13+E13 -> 93 | H13: MAYO-GALKE | I13: 16
A15: TOTAL JOURNALIER = | C15: =SUM(B9:B13)+SUM(E9:E13) -> 94 | D15: CUMUL GENERAL = | F15: =SUM(C9:C13)+SUM(F9:F13) -> 817
H16: TOUBORO | I16: 0
H17: HOME | I17: 2
A18: Transmis le : | B18: =IFERROR(+I2+1,0) -> 43970

Sheet PLUV_35
A1: SODECOTON
H2: JOURNEE | I2: 43970
A3: PLUVIOMETRIE JOURNALIERE ET PAR PENTADE
H4: TABLEAU DE SAISI
B5: JOURNEE DU : | D5: =I2 -> 43970 | H5: STATION | I5: RELEVES
H6: MAROUA | I6: 0
A7: STATION | B7: RELEVES | D7: STATION | E7: RELEVES | H7: KAELE | I7: 0
B8: JOURNALIER | C8: CUMUL | E8: JOURNALIER | F8: CUMUL | H8: TCHATIBALI | I8: 0
A9: MAROUA | B9: =I6 -> 0 | C9: =PLUV_34!C9+B9 -> 30 | D9: NGONG | E9: =I11 -> 0 | F9: =PLUV_34!F9+E9 -> 49 | H9: GUIDER | I9: 0
A10: KAELE | B10: =I7 -> 0 | C10: =PLUV_34!C10+B10 -> 25 | D10: POLI | E10: =I12 -> 0 | F10: =PLUV_34!F10+E10 -> 224 | H10: GAROUA | I10: 0
A11: TCHATIBALI | B11: =I8 -> 0 | C11: =PLUV_34!C11+B11 -> 20 | D11: MAYO-GALKE | E11: =I13 -> 0 | F11: =PLUV_34!F11+E11 -> 124 | H11: NGONG | I11: 0
A12: GUIDER | B12: =I9 -> 0 | C12: =PLUV_34!C12+B12 -> 34 | D12: TOUBORO | E12: =I16 -> 0 | F12: =PLUV_34!F12+E12 -> 188 | H12: POLI | I12: 0
A13: GAROUA | B13: =I10 -> 0 | C13: =PLUV_34!C13+B13 -> 30 | D13: HOME | E13: =I17 -> 3 | F13: =PLUV_34!F13+E13 -> 96 | H13: MAYO-GALKE | I13: 0
A15: TOTAL JOURNALIER = | C15: =SUM(B9:B13)+SUM(E9:E13) -> 3 | D15: CUMUL GENERAL = | F15: =SUM(C9:C13)+SUM(F9:F13) -> 820
H16: TOUBORO | I16: 0
H17: HOME | I17: 3
A18: Transmis le : | B18: =IFERROR(+I2+1,0) -> 43971

Sheet PLUV_36
A1: SODECOTON
H2: JOURNEE | I2: 43971
A3: PLUVIOMETRIE JOURNALIERE ET PAR PENTADE
H4: TABLEAU DE SAISI
B5: JOURNEE DU : | D5: =I2 -> 43971 | H5: STATION | I5: RELEVES
H6: MAROUA | I6: 4
A7: STATION | B7: RELEVES | D7: STATION | E7: RELEVES | H7: KAELE | I7: 42
B8: JOURNALIER | C8: CUMUL | E8: JOURNALIER | F8: CUMUL | H8: TCHATIBALI | I8: 45
A9: MAROUA | B9: =I6 -> 4 | C9: =PLUV_35!C9+B9 -> 34 | D9: NGONG | E9: =I11 -> 0 | F9: =PLUV_35!F9+E9 -> 49 | H9: GUIDER | I9: 0
A10: KAELE | B10: =I7 -> 42 | C10: =PLUV_35!C10+B10 -> 67 | D10: POLI | E10: =I12 -> 0 | F10: =PLUV_35!F10+E10 -> 224 | H10: GAROUA | I10: 0
A11: TCHATIBALI | B11: =I8 -> 45 | C11: =PLUV_35!C11+B11 -> 65 | D11: MAYO-GALKE | E11: =I13 -> 0 | F11: =PLUV_35!F11+E11 -> 124 | H11: NGONG | I11: 0
A12: GUIDER | B12: =I9 -> 0 | C12: =PLUV_35!C12+B12 -> 34 | D12: TOUBORO | E12: =I16 -> 0 | F12: =PLUV_35!F12+E12 -> 188 | H12: POLI | I12: 0
A13: GAROUA | B13: =I10 -> 0 | C13: =PLUV_35!C13+B13 -> 30 | D13: HOME | E13: =I17 -> 0 | F13: =PLUV_35!F13+E13 -> 96 | H13: MAYO-GALKE | I13: 0
A15: TOTAL JOURNALIER = | C15: =SUM(B9:B13)+SUM(E9:E13) -> 91 | D15: CUMUL GENERAL = | F15: =SUM(C9:C13)+SUM(F9:F13) -> 911
H16: TOUBORO | I16: 0
H17: HOME | I17: 0
A18: Transmis le : | B18: =IFERROR(+I2+1,0) -> 43972

Sheet PLUV_37
A1: SODECOTON
H2: JOURNEE | I2: 43972
A3: PLUVIOMETRIE JOURNALIERE ET PAR PENTADE
H4: TABLEAU DE SAISI
B5: JOURNEE DU : | D5: =I2 -> 43972 | H5: STATION | I5: RELEVES
H6: MAROUA | I6: 0
A7: STATION | B7: RELEVES | D7: STATION | E7: RELEVES | H7: KAELE | I7: 0
B8: JOURNALIER | C8: CUMUL | E8: JOURNALIER | F8: CUMUL | H8: TCHATIBALI | I8: 4
A9: MAROUA | B9: =I6 -> 0 | C9: =PLUV_36!C9+B9 -> 34 | D9: NGONG | E9: =I11 -> 0 | F9: =PLUV_36!F9+E9 -> 49 | H9: GUIDER | I9: 0
A10: KAELE | B10: =I7 -> 0 | C10: =PLUV_36!C10+B10 -> 67 | D10: POLI | E10: =I12 -> 0 | F10: =PLUV_36!F10+E10 -> 224 | H10: GAROUA | I10: 0
A11: TCHATIBALI | B11: =I8 -> 4 | C11: =PLUV_36!C11+B11 -> 69 | D11: MAYO-GALKE | E11: =I13 -> 23 | F11: =PLUV_36!F11+E11 -> 147 | H11: NGONG | I11: 0
A12: GUIDER | B12: =I9 -> 0 | C12: =PLUV_36!C12+B12 -> 34 | D12: TOUBORO | E12: =I16 -> 36 | F12: =PLUV_36!F12+E12 -> 224 | H12: POLI | I12: 0
A13: GAROUA | B13: =I10 -> 0 | C13: =PLUV_36!C13+B13 -> 30 | D13: HOME | E13: =I17 -> 12 | F13: =PLUV_36!F13+E13 -> 108 | H13: MAYO-GALKE | I13: 23
A15: TOTAL JOURNALIER = | C15: =SUM(B9:B13)+SUM(E9:E13) -> 75 | D15: CUMUL GENERAL = | F15: =SUM(C9:C13)+SUM(F9:F13) -> 986
H16: TOUBORO | I16: 36
H17: HOME | I17: 12
A18: Transmis le : | B18: =IFERROR(+I2+1,0) -> 43973

Sheet PLUV_38
A1: SODECOTON
H2: JOURNEE | I2: 43974
A3: PLUVIOMETRIE JOURNALIERE ET PAR PENTADE
H4: TABLEAU DE SAISI
B5: JOURNEE DU : | D5: =I2 -> 43974 | H5: STATION | I5: RELEVES
H6: MAROUA | I6: 0
A7: STATION | B7: RELEVES | D7: STATION | E7: RELEVES | H7: KAELE | I7: 0
B8: JOURNALIER | C8: CUMUL | E8: JOURNALIER | F8: CUMUL | H8: TCHATIBALI | I8: 0
A9: MAROUA | B9: =I6 -> 0 | C9: =PLUV_37!C9+B9 -> 34 | D9: NGONG | E9: =I11 -> 6 | F9: =PLUV_37!F9+E9 -> 55 | H9: GUIDER | I9: 0
A10: KAELE | B10: =I7 -> 0 | C10: =PLUV_37!C10+B10 -> 67 | D10: POLI | E10: =I12 -> 2 | F10: =PLUV_37!F10+E10 -> 226 | H10: GAROUA | I10: 0
A11: TCHATIBALI | B11: =I8 -> 0 | C11: =PLUV_37!C11+B11 -> 69 | D11: MAYO-GALKE | E11: =I13 -> 6 | F11: =PLUV_37!F11+E11 -> 153 | H11: NGONG | I11: 6
A12: GUIDER | B12: =I9 -> 0 | C12: =PLUV_37!C12+B12 -> 34 | D12: TOUBORO | E12: =I16 -> 0 | F12: =PLUV_37!F12+E12 -> 224 | H12: POLI | I12: 2
A13: GAROUA | B13: =I10 -> 0 | C13: =PLUV_37!C13+B13 -> 30 | D13: HOME | E13: =I17 -> 0 | F13: =PLUV_37!F13+E13 -> 108 | H13: MAYO-GALKE | I13: 6
A15: TOTAL JOURNALIER = | C15: =SUM(B9:B13)+SUM(E9:E13) -> 14 | D15: CUMUL GENERAL = | F15: =SUM(C9:C13)+SUM(F9:F13) -> 1000
H16: TOUBORO | I16: 0
H17: HOME | I17: 0
A18: Transmis le : | B18: =IFERROR(+I2+1,0) -> 43975

Sheet PLUV_39
A1: SODECOTON
H2: JOURNEE | I2: 43975
A3: PLUVIOMETRIE JOURNALIERE ET PAR PENTADE
H4: TABLEAU DE SAISI
B5: JOURNEE DU : | D5: =I2 -> 43975 | H5: STATION | I5: RELEVES
H6: MAROUA | I6: 2
A7: STATION | B7: RELEVES | D7: STATION | E7: RELEVES | H7: KAELE | I7: 6
B8: JOURNALIER | C8: CUMUL | E8: JOURNALIER | F8: CUMUL | H8: TCHATIBALI | I8: 0
A9: MAROUA | B9: =I6 -> 2 | C9: =PLUV_38!C9+B9 -> 36 | D9: NGONG | E9: =I11 -> 0 | F9: =PLUV_38!F9+E9 -> 55 | H9: GUIDER | I9: 20
A10: KAELE | B10: =I7 -> 6 | C10: =PLUV_38!C10+B10 -> 73 | D10: POLI | E10: =I12 -> 4 | F10: =PLUV_38!F10+E10 -> 230 | H10: GAROUA | I10: 1
A11: TCHATIBALI | B11: =I8 -> 0 | C11: =PLUV_38!C11+B11 -> 69 | D11: MAYO-GALKE | E11: =I13 -> 10 | F11: =PLUV_38!F11+E11 -> 163 | H11: NGONG | I11: 0
A12: GUIDER | B12: =I9 -> 20 | C12: =PLUV_38!C12+B12 -> 54 | D12: TOUBORO | E12: =I16 -> 29 | F12: =PLUV_38!F12+E12 -> 253 | H12: POLI | I12: 4
A13: GAROUA | B13: =I10 -> 1 | C13: =PLUV_38!C13+B13 -> 31 | D13: HOME | E13: =I17 -> 18 | F13: =PLUV_38!F13+E13 -> 126 | H13: MAYO-GALKE | I13: 10
A15: TOTAL JOURNALIER = | C15: =SUM(B9:B13)+SUM(E9:E13) -> 90 | D15: CUMUL GENERAL = | F15: =SUM(C9:C13)+SUM(F9:F13) -> 1090
H16: TOUBORO | I16: 29
H17: HOME | I17: 18
A18: Transmis le : | B18: =IFERROR(+I2+1,0) -> 43976

Sheet PLUV_40
A1: SODECOTON
H2: JOURNEE | I2: 43978
A3: PLUVIOMETRIE JOURNALIERE ET PAR PENTADE
H4: TABLEAU DE SAISI
B5: JOURNEE DU : | D5: =I2 -> 43978 | H5: STATION | I5: RELEVES
H6: MAROUA | I6: 0
A7: STATION | B7: RELEVES | D7: STATION | E7: RELEVES | H7: KAELE | I7: 0
B8: JOURNALIER | C8: CUMUL | E8: JOURNALIER | F8: CUMUL | H8: TCHATIBALI | I8: 0
A9: MAROUA | B9: =I6 -> 0 | C9: =PLUV_39!C9+B9 -> 36 | D9: NGONG | E9: =I11 -> 0 | F9: =PLUV_39!F9+E9 -> 55 | H9: GUIDER | I9: 17
A10: KAELE | B10: =I7 -> 0 | C10: =PLUV_39!C10+B10 -> 73 | D10: POLI | E10: =I12 -> 0 | F10: =PLUV_39!F10+E10 -> 230 | H10: GAROUA | I10: 20
A11: TCHATIBALI | B11: =I8 -> 0 | C11: =PLUV_39!C11+B11 -> 69 | D11: MAYO-GALKE | E11: =I13 -> 0 | F11: =PLUV_39!F11+E11 -> 163 | H11: NGONG | I11: 0
A12: GUIDER | B12: =I9 -> 17 | C12: =PLUV_39!C12+B12 -> 71 | D12: TOUBORO | E12: =I16 -> 0 | F12: =PLUV_39!F12+E12 -> 253 | H12: POLI | I12: 0
A13: GAROUA | B13: =I10 -> 20 | C13: =PLUV_39!C13+B13 -> 51 | D13: HOME | E13: =I17 -> 0 | F13: =PLUV_39!F13+E13 -> 126 | H13: MAYO-GALKE | I13: 0
A15: TOTAL JOURNALIER = | C15: =SUM(B9:B13)+SUM(E9:E13) -> 37 | D15: CUMUL GENERAL = | F15: =SUM(C9:C13)+SUM(F9:F13) -> 1127
H16: TOUBORO | I16: 0
H17: HOME | I17: 0
A18: Transmis le : | B18: =IFERROR(+I2+1,0) -> 43979

Sheet PLUV_41
A1: SODECOTON
H2: JOURNEE | I2: 43979
A3: PLUVIOMETRIE JOURNALIERE ET PAR PENTADE
H4: TABLEAU DE SAISI
B5: JOURNEE DU : | D5: =I2 -> 43979 | H5: STATION | I5: RELEVES
H6: MAROUA | I6: 0
A7: STATION | B7: RELEVES | D7: STATION | E7: RELEVES | H7: KAELE | I7: 0
B8: JOURNALIER | C8: CUMUL | E8: JOURNALIER | F8: CUMUL | H8: TCHATIBALI | I8: 0
A9: MAROUA | B9: =I6 -> 0 | C9: =PLUV_40!C9+B9 -> 36 | D9: NGONG | E9: =I11 -> 0 | F9: =PLUV_40!F9+E9 -> 55 | H9: GUIDER | I9: 0
A10: KAELE | B10: =I7 -> 0 | C10: =PLUV_40!C10+B10 -> 73 | D10: POLI | E10: =I12 -> 10 | F10: =PLUV_40!F10+E10 -> 240 | H10: GAROUA | I10: 0
A11: TCHATIBALI | B11: =I8 -> 0 | C11: =PLUV_40!C11+B11 -> 69 | D11: MAYO-GALKE | E11: =I13 -> 0 | F11: =PLUV_40!F11+E11 -> 163 | H11: NGONG | I11: 0
A12: GUIDER | B12: =I9 -> 0 | C12: =PLUV_40!C12+B12 -> 71 | D12: TOUBORO | E12: =I16 -> 0 | F12: =PLUV_40!F12+E12 -> 253 | H12: POLI | I12: 10
A13: GAROUA | B13: =I10 -> 0 | C13: =PLUV_40!C13+B13 -> 51 | D13: HOME | E13: =I17 -> 0 | F13: =PLUV_40!F13+E13 -> 126 | H13: MAYO-GALKE | I13: 0
A15: TOTAL JOURNALIER = | C15: =SUM(B9:B13)+SUM(E9:E13) -> 10 | D15: CUMUL GENERAL = | F15: =SUM(C9:C13)+SUM(F9:F13) -> 1137
H16: TOUBORO | I16: 0
H17: HOME | I17: 0
A18: Transmis le : | B18: =IFERROR(+I2+1,0) -> 43980

Sheet PLUV_42
A1: SODECOTON
H2: JOURNEE | I2: 43980
A3: PLUVIOMETRIE JOURNALIERE ET PAR PENTADE
H4: TABLEAU DE SAISI
B5: JOURNEE DU : | D5: =I2 -> 43980 | H5: STATION | I5: RELEVES
H6: MAROUA | I6: 0
A7: STATION | B7: RELEVES | D7: STATION | E7: RELEVES | H7: KAELE | I7: 9
B8: JOURNALIER | C8: CUMUL | E8: JOURNALIER | F8: CUMUL | H8: TCHATIBALI | I8: 0
A9: MAROUA | B9: =I6 -> 0 | C9: =PLUV_41!C9+B9 -> 36 | D9: NGONG | E9: =I11 -> 0 | F9: =PLUV_41!F9+E9 -> 55 | H9: GUIDER | I9: 7
A10: KAELE | B10: =I7 -> 9 | C10: =PLUV_41!C10+B10 -> 82 | D10: POLI | E10: =I12 -> 0 | F10: =PLUV_41!F10+E10 -> 240 | H10: GAROUA | I10: 0
A11: TCHATIBALI | B11: =I8 -> 0 | C11: =PLUV_41!C11+B11 -> 69 | D11: MAYO-GALKE | E11: =I13 -> 0 | F11: =PLUV_41!F11+E11 -> 163 | H11: NGONG | I11: 0
A12: GUIDER | B12: =I9 -> 7 | C12: =PLUV_41!C12+B12 -> 78 | D12: TOUBORO | E12: =I16 -> 0 | F12: =PLUV_41!F12+E12 -> 253 | H12: POLI | I12: 0
A13: GAROUA | B13: =I10 -> 0 | C13: =PLUV_41!C13+B13 -> 51 | D13: HOME | E13: =I17 -> 0 | F13: =PLUV_41!F13+E13 -> 126 | H13: MAYO-GALKE | I13: 0
A15: TOTAL JOURNALIER = | C15: =SUM(B9:B13)+SUM(E9:E13) -> 16 | D15: CUMUL GENERAL = | F15: =SUM(C9:C13)+SUM(F9:F13) -> 1153
H16: TOUBORO | I16: 0
H17: HOME | I17: 0
A18: Transmis le : | B18: =IFERROR(+I2+1,0) -> 43981

Sheet PLUV_43
A1: SODECOTON
H2: JOURNEE | I2: 43983
A3: PLUVIOMETRIE JOURNALIERE ET PAR PENTADE
H4: TABLEAU DE SAISI
B5: JOURNEE DU : | D5: =I2 -> 43983 | H5: STATION | I5: RELEVES
H6: MAROUA | I6: 0
A7: STATION | B7: RELEVES | D7: STATION | E7: RELEVES | H7: KAELE | I7: 0
B8: JOURNALIER | C8: CUMUL | E8: JOURNALIER | F8: CUMUL | H8: TCHATIBALI | I8: 6
A9: MAROUA | B9: =I6 -> 0 | C9: =PLUV_42!C9+B9 -> 36 | D9: NGONG | E9: =I11 -> 0 | F9: =PLUV_42!F9+E9 -> 55 | H9: GUIDER | I9: 19
A10: KAELE | B10: =I7 -> 0 | C10: =PLUV_42!C10+B10 -> 82 | D10: POLI | E10: =I12 -> 28 | F10: =PLUV_42!F10+E10 -> 268 | H10: GAROUA | I10: 2
A11: TCHATIBALI | B11: =I8 -> 6 | C11: =PLUV_42!C11+B11 -> 75 | D11: MAYO-GALKE | E11: =I13 -> 0 | F11: =PLUV_42!F11+E11 -> 163 | H11: NGONG | I11: 0
A12: GUIDER | B12: =I9 -> 19 | C12: =PLUV_42!C12+B12 -> 97 | D12: TOUBORO | E12: =I16 -> 5 | F12: =PLUV_42!F12+E12 -> 258 | H12: POLI | I12: 28
A13: GAROUA | B13: =I10 -> 2 | C13: =PLUV_42!C13+B13 -> 53 | D13: HOME | E13: =I17 -> 0 | F13: =PLUV_42!F13+E13 -> 126 | H13: MAYO-GALKE | I13: 0
A15: TOTAL JOURNALIER = | C15: =SUM(B9:B13)+SUM(E9:E13) -> 60 | D15: CUMUL GENERAL = | F15: =SUM(C9:C13)+SUM(F9:F13) -> 1213
H16: TOUBORO | I16: 5
H17: HOME | I17: 0
A18: Transmis le : | B18: =IFERROR(+I2+1,0) -> 43984

Sheet PLUV_44
A1: SODECOTON
H2: JOURNEE | I2: 43984
A3: PLUVIOMETRIE JOURNALIERE ET PAR PENTADE
H4: TABLEAU DE SAISI
B5: JOURNEE DU : | D5: =I2 -> 43984 | H5: STATION | I5: RELEVES
H6: MAROUA | I6: 0
A7: STATION | B7: RELEVES | D7: STATION | E7: RELEVES | H7: KAELE | I7: 1
B8: JOURNALIER | C8: CUMUL | E8: JOURNALIER | F8: CUMUL | H8: TCHATIBALI | I8: 0
A9: MAROUA | B9: =I6 -> 0 | C9: =PLUV_43!C9+B9 -> 36 | D9: NGONG | E9: =I11 -> 0 | F9: =PLUV_43!F9+E9 -> 55 | H9: GUIDER | I9: 0
A10: KAELE | B10: =I7 -> 1 | C10: =PLUV_43!C10+B10 -> 83 | D10: POLI | E10: =I12 -> 0 | F10: =PLUV_43!F10+E10 -> 268 | H10: GAROUA | I10: 0
A11: TCHATIBALI | B11: =I8 -> 0 | C11: =PLUV_43!C11+B11 -> 75 | D11: MAYO-GALKE | E11: =I13 -> 0 | F11: =PLUV_43!F11+E11 -> 163 | H11: NGONG | I11: 0
A12: GUIDER | B12: =I9 -> 0 | C12: =PLUV_43!C12+B12 -> 97 | D12: TOUBORO | E12: =I16 -> 2 | F12: =PLUV_43!F12+E12 -> 260 | H12: POLI | I12: 0
A13: GAROUA | B13: =I10 -> 0 | C13: =PLUV_43!C13+B13 -> 53 | D13: HOME | E13: =I17 -> 0 | F13: =PLUV_43!F13+E13 -> 126 | H13: MAYO-GALKE | I13: 0
A15: TOTAL JOURNALIER = | C15: =SUM(B9:B13)+SUM(E9:E13) -> 3 | D15: CUMUL GENERAL = | F15: =SUM(C9:C13)+SUM(F9:F13) -> 1216
H16: TOUBORO | I16: 2
H17: HOME | I17: 0
A18: Transmis le : | B18: =IFERROR(+I2+1,0) -> 43985

Sheet PLUV_45
A1: SODECOTON
H2: JOURNEE | I2: 43985
A3: PLUVIOMETRIE JOURNALIERE ET PAR PENTADE
H4: TABLEAU DE SAISI
B5: JOURNEE DU : | D5: =I2 -> 43985 | H5: STATION | I5: RELEVES
H6: MAROUA | I6: 0
A7: STATION | B7: RELEVES | D7: STATION | E7: RELEVES | H7: KAELE | I7: 0
B8: JOURNALIER | C8: CUMUL | E8: JOURNALIER | F8: CUMUL | H8: TCHATIBALI | I8: 0
A9: MAROUA | B9: =I6 -> 0 | C9: =PLUV_44!C9+B9 -> 36 | D9: NGONG | E9: =I11 -> 0 | F9: =PLUV_44!F9+E9 -> 55 | H9: GUIDER | I9: 0
A10: KAELE | B10: =I7 -> 0 | C10: =PLUV_44!C10+B10 -> 83 | D10: POLI | E10: =I12 -> 0 | F10: =PLUV_44!F10+E10 -> 268 | H10: GAROUA | I10: 0
A11: TCHATIBALI | B11: =I8 -> 0 | C11: =PLUV_44!C11+B11 -> 75 | D11: MAYO-GALKE | E11: =I13 -> 10 | F11: =PLUV_44!F11+E11 -> 173 | H11: NGONG | I11: 0
A12: GUIDER | B12: =I9 -> 0 | C12: =PLUV_44!C12+B12 -> 97 | D12: TOUBORO | E12: =I16 -> 0 | F12: =PLUV_44!F12+E12 -> 260 | H12: POLI | I12: 0
A13: GAROUA | B13: =I10 -> 0 | C13: =PLUV_44!C13+B13 -> 53 | D13: HOME | E13: =I17 -> 0 | F13: =PLUV_44!F13+E13 -> 126 | H13: MAYO-GALKE | I13: 10
A15: TOTAL JOURNALIER = | C15: =SUM(B9:B13)+SUM(E9:E13) -> 10 | D15: CUMUL GENERAL = | F15: =SUM(C9:C13)+SUM(F9:F13) -> 1226
H16: TOUBORO | I16: 0
H17: HOME | I17: 0
A18: Transmis le : | B18: =IFERROR(+I2+1,0) -> 43986

Sheet PLUV_46
A1: SODECOTON
H2: JOURNEE | I2: 43987
A3: PLUVIOMETRIE JOURNALIERE ET PAR PENTADE
H4: TABLEAU DE SAISI
B5: JOURNEE DU : | D5: =I2 -> 43987 | H5: STATION | I5: RELEVES
H6: MAROUA | I6: 3
A7: STATION | B7: RELEVES | D7: STATION | E7: RELEVES | H7: KAELE | I7: 7
B8: JOURNALIER | C8: CUMUL | E8: JOURNALIER | F8: CUMUL | H8: TCHATIBALI | I8: 7
A9: MAROUA | B9: =I6 -> 3 | C9: =PLUV_45!C9+B9 -> 39 | D9: NGONG | E9: =I11 -> 26 | F9: =PLUV_45!F9+E9 -> 81 | H9: GUIDER | I9: 7
A10: KAELE | B10: =I7 -> 7 | C10: =PLUV_45!C10+B10 -> 90 | D10: POLI | E10: =I12 -> 36 | F10: =PLUV_45!F10+E10 -> 304 | H10: GAROUA | I10: 20
A11: TCHATIBALI | B11: =I8 -> 7 | C11: =PLUV_45!C11+B11 -> 82 | D11: MAYO-GALKE | E11: =I13 -> 16 | F11: =PLUV_45!F11+E11 -> 189 | H11: NGONG | I11: 26
A12: GUIDER | B12: =I9 -> 7 | C12: =PLUV_45!C12+B12 -> 104 | D12: TOUBORO | E12: =I16 -> 35 | F12: =PLUV_45!F12+E12 -> 295 | H12: POLI | I12: 36
A13: GAROUA | B13: =I10 -> 20 | C13: =PLUV_45!C13+B13 -> 73 | D13: HOME | E13: =I17 -> 13 | F13: =PLUV_45!F13+E13 -> 139 | H13: MAYO-GALKE | I13: 16
A15: TOTAL JOURNALIER = | C15: =SUM(B9:B13)+SUM(E9:E13) -> 170 | D15: CUMUL GENERAL = | F15: =SUM(C9:C13)+SUM(F9:F13) -> 1396
H16: TOUBORO | I16: 35
H17: HOME | I17: 13
A18: Transmis le : | B18: =IFERROR(+I2+1,0) -> 43988

Sheet PLUV_47
A1: SODECOTON
H2: JOURNEE | I2: 43988
A3: PLUVIOMETRIE JOURNALIERE ET PAR PENTADE
H4: TABLEAU DE SAISI
B5: JOURNEE DU : | D5: =I2 -> 43988 | H5: STATION | I5: RELEVES
H6: MAROUA | I6: 0
A7: STATION | B7: RELEVES | D7: STATION | E7: RELEVES | H7: KAELE | I7: 0
B8: JOURNALIER | C8: CUMUL | E8: JOURNALIER | F8: CUMUL | H8: TCHATIBALI | I8: 0
A9: MAROUA | B9: =I6 -> 0 | C9: =PLUV_46!C9+B9 -> 39 | D9: NGONG | E9: =I11 -> 0 | F9: =PLUV_46!F9+E9 -> 81 | H9: GUIDER | I9: 0
A10: KAELE | B10: =I7 -> 0 | C10: =PLUV_46!C10+B10 -> 90 | D10: POLI | E10: =I12 -> 0 | F10: =PLUV_46!F10+E10 -> 304 | H10: GAROUA | I10: 0
A11: TCHATIBALI | B11: =I8 -> 0 | C11: =PLUV_46!C11+B11 -> 82 | D11: MAYO-GALKE | E11: =I13 -> 1 | F11: =PLUV_46!F11+E11 -> 190 | H11: NGONG | I11: 0
A12: GUIDER | B12: =I9 -> 0 | C12: =PLUV_46!C12+B12 -> 104 | D12: TOUBORO | E12: =I16 -> 0 | F12: =PLUV_46!F12+E12 -> 295 | H12: POLI | I12: 0
A13: GAROUA | B13: =I10 -> 0 | C13: =PLUV_46!C13+B13 -> 73 | D13: HOME | E13: =I17 -> 0 | F13: =PLUV_46!F13+E13 -> 139 | H13: MAYO-GALKE | I13: 1
A15: TOTAL JOURNALIER = | C15: =SUM(B9:B13)+SUM(E9:E13) -> 1 | D15: CUMUL GENERAL = | F15: =SUM(C9:C13)+SUM(F9:F13) -> 1397
H16: TOUBORO | I16: 0
H17: HOME | I17: 0
A18: Transmis le : | B18: =IFERROR(+I2+1,0) -> 43989

Sheet PLUV_48
A1: SODECOTON
H2: JOURNEE | I2: 43989
A3: PLUVIOMETRIE JOURNALIERE ET PAR PENTADE
H4: TABLEAU DE SAISI
