Workbook

Sheet 26-03-14
A1: SODECOTON
H2: TABLEAU DE SAISI
A3: PLUVIOMETRIE JOURNALIERE ET PAR PENTADE | H3: STATION | I3: RELEVES
H4: MAROUA | I4: 0
B5: JOURNEE DU : | D5: =I15 -> 41724 | H5: KAELE | I5: 0
H6: TCHATIBALI | I6: 0
A7: STATION | B7: RELEVES | D7: STATION | E7: RELEVES | H7: GUIDER | I7: 0
B8: JOURNALIER | C8: CUMUL | E8: JOURNALIER | F8: CUMUL | H8: GAROUA | I8: 1
A9: MAROUA | B9: =I4 -> 0 | C9: =B9 -> 0 | D9: NGONG | E9: =I9 -> 0 | F9: =E9 -> 0 | H9: NGONG | I9: 0
A10: KAELE | B10: =I5 -> 0 | C10: =B10 -> 0 | D10: POLI | E10: =I10 -> 11 | F10: =E10 -> 11 | H10: POLI | I10: 11
A11: TCHATIBALI | B11: =I6 -> 0 | C11: =B11 -> 0 | D11: MAYO-GALKE | E11: =I11 -> 22 | F11: =E11 -> 22 | H11: MAYO-GALKE | I11: 22
A12: GUIDER | B12: =I7 -> 0 | C12: =B12 -> 0 | D12: TOUBOURO | E12: =I12 -> 8 | F12: =E12 -> 8 | H12: TOUBOURO | I12: 8
A13: GAROUA | B13: =I8 -> 1 | C13: =B13 -> 1 | D13: HOME | E13: =I13 -> 4 | F13: =E13 -> 4 | H13: HOME | I13: 4
A15: TOTAL JOURNALIER = | C15: =SUM(B9:B13)+SUM(E9:E13) -> 46 | D15: CUMUL GENERAL = | F15: =SUM(C9:C13)+SUM(F9:F13) -> 46 | H15: JOURNEE | I15: 41724
H16: TRANSMISSION | I16: =I15+1 -> 41725
A20: Transmis le : | B20: =I16 -> 41725

Sheet 27-03-14
A1: SODECOTON
H2: TABLEAU DE SAISI
A3: PLUVIOMETRIE JOURNALIERE ET PAR PENTADE | H3: STATION | I3: RELEVES
H4: MAROUA | I4: 2
B5: JOURNEE DU : | D5: =I15 -> 41725 | H5: KAELE | I5: 3
H6: TCHATIBALI | I6: 0
A7: STATION | B7: RELEVES | D7: STATION | E7: RELEVES | H7: GUIDER | I7: 7
B8: JOURNALIER | C8: CUMUL | E8: JOURNALIER | F8: CUMUL | H8: GAROUA | I8: 2
A9: MAROUA | B9: =I4 -> 2 | C9: ='26-03-14'!C9+B9 -> 2 | D9: NGONG | E9: =I9 -> 0 | F9: ='26-03-14'!F9+E9 -> 0 | H9: NGONG | I9: 0
A10: KAELE | B10: =I5 -> 3 | C10: ='26-03-14'!C10+B10 -> 3 | D10: POLI | E10: =I10 -> 4 | F10: ='26-03-14'!F10+E10 -> 15 | H10: POLI | I10: 4
A11: TCHATIBALI | B11: =I6 -> 0 | C11: ='26-03-14'!C11+B11 -> 0 | D11: MAYO-GALKE | E11: =I11 -> 0 | F11: ='26-03-14'!F11+E11 -> 22 | H11: MAYO-GALKE | I11: 0
A12: GUIDER | B12: =I7 -> 7 | C12: ='26-03-14'!C12+B12 -> 7 | D12: TOUBOURO | E12: =I12 -> 0 | F12: ='26-03-14'!F12+E12 -> 8 | H12: TOUBOURO | I12: 0
A13: GAROUA | B13: =I8 -> 2 | C13: ='26-03-14'!C13+B13 -> 3 | D13: HOME | E13: =I13 -> 0 | F13: ='26-03-14'!F13+E13 -> 4 | H13: HOME | I13: 0
A15: TOTAL JOURNALIER = | C15: =SUM(B9:B13)+SUM(E9:E13) -> 18 | D15: CUMUL GENERAL = | F15: =SUM(C9:C13)+SUM(F9:F13) -> 64 | H15: JOURNEE | I15: 41725
H16: TRANSMISSION | I16: =I15+1 -> 41726
A20: Transmis le : | B20: =I16 -> 41726

Sheet 28-03-14
A1: SODECOTON
H2: TABLEAU DE SAISI
A3: PLUVIOMETRIE JOURNALIERE ET PAR PENTADE | H3: STATION | I3: RELEVES
H4: MAROUA | I4: 0
B5: JOURNEE DU : | D5: =I15 -> 41726 | H5: KAELE | I5: 2
H6: TCHATIBALI | I6: 0
A7: STATION | B7: RELEVES | D7: STATION | E7: RELEVES | H7: GUIDER | I7: 4
B8: JOURNALIER | C8: CUMUL | E8: JOURNALIER | F8: CUMUL | H8: GAROUA | I8: 0
A9: MAROUA | B9: =I4 -> 0 | C9: ='27-03-14'!C9+B9 -> 2 | D9: NGONG | E9: =I9 -> 0 | F9: ='27-03-14'!F9+E9 -> 0 | H9: NGONG | I9: 0
A10: KAELE | B10: =I5 -> 2 | C10: ='27-03-14'!C10+B10 -> 5 | D10: POLI | E10: =I10 -> 0 | F10: ='27-03-14'!F10+E10 -> 15 | H10: POLI | I10: 0
A11: TCHATIBALI | B11: =I6 -> 0 | C11: ='27-03-14'!C11+B11 -> 0 | D11: MAYO-GALKE | E11: =I11 -> 0 | F11: ='27-03-14'!F11+E11 -> 22 | H11: MAYO-GALKE | I11: 0
A12: GUIDER | B12: =I7 -> 4 | C12: ='27-03-14'!C12+B12 -> 11 | D12: TOUBOURO | E12: =I12 -> 0 | F12: ='27-03-14'!F12+E12 -> 8 | H12: TOUBOURO | I12: 0
A13: GAROUA | B13: =I8 -> 0 | C13: ='27-03-14'!C13+B13 -> 3 | D13: HOME | E13: =I13 -> 0 | F13: ='27-03-14'!F13+E13 -> 4 | H13: HOME | I13: 0
A15: TOTAL JOURNALIER = | C15: =SUM(B9:B13)+SUM(E9:E13) -> 6 | D15: CUMUL GENERAL = | F15: =SUM(C9:C13)+SUM(F9:F13) -> 70 | H15: JOURNEE | I15: 41726
H16: TRANSMISSION | I16: =I15+1 -> 41727
A20: Transmis le : | B20: =I16 -> 41727

Sheet 29-03-14
A1: SODECOTON
H2: TABLEAU DE SAISI
A3: PLUVIOMETRIE JOURNALIERE ET PAR PENTADE | H3: STATION | I3: RELEVES
H4: MAROUA | I4: 0
B5: JOURNEE DU : | D5: =I15 -> 41727 | H5: KAELE | I5: 3
H6: TCHATIBALI | I6: 10
A7: STATION | B7: RELEVES | D7: STATION | E7: RELEVES | H7: GUIDER | I7: 0
B8: JOURNALIER | C8: CUMUL | E8: JOURNALIER | F8: CUMUL | H8: GAROUA | I8: 11
A9: MAROUA | B9: =I4 -> 0 | C9: ='28-03-14'!C9+B9 -> 2 | D9: NGONG | E9: =I9 -> 6 | F9: ='28-03-14'!F9+E9 -> 6 | H9: NGONG | I9: 6
A10: KAELE | B10: =I5 -> 3 | C10: ='28-03-14'!C10+B10 -> 8 | D10: POLI | E10: =I10 -> 0 | F10: ='28-03-14'!F10+E10 -> 15 | H10: POLI | I10: 0
A11: TCHATIBALI | B11: =I6 -> 10 | C11: ='28-03-14'!C11+B11 -> 10 | D11: MAYO-GALKE | E11: =I11 -> 9 | F11: ='28-03-14'!F11+E11 -> 31 | H11: MAYO-GALKE | I11: 9
A12: GUIDER | B12: =I7 -> 0 | C12: ='28-03-14'!C12+B12 -> 11 | D12: TOUBOURO | E12: =I12 -> 0 | F12: ='28-03-14'!F12+E12 -> 8 | H12: TOUBOURO | I12: 0
A13: GAROUA | B13: =I8 -> 11 | C13: ='28-03-14'!C13+B13 -> 14 | D13: HOME | E13: =I13 -> 0 | F13: ='28-03-14'!F13+E13 -> 4 | H13: HOME | I13: 0
A15: TOTAL JOURNALIER = | C15: =SUM(B9:B13)+SUM(E9:E13) -> 39 | D15: CUMUL GENERAL = | F15: =SUM(C9:C13)+SUM(F9:F13) -> 109 | H15: JOURNEE | I15: 41727
H16: TRANSMISSION | I16: =I15+1 -> 41728
A20: Transmis le : | B20: =I16 -> 41728

Sheet 30-03-14
A1: SODECOTON
H2: TABLEAU DE SAISI
A3: PLUVIOMETRIE JOURNALIERE ET PAR PENTADE | H3: STATION | I3: RELEVES
H4: MAROUA | I4: 0
B5: JOURNEE DU : | D5: =I15 -> 41728 | H5: KAELE | I5: 0
H6: TCHATIBALI | I6: 0
A7: STATION | B7: RELEVES | D7: STATION | E7: RELEVES | H7: GUIDER | I7: 0
B8: JOURNALIER | C8: CUMUL | E8: JOURNALIER | F8: CUMUL | H8: GAROUA | I8: 1
A9: MAROUA | B9: =I4 -> 0 | C9: ='29-03-14'!C9+B9 -> 2 | D9: NGONG | E9: =I9 -> 0 | F9: ='29-03-14'!F9+E9 -> 6 | H9: NGONG | I9: 0
A10: KAELE | B10: =I5 -> 0 | C10: ='29-03-14'!C10+B10 -> 8 | D10: POLI | E10: =I10 -> 43 | F10: ='29-03-14'!F10+E10 -> 58 | H10: POLI | I10: 43
A11: TCHATIBALI | B11: =I6 -> 0 | C11: ='29-03-14'!C11+B11 -> 10 | D11: MAYO-GALKE | E11: =I11 -> 0 | F11: ='29-03-14'!F11+E11 -> 31 | H11: MAYO-GALKE | I11: 0
A12: GUIDER | B12: =I7 -> 0 | C12: ='29-03-14'!C12+B12 -> 11 | D12: TOUBOURO | E12: =I12 -> 2 | F12: ='29-03-14'!F12+E12 -> 10 | H12: TOUBOURO | I12: 2
A13: GAROUA | B13: =I8 -> 1 | C13: ='29-03-14'!C13+B13 -> 15 | D13: HOME | E13: =I13 -> 23 | F13: ='29-03-14'!F13+E13 -> 27 | H13: HOME | I13: 23
A15: TOTAL JOURNALIER = | C15: =SUM(B9:B13)+SUM(E9:E13) -> 69 | D15: CUMUL GENERAL = | F15: =SUM(C9:C13)+SUM(F9:F13) -> 178 | H15: JOURNEE | I15: 41728
H16: TRANSMISSION | I16: =I15+1 -> 41729
A20: Transmis le : | B20: =I16 -> 41729

Sheet 31-03-14
A1: SODECOTON
H2: TABLEAU DE SAISI
A3: PLUVIOMETRIE JOURNALIERE ET PAR PENTADE | H3: STATION | I3: RELEVES
H4: MAROUA | I4: 0
B5: JOURNEE DU : | D5: =I15 -> 41729 | H5: KAELE | I5: 0
H6: TCHATIBALI | I6: 0
A7: STATION | B7: RELEVES | D7: STATION | E7: RELEVES | H7: GUIDER | I7: 0
B8: JOURNALIER | C8: CUMUL | E8: JOURNALIER | F8: CUMUL | H8: GAROUA | I8: 0
A9: MAROUA | B9: =I4 -> 0 | C9: ='30-03-14'!C9+B9 -> 2 | D9: NGONG | E9: =I9 -> 0 | F9: ='30-03-14'!F9+E9 -> 6 | H9: NGONG | I9: 0
A10: KAELE | B10: =I5 -> 0 | C10: ='30-03-14'!C10+B10 -> 8 | D10: POLI | E10: =I10 -> 0 | F10: ='30-03-14'!F10+E10 -> 58 | H10: POLI | I10: 0
A11: TCHATIBALI | B11: =I6 -> 0 | C11: ='30-03-14'!C11+B11 -> 10 | D11: MAYO-GALKE | E11: =I11 -> 0 | F11: ='30-03-14'!F11+E11 -> 31 | H11: MAYO-GALKE | I11: 0
A12: GUIDER | B12: =I7 -> 0 | C12: ='30-03-14'!C12+B12 -> 11 | D12: TOUBOURO | E12: =I12 -> 0 | F12: ='30-03-14'!F12+E12 -> 10 | H12: TOUBOURO | I12: 0
A13: GAROUA | B13: =I8 -> 0 | C13: ='30-03-14'!C13+B13 -> 15 | D13: HOME | E13: =I13 -> 0 | F13: ='30-03-14'!F13+E13 -> 27 | H13: HOME | I13: 0
A15: TOTAL JOURNALIER = | C15: =SUM(B9:B13)+SUM(E9:E13) -> 0 | D15: CUMUL GENERAL = | F15: =SUM(C9:C13)+SUM(F9:F13) -> 178 | H15: JOURNEE | I15: 41729
H16: TRANSMISSION | I16: =I15+1 -> 41730
A20: Transmis le : | B20: =I16 -> 41730

Sheet 01-04-14
A1: SODECOTON
H2: TABLEAU DE SAISI
A3: PLUVIOMETRIE JOURNALIERE ET PAR PENTADE | H3: STATION | I3: RELEVES
H4: MAROUA | I4: 0
B5: JOURNEE DU : | D5: =I15 -> 41730 | H5: KAELE | I5: 0
H6: TCHATIBALI | I6: 0
A7: STATION | B7: RELEVES | D7: STATION | E7: RELEVES | H7: GUIDER | I7: 0
B8: JOURNALIER | C8: CUMUL | E8: JOURNALIER | F8: CUMUL | H8: GAROUA | I8: 0
A9: MAROUA | B9: =I4 -> 0 | C9: ='31-03-14'!C9+B9 -> 2 | D9: NGONG | E9: =I9 -> 0 | F9: ='31-03-14'!F9+E9 -> 6 | H9: NGONG | I9: 0
A10: KAELE | B10: =I5 -> 0 | C10: ='31-03-14'!C10+B10 -> 8 | D10: POLI | E10: =I10 -> 0 | F10: ='31-03-14'!F10+E10 -> 58 | H10: POLI | I10: 0
A11: TCHATIBALI | B11: =I6 -> 0 | C11: ='31-03-14'!C11+B11 -> 10 | D11: MAYO-GALKE | E11: =I11 -> 0 | F11: ='31-03-14'!F11+E11 -> 31 | H11: MAYO-GALKE | I11: 0
A12: GUIDER | B12: =I7 -> 0 | C12: ='31-03-14'!C12+B12 -> 11 | D12: TOUBOURO | E12: =I12 -> 0 | F12: ='31-03-14'!F12+E12 -> 10 | H12: TOUBOURO | I12: 0
A13: GAROUA | B13: =I8 -> 0 | C13: ='31-03-14'!C13+B13 -> 15 | D13: HOME | E13: =I13 -> 0 | F13: ='31-03-14'!F13+E13 -> 27 | H13: HOME | I13: 0
A15: TOTAL JOURNALIER = | C15: =SUM(B9:B13)+SUM(E9:E13) -> 0 | D15: CUMUL GENERAL = | F15: =SUM(C9:C13)+SUM(F9:F13) -> 178 | H15: JOURNEE | I15: 41730
H16: TRANSMISSION | I16: =I15+1 -> 41731
A20: Transmis le : | B20: =I16 -> 41731

Sheet 02-04-14
A1: SODECOTON
H2: TABLEAU DE SAISI
A3: PLUVIOMETRIE JOURNALIERE ET PAR PENTADE | H3: STATION | I3: RELEVES
H4: MAROUA | I4: 0
B5: JOURNEE DU : | D5: =I15 -> 41731 | H5: KAELE | I5: 0
H6: TCHATIBALI | I6: 0
A7: STATION | B7: RELEVES | D7: STATION | E7: RELEVES | H7: GUIDER | I7: 0
B8: JOURNALIER | C8: CUMUL | E8: JOURNALIER | F8: CUMUL | H8: GAROUA | I8: 0
A9: MAROUA | B9: =I4 -> 0 | C9: ='01-04-14'!C9+B9 -> 2 | D9: NGONG | E9: =I9 -> 0 | F9: ='01-04-14'!F9+E9 -> 6 | H9: NGONG | I9: 0
A10: KAELE | B10: =I5 -> 0 | C10: ='01-04-14'!C10+B10 -> 8 | D10: POLI | E10: =I10 -> 0 | F10: ='01-04-14'!F10+E10 -> 58 | H10: POLI | I10: 0
A11: TCHATIBALI | B11: =I6 -> 0 | C11: ='01-04-14'!C11+B11 -> 10 | D11: MAYO-GALKE | E11: =I11 -> 0 | F11: ='01-04-14'!F11+E11 -> 31 | H11: MAYO-GALKE | I11: 0
A12: GUIDER | B12: =I7 -> 0 | C12: ='01-04-14'!C12+B12 -> 11 | D12: TOUBOURO | E12: =I12 -> 0 | F12: ='01-04-14'!F12+E12 -> 10 | H12: TOUBOURO | I12: 0
A13: GAROUA | B13: =I8 -> 0 | C13: ='01-04-14'!C13+B13 -> 15 | D13: HOME | E13: =I13 -> 0 | F13: ='01-04-14'!F13+E13 -> 27 | H13: HOME | I13: 0
A15: TOTAL JOURNALIER = | C15: =SUM(B9:B13)+SUM(E9:E13) -> 0 | D15: CUMUL GENERAL = | F15: =SUM(C9:C13)+SUM(F9:F13) -> 178 | H15: JOURNEE | I15: 41731
H16: TRANSMISSION | I16: =I15+1 -> 41732
A20: Transmis le : | B20: =I16 -> 41732

Sheet 03-04-14
A1: SODECOTON
H2: TABLEAU DE SAISI
A3: PLUVIOMETRIE JOURNALIERE ET PAR PENTADE | H3: STATION | I3: RELEVES
H4: MAROUA | I4: 0
B5: JOURNEE DU : | D5: =I15 -> 41732 | H5: KAELE | I5: 0
H6: TCHATIBALI | I6: 0
A7: STATION | B7: RELEVES | D7: STATION | E7: RELEVES | H7: GUIDER | I7: 0
B8: JOURNALIER | C8: CUMUL | E8: JOURNALIER | F8: CUMUL | H8: GAROUA | I8: 0
A9: MAROUA | B9: =I4 -> 0 | C9: ='02-04-14'!C9+B9 -> 2 | D9: NGONG | E9: =I9 -> 0 | F9: ='02-04-14'!F9+E9 -> 6 | H9: NGONG | I9: 0
A10: KAELE | B10: =I5 -> 0 | C10: ='02-04-14'!C10+B10 -> 8 | D10: POLI | E10: =I10 -> 0 | F10: ='02-04-14'!F10+E10 -> 58 | H10: POLI | I10: 0
A11: TCHATIBALI | B11: =I6 -> 0 | C11: ='02-04-14'!C11+B11 -> 10 | D11: MAYO-GALKE | E11: =I11 -> 0 | F11: ='02-04-14'!F11+E11 -> 31 | H11: MAYO-GALKE | I11: 0
A12: GUIDER | B12: =I7 -> 0 | C12: ='02-04-14'!C12+B12 -> 11 | D12: TOUBOURO | E12: =I12 -> 0 | F12: ='02-04-14'!F12+E12 -> 10 | H12: TOUBOURO | I12: 0
A13: GAROUA | B13: =I8 -> 0 | C13: ='02-04-14'!C13+B13 -> 15 | D13: HOME | E13: =I13 -> 0 | F13: ='02-04-14'!F13+E13 -> 27 | H13: HOME | I13: 0
A15: TOTAL JOURNALIER = | C15: =SUM(B9:B13)+SUM(E9:E13) -> 0 | D15: CUMUL GENERAL = | F15: =SUM(C9:C13)+SUM(F9:F13) -> 178 | H15: JOURNEE | I15: 41732
H16: TRANSMISSION | I16: =I15+1 -> 41733
A20: Transmis le : | B20: =I16 -> 41733

Sheet 04-04-14
A1: SODECOTON
H2: TABLEAU DE SAISI
A3: PLUVIOMETRIE JOURNALIERE ET PAR PENTADE | H3: STATION | I3: RELEVES
H4: MAROUA | I4: 0
B5: JOURNEE DU : | D5: =I15 -> 41733 | H5: KAELE | I5: 0
H6: TCHATIBALI | I6: 0
A7: STATION | B7: RELEVES | D7: STATION | E7: RELEVES | H7: GUIDER | I7: 0
B8: JOURNALIER | C8: CUMUL | E8: JOURNALIER | F8: CUMUL | H8: GAROUA | I8: 0
A9: MAROUA | B9: =I4 -> 0 | C9: ='03-04-14'!C9+B9 -> 2 | D9: NGONG | E9: =I9 -> 0 | F9: ='03-04-14'!F9+E9 -> 6 | H9: NGONG | I9: 0
A10: KAELE | B10: =I5 -> 0 | C10: ='03-04-14'!C10+B10 -> 8 | D10: POLI | E10: =I10 -> 0 | F10: ='03-04-14'!F10+E10 -> 58 | H10: POLI | I10: 0
A11: TCHATIBALI | B11: =I6 -> 0 | C11: ='03-04-14'!C11+B11 -> 10 | D11: MAYO-GALKE | E11: =I11 -> 0 | F11: ='03-04-14'!F11+E11 -> 31 | H11: MAYO-GALKE | I11: 0
A12: GUIDER | B12: =I7 -> 0 | C12: ='03-04-14'!C12+B12 -> 11 | D12: TOUBOURO | E12: =I12 -> 0 | F12: ='03-04-14'!F12+E12 -> 10 | H12: TOUBOURO | I12: 0
A13: GAROUA | B13: =I8 -> 0 | C13: ='03-04-14'!C13+B13 -> 15 | D13: HOME | E13: =I13 -> 0 | F13: ='03-04-14'!F13+E13 -> 27 | H13: HOME | I13: 0
A15: TOTAL JOURNALIER = | C15: =SUM(B9:B13)+SUM(E9:E13) -> 0 | D15: CUMUL GENERAL = | F15: =SUM(C9:C13)+SUM(F9:F13) -> 178 | H15: JOURNEE | I15: 41733
H16: TRANSMISSION | I16: =I15+1 -> 41734
A20: Transmis le : | B20: =I16 -> 41734

Sheet 05-04-14
A1: SODECOTON
H2: TABLEAU DE SAISI
A3: PLUVIOMETRIE JOURNALIERE ET PAR PENTADE | H3: STATION | I3: RELEVES
H4: MAROUA | I4: 0
B5: JOURNEE DU : | D5: =I15 -> 41734 | H5: KAELE | I5: 0
H6: TCHATIBALI | I6: 0
A7: STATION | B7: RELEVES | D7: STATION | E7: RELEVES | H7: GUIDER | I7: 0
B8: JOURNALIER | C8: CUMUL | E8: JOURNALIER | F8: CUMUL | H8: GAROUA | I8: 0
A9: MAROUA | B9: =I4 -> 0 | C9: ='04-04-14'!C9+B9 -> 2 | D9: NGONG | E9: =I9 -> 0 | F9: ='04-04-14'!F9+E9 -> 6 | H9: NGONG | I9: 0
A10: KAELE | B10: =I5 -> 0 | C10: ='04-04-14'!C10+B10 -> 8 | D10: POLI | E10: =I10 -> 0 | F10: ='04-04-14'!F10+E10 -> 58 | H10: POLI | I10: 0
A11: TCHATIBALI | B11: =I6 -> 0 | C11: ='04-04-14'!C11+B11 -> 10 | D11: MAYO-GALKE | E11: =I11 -> 0 | F11: ='04-04-14'!F11+E11 -> 31 | H11: MAYO-GALKE | I11: 0
A12: GUIDER | B12: =I7 -> 0 | C12: ='04-04-14'!C12+B12 -> 11 | D12: TOUBOURO | E12: =I12 -> 0 | F12: ='04-04-14'!F12+E12 -> 10 | H12: TOUBOURO | I12: 0
A13: GAROUA | B13: =I8 -> 0 | C13: ='04-04-14'!C13+B13 -> 15 | D13: HOME | E13: =I13 -> 0 | F13: ='04-04-14'!F13+E13 -> 27 | H13: HOME | I13: 0
A15: TOTAL JOURNALIER = | C15: =SUM(B9:B13)+SUM(E9:E13) -> 0 | D15: CUMUL GENERAL = | F15: =SUM(C9:C13)+SUM(F9:F13) -> 178 | H15: JOURNEE | I15: 41734
H16: TRANSMISSION | I16: =I15+1 -> 41735
A20: Transmis le : | B20: =I16 -> 41735

Sheet 06-04-14
A1: SODECOTON
H2: TABLEAU DE SAISI
A3: PLUVIOMETRIE JOURNALIERE ET PAR PENTADE | H3: STATION | I3: RELEVES
H4: MAROUA | I4: 0
B5: JOURNEE DU : | D5: =I15 -> 41735 | H5: KAELE | I5: 0
H6: TCHATIBALI | I6: 0
A7: STATION | B7: RELEVES | D7: STATION | E7: RELEVES | H7: GUIDER | I7: 0
B8: JOURNALIER | C8: CUMUL | E8: JOURNALIER | F8: CUMUL | H8: GAROUA | I8: 0
A9: MAROUA | B9: =I4 -> 0 | C9: ='05-04-14'!C9+B9 -> 2 | D9: NGONG | E9: =I9 -> 0 | F9: ='05-04-14'!F9+E9 -> 6 | H9: NGONG | I9: 0
A10: KAELE | B10: =I5 -> 0 | C10: ='05-04-14'!C10+B10 -> 8 | D10: POLI | E10: =I10 -> 0 | F10: ='05-04-14'!F10+E10 -> 58 | H10: POLI | I10: 0
A11: TCHATIBALI | B11: =I6 -> 0 | C11: ='05-04-14'!C11+B11 -> 10 | D11: MAYO-GALKE | E11: =I11 -> 0 | F11: ='05-04-14'!F11+E11 -> 31 | H11: MAYO-GALKE | I11: 0
A12: GUIDER | B12: =I7 -> 0 | C12: ='05-04-14'!C12+B12 -> 11 | D12: TOUBOURO | E12: =I12 -> 0 | F12: ='05-04-14'!F12+E12 -> 10 | H12: TOUBOURO | I12: 0
A13: GAROUA | B13: =I8 -> 0 | C13: ='05-04-14'!C13+B13 -> 15 | D13: HOME | E13: =I13 -> 0 | F13: ='05-04-14'!F13+E13 -> 27 | H13: HOME | I13: 0
A15: TOTAL JOURNALIER = | C15: =SUM(B9:B13)+SUM(E9:E13) -> 0 | D15: CUMUL GENERAL = | F15: =SUM(C9:C13)+SUM(F9:F13) -> 178 | H15: JOURNEE | I15: 41735
H16: TRANSMISSION | I16: =I15+1 -> 41736
A20: Transmis le : | B20: =I16 -> 41736

Sheet 07-04-14
A1: SODECOTON
H2: TABLEAU DE SAISI
A3: PLUVIOMETRIE JOURNALIERE ET PAR PENTADE | H3: STATION | I3: RELEVES
H4: MAROUA | I4: 0
B5: JOURNEE DU : | D5: =I15 -> 41736 | H5: KAELE | I5: 0
H6: TCHATIBALI | I6: 0
A7: STATION | B7: RELEVES | D7: STATION | E7: RELEVES | H7: GUIDER | I7: 0
B8: JOURNALIER | C8: CUMUL | E8: JOURNALIER | F8: CUMUL | H8: GAROUA | I8: 0
A9: MAROUA | B9: =I4 -> 0 | C9: ='06-04-14'!C9+B9 -> 2 | D9: NGONG | E9: =I9 -> 0 | F9: ='06-04-14'!F9+E9 -> 6 | H9: NGONG | I9: 0
A10: KAELE | B10: =I5 -> 0 | C10: ='06-04-14'!C10+B10 -> 8 | D10: POLI | E10: =I10 -> 0 | F10: ='06-04-14'!F10+E10 -> 58 | H10: POLI | I10: 0
A11: TCHATIBALI | B11: =I6 -> 0 | C11: ='06-04-14'!C11+B11 -> 10 | D11: MAYO-GALKE | E11: =I11 -> 0 | F11: ='06-04-14'!F11+E11 -> 31 | H11: MAYO-GALKE | I11: 0
A12: GUIDER | B12: =I7 -> 0 | C12: ='06-04-14'!C12+B12 -> 11 | D12: TOUBOURO | E12: =I12 -> 0 | F12: ='06-04-14'!F12+E12 -> 10 | H12: TOUBOURO | I12: 0
A13: GAROUA | B13: =I8 -> 0 | C13: ='06-04-14'!C13+B13 -> 15 | D13: HOME | E13: =I13 -> 0 | F13: ='06-04-14'!F13+E13 -> 27 | H13: HOME | I13: 0
A15: TOTAL JOURNALIER = | C15: =SUM(B9:B13)+SUM(E9:E13) -> 0 | D15: CUMUL GENERAL = | F15: =SUM(C9:C13)+SUM(F9:F13) -> 178 | H15: JOURNEE | I15: 41736
H16: TRANSMISSION | I16: =I15+1 -> 41737
A20: Transmis le : | B20: =I16 -> 41737

Sheet 08-04-14
A1: SODECOTON
H2: TABLEAU DE SAISI
A3: PLUVIOMETRIE JOURNALIERE ET PAR PENTADE | H3: STATION | I3: RELEVES
H4: MAROUA | I4: 0
B5: JOURNEE DU : | D5: =I15 -> 41737 | H5: KAELE | I5: 0
H6: TCHATIBALI | I6: 0
A7: STATION | B7: RELEVES | D7: STATION | E7: RELEVES | H7: GUIDER | I7: 0
B8: JOURNALIER | C8: CUMUL | E8: JOURNALIER | F8: CUMUL | H8: GAROUA | I8: 0
A9: MAROUA | B9: =I4 -> 0 | C9: ='07-04-14'!C9+B9 -> 2 | D9: NGONG | E9: =I9 -> 0 | F9: ='07-04-14'!F9+E9 -> 6 | H9: NGONG | I9: 0
A10: KAELE | B10: =I5 -> 0 | C10: ='07-04-14'!C10+B10 -> 8 | D10: POLI | E10: =I10 -> 0 | F10: ='07-04-14'!F10+E10 -> 58 | H10: POLI | I10: 0
A11: TCHATIBALI | B11: =I6 -> 0 | C11: ='07-04-14'!C11+B11 -> 10 | D11: MAYO-GALKE | E11: =I11 -> 0 | F11: ='07-04-14'!F11+E11 -> 31 | H11: MAYO-GALKE | I11: 0
A12: GUIDER | B12: =I7 -> 0 | C12: ='07-04-14'!C12+B12 -> 11 | D12: TOUBOURO | E12: =I12 -> 0 | F12: ='07-04-14'!F12+E12 -> 10 | H12: TOUBOURO | I12: 0
A13: GAROUA | B13: =I8 -> 0 | C13: ='07-04-14'!C13+B13 -> 15 | D13: HOME | E13: =I13 -> 0 | F13: ='07-04-14'!F13+E13 -> 27 | H13: HOME | I13: 0
A15: TOTAL JOURNALIER = | C15: =SUM(B9:B13)+SUM(E9:E13) -> 0 | D15: CUMUL GENERAL = | F15: =SUM(C9:C13)+SUM(F9:F13) -> 178 | H15: JOURNEE | I15: 41737
H16: TRANSMISSION | I16: =I15+1 -> 41738
A20: Transmis le : | B20: =I16 -> 41738

Sheet 09-04-14
A1: SODECOTON
H2: TABLEAU DE SAISI
A3: PLUVIOMETRIE JOURNALIERE ET PAR PENTADE | H3: STATION | I3: RELEVES
H4: MAROUA | I4: 0
B5: JOURNEE DU : | D5: =I15 -> 41738 | H5: KAELE | I5: 0
H6: TCHATIBALI | I6: 0
A7: STATION | B7: RELEVES | D7: STATION | E7: RELEVES | H7: GUIDER | I7: 0
B8: JOURNALIER | C8: CUMUL | E8: JOURNALIER | F8: CUMUL | H8: GAROUA | I8: 0
A9: MAROUA | B9: =I4 -> 0 | C9: ='08-04-14'!C9+B9 -> 2 | D9: NGONG | E9: =I9 -> 0 | F9: ='08-04-14'!F9+E9 -> 6 | H9: NGONG | I9: 0
A10: KAELE | B10: =I5 -> 0 | C10: ='08-04-14'!C10+B10 -> 8 | D10: POLI | E10: =I10 -> 0 | F10: ='08-04-14'!F10+E10 -> 58 | H10: POLI | I10: 0
A11: TCHATIBALI | B11: =I6 -> 0 | C11: ='08-04-14'!C11+B11 -> 10 | D11: MAYO-GALKE | E11: =I11 -> 0 | F11: ='08-04-14'!F11+E11 -> 31 | H11: MAYO-GALKE | I11: 0
A12: GUIDER | B12: =I7 -> 0 | C12: ='08-04-14'!C12+B12 -> 11 | D12: TOUBOURO | E12: =I12 -> 0 | F12: ='08-04-14'!F12+E12 -> 10 | H12: TOUBOURO | I12: 0
A13: GAROUA | B13: =I8 -> 0 | C13: ='08-04-14'!C13+B13 -> 15 | D13: HOME | E13: =I13 -> 0 | F13: ='08-04-14'!F13+E13 -> 27 | H13: HOME | I13: 0
A15: TOTAL JOURNALIER = | C15: =SUM(B9:B13)+SUM(E9:E13) -> 0 | D15: CUMUL GENERAL = | F15: =SUM(C9:C13)+SUM(F9:F13) -> 178 | H15: JOURNEE | I15: 41738
H16: TRANSMISSION | I16: =I15+1 -> 41739
A20: Transmis le : | B20: =I16 -> 41739

Sheet 10-04-14
A1: SODECOTON
H2: TABLEAU DE SAISI
A3: PLUVIOMETRIE JOURNALIERE ET PAR PENTADE | H3: STATION | I3: RELEVES
H4: MAROUA | I4: 0
B5: JOURNEE DU : | D5: =I15 -> 41739 | H5: KAELE | I5: 0
H6: TCHATIBALI | I6: 0
A7: STATION | B7: RELEVES | D7: STATION | E7: RELEVES | H7: GUIDER | I7: 0
B8: JOURNALIER | C8: CUMUL | E8: JOURNALIER | F8: CUMUL | H8: GAROUA | I8: 0
A9: MAROUA | B9: =I4 -> 0 | C9: ='09-04-14'!C9+B9 -> 2 | D9: NGONG | E9: =I9 -> 0 | F9: ='09-04-14'!F9+E9 -> 6 | H9: NGONG | I9: 0
A10: KAELE | B10: =I5 -> 0 | C10: ='09-04-14'!C10+B10 -> 8 | D10: POLI | E10: =I10 -> 0 | F10: ='09-04-14'!F10+E10 -> 58 | H10: POLI | I10: 0
A11: TCHATIBALI | B11: =I6 -> 0 | C11: ='09-04-14'!C11+B11 -> 10 | D11: MAYO-GALKE | E11: =I11 -> 0 | F11: ='09-04-14'!F11+E11 -> 31 | H11: MAYO-GALKE | I11: 0
A12: GUIDER | B12: =I7 -> 0 | C12: ='09-04-14'!C12+B12 -> 11 | D12: TOUBOURO | E12: =I12 -> 0 | F12: ='09-04-14'!F12+E12 -> 10 | H12: TOUBOURO | I12: 0
A13: GAROUA | B13: =I8 -> 0 | C13: ='09-04-14'!C13+B13 -> 15 | D13: HOME | E13: =I13 -> 0 | F13: ='09-04-14'!F13+E13 -> 27 | H13: HOME | I13: 0
A15: TOTAL JOURNALIER = | C15: =SUM(B9:B13)+SUM(E9:E13) -> 0 | D15: CUMUL GENERAL = | F15: =SUM(C9:C13)+SUM(F9:F13) -> 178 | H15: JOURNEE | I15: 41739
H16: TRANSMISSION | I16: =I15+1 -> 41740
A20: Transmis le : | B20: =I16 -> 41740

Sheet 11-04-14
A1: SODECOTON
H2: TABLEAU DE SAISI
A3: PLUVIOMETRIE JOURNALIERE ET PAR PENTADE | H3: STATION | I3: RELEVES
H4: MAROUA | I4: 0
B5: JOURNEE DU : | D5: =I15 -> 41740 | H5: KAELE | I5: 0
H6: TCHATIBALI | I6: 0
A7: STATION | B7: RELEVES | D7: STATION | E7: RELEVES | H7: GUIDER | I7: 0
B8: JOURNALIER | C8: CUMUL | E8: JOURNALIER | F8: CUMUL | H8: GAROUA | I8: 0
A9: MAROUA | B9: =I4 -> 0 | C9: ='10-04-14'!C9+B9 -> 2 | D9: NGONG | E9: =I9 -> 0 | F9: ='10-04-14'!F9+E9 -> 6 | H9: NGONG | I9: 0
A10: KAELE | B10: =I5 -> 0 | C10: ='10-04-14'!C10+B10 -> 8 | D10: POLI | E10: =I10 -> 0 | F10: ='10-04-14'!F10+E10 -> 58 | H10: POLI | I10: 0
A11: TCHATIBALI | B11: =I6 -> 0 | C11: ='10-04-14'!C11+B11 -> 10 | D11: MAYO-GALKE | E11: =I11 -> 0 | F11: ='10-04-14'!F11+E11 -> 31 | H11: MAYO-GALKE | I11: 0
A12: GUIDER | B12: =I7 -> 0 | C12: ='10-04-14'!C12+B12 -> 11 | D12: TOUBOURO | E12: =I12 -> 0 | F12: ='10-04-14'!F12+E12 -> 10 | H12: TOUBOURO | I12: 0
A13: GAROUA | B13: =I8 -> 0 | C13: ='10-04-14'!C13+B13 -> 15 | D13: HOME | E13: =I13 -> 2 | F13: ='10-04-14'!F13+E13 -> 29 | H13: HOME | I13: 2
A15: TOTAL JOURNALIER = | C15: =SUM(B9:B13)+SUM(E9:E13) -> 2 | D15: CUMUL GENERAL = | F15: =SUM(C9:C13)+SUM(F9:F13) -> 180 | H15: JOURNEE | I15: 41740
H16: TRANSMISSION | I16: =I15+1 -> 41741
A20: Transmis le : | B20: =I16 -> 41741

Sheet 12-04-14
A1: SODECOTON
H2: TABLEAU DE SAISI
A3: PLUVIOMETRIE JOURNALIERE ET PAR PENTADE | H3: STATION | I3: RELEVES
H4: MAROUA | I4: 0
B5: JOURNEE DU : | D5: =I15 -> 41741 | H5: KAELE | I5: 0
H6: TCHATIBALI | I6: 0
A7: STATION | B7: RELEVES | D7: STATION | E7: RELEVES | H7: GUIDER | I7: 0
B8: JOURNALIER | C8: CUMUL | E8: JOURNALIER | F8: CUMUL | H8: GAROUA | I8: 0
A9: MAROUA | B9: =I4 -> 0 | C9: ='11-04-14'!C9+B9 -> 2 | D9: NGONG | E9: =I9 -> 0 | F9: ='11-04-14'!F9+E9 -> 6 | H9: NGONG | I9: 0
A10: KAELE | B10: =I5 -> 0 | C10: ='11-04-14'!C10+B10 -> 8 | D10: POLI | E10: =I10 -> 5 | F10: ='11-04-14'!F10+E10 -> 63 | H10: POLI | I10: 5
A11: TCHATIBALI | B11: =I6 -> 0 | C11: ='11-04-14'!C11+B11 -> 10 | D11: MAYO-GALKE | E11: =I11 -> 0 | F11: ='11-04-14'!F11+E11 -> 31 | H11: MAYO-GALKE | I11: 0
A12: GUIDER | B12: =I7 -> 0 | C12: ='11-04-14'!C12+B12 -> 11 | D12: TOUBOURO | E12: =I12 -> 0 | F12: ='11-04-14'!F12+E12 -> 10 | H12: TOUBOURO | I12: 0
A13: GAROUA | B13: =I8 -> 0 | C13: ='11-04-14'!C13+B13 -> 15 | D13: HOME | E13: =I13 -> 0 | F13: ='11-04-14'!F13+E13 -> 29 | H13: HOME | I13: 0
A15: TOTAL JOURNALIER = | C15: =SUM(B9:B13)+SUM(E9:E13) -> 5 | D15: CUMUL GENERAL = | F15: =SUM(C9:C13)+SUM(F9:F13) -> 185 | H15: JOURNEE | I15: 41741
H16: TRANSMISSION | I16: =I15+1 -> 41742
A20: Transmis le : | B20: =I16 -> 41742

Sheet 13-04-14
A1: SODECOTON
H2: TABLEAU DE SAISI
A3: PLUVIOMETRIE JOURNALIERE ET PAR PENTADE | H3: STATION | I3: RELEVES
H4: MAROUA | I4: 0
B5: JOURNEE DU : | D5: =I15 -> 41742 | H5: KAELE | I5: 0
H6: TCHATIBALI | I6: 0
A7: STATION | B7: RELEVES | D7: STATION | E7: RELEVES | H7: GUIDER | I7: 0
B8: JOURNALIER | C8: CUMUL | E8: JOURNALIER | F8: CUMUL | H8: GAROUA | I8: 0
A9: MAROUA | B9: =I4 -> 0 | C9: ='12-04-14'!C9+B9 -> 2 | D9: NGONG | E9: =I9 -> 0 | F9: ='12-04-14'!F9+E9 -> 6 | H9: NGONG | I9: 0
A10: KAELE | B10: =I5 -> 0 | C10: ='12-04-14'!C10+B10 -> 8 | D10: POLI | E10: =I10 -> 0 | F10: ='12-04-14'!F10+E10 -> 63 | H10: POLI | I10: 0
A11: TCHATIBALI | B11: =I6 -> 0 | C11: ='12-04-14'!C11+B11 -> 10 | D11: MAYO-GALKE | E11: =I11 -> 0 | F11: ='12-04-14'!F11+E11 -> 31 | H11: MAYO-GALKE | I11: 0
A12: GUIDER | B12: =I7 -> 0 | C12: ='12-04-14'!C12+B12 -> 11 | D12: TOUBOURO | E12: =I12 -> 0 | F12: ='12-04-14'!F12+E12 -> 10 | H12: TOUBOURO | I12: 0
A13: GAROUA | B13: =I8 -> 0 | C13: ='12-04-14'!C13+B13 -> 15 | D13: HOME | E13: =I13 -> 0 | F13: ='12-04-14'!F13+E13 -> 29 | H13: HOME | I13: 0
A15: TOTAL JOURNALIER = | C15: =SUM(B9:B13)+SUM(E9:E13) -> 0 | D15: CUMUL GENERAL = | F15: =SUM(C9:C13)+SUM(F9:F13) -> 185 | H15: JOURNEE | I15: 41742
H16: TRANSMISSION | I16: =I15+1 -> 41743
A20: Transmis le : | B20: =I16 -> 41743

Sheet 14-04-14
A1: SODECOTON
H2: TABLEAU DE SAISI
A3: PLUVIOMETRIE JOURNALIERE ET PAR PENTADE | H3: STATION | I3: RELEVES
H4: MAROUA | I4: 0
B5: JOURNEE DU : | D5: =I15 -> 41743 | H5: KAELE | I5: 0
H6: TCHATIBALI | I6: 0
A7: STATION | B7: RELEVES | D7: STATION | E7: RELEVES | H7: GUIDER | I7: 0
B8: JOURNALIER | C8: CUMUL | E8: JOURNALIER | F8: CUMUL | H8: GAROUA | I8: 0
A9: MAROUA | B9: =I4 -> 0 | C9: ='13-04-14'!C9+B9 -> 2 | D9: NGONG | E9: =I9 -> 0 | F9: ='13-04-14'!F9+E9 -> 6 | H9: NGONG | I9: 0
A10: KAELE | B10: =I5 -> 0 | C10: ='13-04-14'!C10+B10 -> 8 | D10: POLI | E10: =I10 -> 0 | F10: ='13-04-14'!F10+E10 -> 63 | H10: POLI | I10: 0
A11: TCHATIBALI | B11: =I6 -> 0 | C11: ='13-04-14'!C11+B11 -> 10 | D11: MAYO-GALKE | E11: =I11 -> 0 | F11: ='13-04-14'!F11+E11 -> 31 | H11: MAYO-GALKE | I11: 0
A12: GUIDER | B12: =I7 -> 0 | C12: ='13-04-14'!C12+B12 -> 11 | D12: TOUBOURO | E12: =I12 -> 0 | F12: ='13-04-14'!F12+E12 -> 10 | H12: TOUBOURO | I12: 0
A13: GAROUA | B13: =I8 -> 0 | C13: ='13-04-14'!C13+B13 -> 15 | D13: HOME | E13: =I13 -> 0 | F13: ='13-04-14'!F13+E13 -> 29 | H13: HOME | I13: 0
A15: TOTAL JOURNALIER = | C15: =SUM(B9:B13)+SUM(E9:E13) -> 0 | D15: CUMUL GENERAL = | F15: =SUM(C9:C13)+SUM(F9:F13) -> 185 | H15: JOURNEE | I15: 41743
H16: TRANSMISSION | I16: =I15+1 -> 41744
A20: Transmis le : | B20: =I16 -> 41744

Sheet 15-04-14
A1: SODECOTON
H2: TABLEAU DE SAISI
A3: PLUVIOMETRIE JOURNALIERE ET PAR PENTADE | H3: STATION | I3: RELEVES
H4: MAROUA | I4: 0
B5: JOURNEE DU : | D5: =I15 -> 41744 | H5: KAELE | I5: 0
H6: TCHATIBALI | I6: 0
A7: STATION | B7: RELEVES | D7: STATION | E7: RELEVES | H7: GUIDER | I7: 0
B8: JOURNALIER | C8: CUMUL | E8: JOURNALIER | F8: CUMUL | H8: GAROUA | I8: 0
A9: MAROUA | B9: =I4 -> 0 | C9: ='14-04-14'!C9+B9 -> 2 | D9: NGONG | E9: =I9 -> 0 | F9: ='14-04-14'!F9+E9 -> 6 | H9: NGONG | I9: 0
A10: KAELE | B10: =I5 -> 0 | C10: ='14-04-14'!C10+B10 -> 8 | D10: POLI | E10: =I10 -> 0 | F10: ='14-04-14'!F10+E10 -> 63 | H10: POLI | I10: 0
A11: TCHATIBALI | B11: =I6 -> 0 | C11: ='14-04-14'!C11+B11 -> 10 | D11: MAYO-GALKE | E11: =I11 -> 3 | F11: ='14-04-14'!F11+E11 -> 34 | H11: MAYO-GALKE | I11: 3
A12: GUIDER | B12: =I7 -> 0 | C12: ='14-04-14'!C12+B12 -> 11 | D12: TOUBOURO | E12: =I12 -> 0 | F12: ='14-04-14'!F12+E12 -> 10 | H12: TOUBOURO | I12: 0
A13: GAROUA | B13: =I8 -> 0 | C13: ='14-04-14'!C13+B13 -> 15 | D13: HOME | E13: =I13 -> 10 | F13: ='14-04-14'!F13+E13 -> 39 | H13: HOME | I13: 10
A15: TOTAL JOURNALIER = | C15: =SUM(B9:B13)+SUM(E9:E13) -> 13 | D15: CUMUL GENERAL = | F15: =SUM(C9:C13)+SUM(F9:F13) -> 198 | H15: JOURNEE | I15: 41744
H16: TRANSMISSION | I16: =I15+1 -> 41745
A20: Transmis le : | B20: =I16 -> 41745

Sheet 16-04-14
A1: SODECOTON
H2: TABLEAU DE SAISI
A3: PLUVIOMETRIE JOURNALIERE ET PAR PENTADE | H3: STATION | I3: RELEVES
H4: MAROUA | I4: 0
B5: JOURNEE DU : | D5: =I15 -> 41745 | H5: KAELE | I5: 0
H6: TCHATIBALI | I6: 0
A7: STATION | B7: RELEVES | D7: STATION | E7: RELEVES | H7: GUIDER | I7: 0
B8: JOURNALIER | C8: CUMUL | E8: JOURNALIER | F8: CUMUL | H8: GAROUA | I8: 0
A9: MAROUA | B9: =I4 -> 0 | C9: ='15-04-14'!C9+B9 -> 2 | D9: NGONG | E9: =I9 -> 0 | F9: ='15-04-14'!F9+E9 -> 6 | H9: NGONG | I9: 0
A10: KAELE | B10: =I5 -> 0 | C10: ='15-04-14'!C10+B10 -> 8 | D10: POLI | E10: =I10 -> 0 | F10: ='15-04-14'!F10+E10 -> 63 | H10: POLI | I10: 0
A11: TCHATIBALI | B11: =I6 -> 0 | C11: ='15-04-14'!C11+B11 -> 10 | D11: MAYO-GALKE | E11: =I11 -> 0 | F11: ='15-04-14'!F11+E11 -> 34 | H11: MAYO-GALKE | I11: 0
A12: GUIDER | B12: =I7 -> 0 | C12: ='15-04-14'!C12+B12 -> 11 | D12: TOUBOURO | E12: =I12 -> 0 | F12: ='15-04-14'!F12+E12 -> 10 | H12: TOUBOURO | I12: 0
A13: GAROUA | B13: =I8 -> 0 | C13: ='15-04-14'!C13+B13 -> 15 | D13: HOME | E13: =I13 -> 0 | F13: ='15-04-14'!F13+E13 -> 39 | H13: HOME | I13: 0
A15: TOTAL JOURNALIER = | C15: =SUM(B9:B13)+SUM(E9:E13) -> 0 | D15: CUMUL GENERAL = | F15: =SUM(C9:C13)+SUM(F9:F13) -> 198 | H15: JOURNEE | I15: 41745
H16: TRANSMISSION | I16: =I15+1 -> 41746
A20: Transmis le : | B20: =I16 -> 41746

Sheet 17-04-14
A1: SODECOTON
H2: TABLEAU DE SAISI
A3: PLUVIOMETRIE JOURNALIERE ET PAR PENTADE | H3: STATION | I3: RELEVES
H4: MAROUA | I4: 11
B5: JOURNEE DU : | D5: =I15 -> 41746 | H5: KAELE | I5: 0
H6: TCHATIBALI | I6: 0
A7: STATION | B7: RELEVES | D7: STATION | E7: RELEVES | H7: GUIDER | I7: 0
B8: JOURNALIER | C8: CUMUL | E8: JOURNALIER | F8: CUMUL | H8: GAROUA | I8: 0
A9: MAROUA | B9: =I4 -> 11 | C9: ='16-04-14'!C9+B9 -> 13 | D9: NGONG | E9: =I9 -> 0 | F9: ='16-04-14'!F9+E9 -> 6 | H9: NGONG | I9: 0
A10: KAELE | B10: =I5 -> 0 | C10: ='16-04-14'!C10+B10 -> 8 | D10: POLI | E10: =I10 -> 1 | F10: ='16-04-14'!F10+E10 -> 64 | H10: POLI | I10: 1
A11: TCHATIBALI | B11: =I6 -> 0 | C11: ='16-04-14'!C11+B11 -> 10 | D11: MAYO-GALKE | E11: =I11 -> 0 | F11: ='16-04-14'!F11+E11 -> 34 | H11: MAYO-GALKE | I11: 0
A12: GUIDER | B12: =I7 -> 0 | C12: ='16-04-14'!C12+B12 -> 11 | D12: TOUBOURO | E12: =I12 -> 0 | F12: ='16-04-14'!F12+E12 -> 10 | H12: TOUBOURO | I12: 0
A13: GAROUA | B13: =I8 -> 0 | C13: ='16-04-14'!C13+B13 -> 15 | D13: HOME | E13: =I13 -> 0 | F13: ='16-04-14'!F13+E13 -> 39 | H13: HOME | I13: 0
A15: TOTAL JOURNALIER = | C15: =SUM(B9:B13)+SUM(E9:E13) -> 12 | D15: CUMUL GENERAL = | F15: =SUM(C9:C13)+SUM(F9:F13) -> 210 | H15: JOURNEE | I15: 41746
H16: TRANSMISSION | I16: =I15+1 -> 41747
A20: Transmis le : | B20: =I16 -> 41747

Sheet 18-04-14
A1: SODECOTON
H2: TABLEAU DE SAISI
A3: PLUVIOMETRIE JOURNALIERE ET PAR PENTADE | H3: STATION | I3: RELEVES
H4: MAROUA | I4: 0
B5: JOURNEE DU : | D5: =I15 -> 41747 | H5: KAELE | I5: 0
H6: TCHATIBALI | I6: 0
A7: STATION | B7: RELEVES | D7: STATION | E7: RELEVES | H7: GUIDER | I7: 0
B8: JOURNALIER | C8: CUMUL | E8: JOURNALIER | F8: CUMUL | H8: GAROUA | I8: 0
A9: MAROUA | B9: =I4 -> 0 | C9: ='17-04-14'!C9+B9 -> 13 | D9: NGONG | E9: =I9 -> 0 | F9: ='17-04-14'!F9+E9 -> 6 | H9: NGONG | I9: 0
A10: KAELE | B10: =I5 -> 0 | C10: ='17-04-14'!C10+B10 -> 8 | D10: POLI | E10: =I10 -> 11 | F10: ='17-04-14'!F10+E10 -> 75 | H10: POLI | I10: 11
A11: TCHATIBALI | B11: =I6 -> 0 | C11: ='17-04-14'!C11+B11 -> 10 | D11: MAYO-GALKE | E11: =I11 -> 0 | F11: ='17-04-14'!F11+E11 -> 34 | H11: MAYO-GALKE | I11: 0
A12: GUIDER | B12: =I7 -> 0 | C12: ='17-04-14'!C12+B12 -> 11 | D12: TOUBOURO | E12: =I12 -> 0 | F12: ='17-04-14'!F12+E12 -> 10 | H12: TOUBOURO | I12: 0
A13: GAROUA | B13: =I8 -> 0 | C13: ='17-04-14'!C13+B13 -> 15 | D13: HOME | E13: =I13 -> 0 | F13: ='17-04-14'!F13+E13 -> 39 | H13: HOME | I13: 0
A15: TOTAL JOURNALIER = | C15: =SUM(B9:B13)+SUM(E9:E13) -> 11 | D15: CUMUL GENERAL = | F15: =SUM(C9:C13)+SUM(F9:F13) -> 221 | H15: JOURNEE | I15: 41747
H16: TRANSMISSION | I16: =I15+1 -> 41748
A20: Transmis le : | B20: =I16 -> 41748

Sheet 19-04-14
A1: SODECOTON
H2: TABLEAU DE SAISI
A3: PLUVIOMETRIE JOURNALIERE ET PAR PENTADE | H3: STATION | I3: RELEVES
H4: MAROUA | I4: 1
B5: JOURNEE DU : | D5: =I15 -> 0 | H5: KAELE | I5: 2
H6: TCHATIBALI | I6: 1
A7: STATION | B7: RELEVES | D7: STATION | E7: RELEVES | H7: GUIDER | I7: 9
B8: JOURNALIER | C8: CUMUL | E8: JOURNALIER | F8: CUMUL | H8: GAROUA | I8: 30
A9: MAROUA | B9: =I4 -> 1 | C9: ='18-04-14'!C9+B9 -> 14 | D9: NGONG | E9: =I9 -> 0 | F9: ='18-04-14'!F9+E9 -> 6 | H9: NGONG | I9: 0
A10: KAELE | B10: =I5 -> 2 | C10: ='18-04-14'!C10+B10 -> 10 | D10: POLI | E10: =I10 -> 0 | F10: ='18-04-14'!F10+E10 -> 75 | H10: POLI | I10: 0
A11: TCHATIBALI | B11: =I6 -> 1 | C11: ='18-04-14'!C11+B11 -> 11 | D11: MAYO-GALKE | E11: =I11 -> 2 | F11: ='18-04-14'!F11+E11 -> 36 | H11: MAYO-GALKE | I11: 2
A12: GUIDER | B12: =I7 -> 9 | C12: ='18-04-14'!C12+B12 -> 20 | D12: TOUBOURO | E12: =I12 -> 0 | F12: ='18-04-14'!F12+E12 -> 10 | H12: TOUBOURO | I12: 0
A13: GAROUA | B13: =I8 -> 30 | C13: ='18-04-14'!C13+B13 -> 45 | D13: HOME | E13: =I13 -> 1 | F13: ='18-04-14'!F13+E13 -> 40 | H13: HOME | I13: 1
A15: TOTAL JOURNALIER = | C15: =SUM(B9:B13)+SUM(E9:E13) -> 46 | D15: CUMUL GENERAL = | F15: =SUM(C9:C13)+SUM(F9:F13) -> 267 | H15: JOURNEE
H16: TRANSMISSION | I16: =I15+1 -> 1
A20: Transmis le : | B20: =I16 -> 1

Sheet 20-04-14
A1: SODECOTON
H2: TABLEAU DE SAISI
A3: PLUVIOMETRIE JOURNALIERE ET PAR PENTADE | H3: STATION | I3: RELEVES
H4: MAROUA | I4: 0
B5: JOURNEE DU : | D5: =I15 -> 41749 | H5: KAELE | I5: 0
H6: TCHATIBALI | I6: 2
A7: STATION | B7: RELEVES | D7: STATION | E7: RELEVES | H7: GUIDER | I7: 0
B8: JOURNALIER | C8: CUMUL | E8: JOURNALIER | F8: CUMUL | H8: GAROUA | I8: 0
A9: MAROUA | B9: =I4 -> 0 | C9: ='19-04-14'!C9+B9 -> 14 | D9: NGONG | E9: =I9 -> 0 | F9: ='19-04-14'!F9+E9 -> 6 | H9: NGONG | I9: 0
A10: KAELE | B10: =I5 -> 0 | C10: ='19-04-14'!C10+B10 -> 10 | D10: POLI | E10: =I10 -> 10 | F10: ='19-04-14'!F10+E10 -> 85 | H10: POLI | I10: 10
A11: TCHATIBALI | B11: =I6 -> 2 | C11: ='19-04-14'!C11+B11 -> 13 | D11: MAYO-GALKE | E11: =I11 -> 14 | F11: ='19-04-14'!F11+E11 -> 50 | H11: MAYO-GALKE | I11: 14
A12: GUIDER | B12: =I7 -> 0 | C12: ='19-04-14'!C12+B12 -> 20 | D12: TOUBOURO | E12: =I12 -> 0 | F12: ='19-04-14'!F12+E12 -> 10 | H12: TOUBOURO | I12: 0
A13: GAROUA | B13: =I8 -> 0 | C13: ='19-04-14'!C13+B13 -> 45 | D13: HOME | E13: =I13 -> 9 | F13: ='19-04-14'!F13+E13 -> 49 | H13: HOME | I13: 9
A15: TOTAL JOURNALIER = | C15: =SUM(B9:B13)+SUM(E9:E13) -> 35 | D15: CUMUL GENERAL = | F15: =SUM(C9:C13)+SUM(F9:F13) -> 302 | H15: JOURNEE | I15: 41749
H16: TRANSMISSION | I16: =I15+1 -> 41750
A20: Transmis le : | B20: =I16 -> 41750

Sheet 21-04-14
A1: SODECOTON
H2: TABLEAU DE SAISI
A3: PLUVIOMETRIE JOURNALIERE ET PAR PENTADE | H3: STATION | I3: RELEVES
H4: MAROUA | I4: 0
B5: JOURNEE DU : | D5: =I15 -> 41750 | H5: KAELE | I5: 0
H6: TCHATIBALI | I6: 0
A7: STATION | B7: RELEVES | D7: STATION | E7: RELEVES | H7: GUIDER | I7: 0
B8: JOURNALIER | C8: CUMUL | E8: JOURNALIER | F8: CUMUL | H8: GAROUA | I8: 0
A9: MAROUA | B9: =I4 -> 0 | C9: ='20-04-14'!C9+B9 -> 14 | D9: NGONG | E9: =I9 -> 0 | F9: ='20-04-14'!F9+E9 -> 6 | H9: NGONG | I9: 0
A10: KAELE | B10: =I5 -> 0 | C10: ='20-04-14'!C10+B10 -> 10 | D10: POLI | E10: =I10 -> 0 | F10: ='20-04-14'!F10+E10 -> 85 | H10: POLI | I10: 0
A11: TCHATIBALI | B11: =I6 -> 0 | C11: ='20-04-14'!C11+B11 -> 13 | D11: MAYO-GALKE | E11: =I11 -> 0 | F11: ='20-04-14'!F11+E11 -> 50 | H11: MAYO-GALKE | I11: 0
A12: GUIDER | B12: =I7 -> 0 | C12: ='20-04-14'!C12+B12 -> 20 | D12: TOUBOURO | E12: =I12 -> 0 | F12: ='20-04-14'!F12+E12 -> 10 | H12: TOUBOURO | I12: 0
A13: GAROUA | B13: =I8 -> 0 | C13: ='20-04-14'!C13+B13 -> 45 | D13: HOME | E13: =I13 -> 5 | F13: ='20-04-14'!F13+E13 -> 54 | H13: HOME | I13: 5
A15: TOTAL JOURNALIER = | C15: =SUM(B9:B13)+SUM(E9:E13) -> 5 | D15: CUMUL GENERAL = | F15: =SUM(C9:C13)+SUM(F9:F13) -> 307 | H15: JOURNEE | I15: 41750
H16: TRANSMISSION | I16: =I15+1 -> 41751
A20: Transmis le : | B20: =I16 -> 41751

Sheet 22-04-14
A1: SODECOTON
H2: TABLEAU DE SAISI
A3: PLUVIOMETRIE JOURNALIERE ET PAR PENTADE | H3: STATION | I3: RELEVES
H4: MAROUA | I4: 0
B5: JOURNEE DU : | D5: =I15 -> 41751 | H5: KAELE | I5: 0
H6: TCHATIBALI | I6: 9
A7: STATION | B7: RELEVES | D7: STATION | E7: RELEVES | H7: GUIDER | I7: 33
B8: JOURNALIER | C8: CUMUL | E8: JOURNALIER | F8: CUMUL | H8: GAROUA | I8: 15
A9: MAROUA | B9: =I4 -> 0 | C9: ='21-04-14'!C9+B9 -> 14 | D9: NGONG | E9: =I9 -> 4 | F9: ='21-04-14'!F9+E9 -> 10 | H9: NGONG | I9: 4
A10: KAELE | B10: =I5 -> 0 | C10: ='21-04-14'!C10+B10 -> 10 | D10: POLI | E10: =I10 -> 0 | F10: ='21-04-14'!F10+E10 -> 85 | H10: POLI | I10: 0
A11: TCHATIBALI | B11: =I6 -> 9 | C11: ='21-04-14'!C11+B11 -> 22 | D11: MAYO-GALKE | E11: =I11 -> 10 | F11: ='21-04-14'!F11+E11 -> 60 | H11: MAYO-GALKE | I11: 10
A12: GUIDER | B12: =I7 -> 33 | C12: ='21-04-14'!C12+B12 -> 53 | D12: TOUBOURO | E12: =I12 -> 0 | F12: ='21-04-14'!F12+E12 -> 10 | H12: TOUBOURO | I12: 0
A13: GAROUA | B13: =I8 -> 15 | C13: ='21-04-14'!C13+B13 -> 60 | D13: HOME | E13: =I13 -> 7 | F13: ='21-04-14'!F13+E13 -> 61 | H13: HOME | I13: 7
A15: TOTAL JOURNALIER = | C15: =SUM(B9:B13)+SUM(E9:E13) -> 78 | D15: CUMUL GENERAL = | F15: =SUM(C9:C13)+SUM(F9:F13) -> 385 | H15: JOURNEE | I15: 41751
H16: TRANSMISSION | I16: =I15+1 -> 41752
A20: Transmis le : | B20: =I16 -> 41752

Sheet 23-04-14
A1: SODECOTON
H2: TABLEAU DE SAISI
A3: PLUVIOMETRIE JOURNALIERE ET PAR PENTADE | H3: STATION | I3: RELEVES
H4: MAROUA | I4: 0
B5: JOURNEE DU : | D5: =I15 -> 41752 | H5: KAELE | I5: 0
H6: TCHATIBALI | I6: 0
A7: STATION | B7: RELEVES | D7: STATION | E7: RELEVES | H7: GUIDER | I7: 0
B8: JOURNALIER | C8: CUMUL | E8: JOURNALIER | F8: CUMUL | H8: GAROUA | I8: 0
A9: MAROUA | B9: =I4 -> 0 | C9: ='22-04-14'!C9+B9 -> 14 | D9: NGONG | E9: =I9 -> 0 | F9: ='22-04-14'!F9+E9 -> 10 | H9: NGONG | I9: 0
A10: KAELE | B10: =I5 -> 0 | C10: ='22-04-14'!C10+B10 -> 10 | D10: POLI | E10: =I10 -> 0 | F10: ='22-04-14'!F10+E10 -> 85 | H10: POLI | I10: 0
A11: TCHATIBALI | B11: =I6 -> 0 | C11: ='22-04-14'!C11+B11 -> 22 | D11: MAYO-GALKE | E11: =I11 -> 0 | F11: ='22-04-14'!F11+E11 -> 60 | H11: MAYO-GALKE | I11: 0
A12: GUIDER | B12: =I7 -> 0 | C12: ='22-04-14'!C12+B12 -> 53 | D12: TOUBOURO | E12: =I12 -> 0 | F12: ='22-04-14'!F12+E12 -> 10 | H12: TOUBOURO | I12: 0
A13: GAROUA | B13: =I8 -> 0 | C13: ='22-04-14'!C13+B13 -> 60 | D13: HOME | E13: =I13 -> 0 | F13: ='22-04-14'!F13+E13 -> 61 | H13: HOME | I13: 0
A15: TOTAL JOURNALIER = | C15: =SUM(B9:B13)+SUM(E9:E13) -> 0 | D15: CUMUL GENERAL = | F15: =SUM(C9:C13)+SUM(F9:F13) -> 385 | H15: JOURNEE | I15: 41752
H16: TRANSMISSION | I16: =I15+1 -> 41753
A20: Transmis le : | B20: =I16 -> 41753

Sheet 24-04-14
A1: SODECOTON
H2: TABLEAU DE SAISI
A3: PLUVIOMETRIE JOURNALIERE ET PAR PENTADE | H3: STATION | I3: RELEVES
H4: MAROUA | I4: 0
B5: JOURNEE DU : | D5: =I15 -> 41753 | H5: KAELE | I5: 0
H6: TCHATIBALI | I6: 0
A7: STATION | B7: RELEVES | D7: STATION | E7: RELEVES | H7: GUIDER | I7: 0
B8: JOURNALIER | C8: CUMUL | E8: JOURNALIER | F8: CUMUL | H8: GAROUA | I8: 0
A9: MAROUA | B9: =I4 -> 0 | C9: ='23-04-14'!C9+B9 -> 14 | D9: NGONG | E9: =I9 -> 0 | F9: ='23-04-14'!F9+E9 -> 10 | H9: NGONG | I9: 0
A10: KAELE | B10: =I5 -> 0 | C10: ='23-04-14'!C10+B10 -> 10 | D10: POLI | E10: =I10 -> 0 | F10: ='23-04-14'!F10+E10 -> 85 | H10: POLI | I10: 0
A11: TCHATIBALI | B11: =I6 -> 0 | C11: ='23-04-14'!C11+B11 -> 22 | D11: MAYO-GALKE | E11: =I11 -> 0 | F11: ='23-04-14'!F11+E11 -> 60 | H11: MAYO-GALKE | I11: 0
A12: GUIDER | B12: =I7 -> 0 | C12: ='23-04-14'!C12+B12 -> 53 | D12: TOUBOURO | E12: =I12 -> 0 | F12: ='23-04-14'!F12+E12 -> 10 | H12: TOUBOURO | I12: 0
A13: GAROUA | B13: =I8 -> 0 | C13: ='23-04-14'!C13+B13 -> 60 | D13: HOME | E13: =I13 -> 0 | F13: ='23-04-14'!F13+E13 -> 61 | H13: HOME | I13: 0
A15: TOTAL JOURNALIER = | C15: =SUM(B9:B13)+SUM(E9:E13) -> 0 | D15: CUMUL GENERAL = | F15: =SUM(C9:C13)+SUM(F9:F13) -> 385 | H15: JOURNEE | I15: 41753
H16: TRANSMISSION | I16: =I15+1 -> 41754
A20: Transmis le : | B20: =I16 -> 41754

Sheet 25-04-14
A1: SODECOTON
H2: TABLEAU DE SAISI
A3: PLUVIOMETRIE JOURNALIERE ET PAR PENTADE | H3: STATION | I3: RELEVES
H4: MAROUA | I4: 0
B5: JOURNEE DU : | D5: =I15 -> 41754 | H5: KAELE | I5: 0
H6: TCHATIBALI | I6: 0
A7: STATION | B7: RELEVES | D7: STATION | E7: RELEVES | H7: GUIDER | I7: 0
B8: JOURNALIER | C8: CUMUL | E8: JOURNALIER | F8: CUMUL | H8: GAROUA | I8: 0
A9: MAROUA | B9: =I4 -> 0 | C9: ='24-04-14'!C9+B9 -> 14 | D9: NGONG | E9: =I9 -> 0 | F9: ='24-04-14'!F9+E9 -> 10 | H9: NGONG | I9: 0
A10: KAELE | B10: =I5 -> 0 | C10: ='24-04-14'!C10+B10 -> 10 | D10: POLI | E10: =I10 -> 0 | F10: ='24-04-14'!F10+E10 -> 85 | H10: POLI | I10: 0
A11: TCHATIBALI | B11: =I6 -> 0 | C11: ='24-04-14'!C11+B11 -> 22 | D11: MAYO-GALKE | E11: =I11 -> 0 | F11: ='24-04-14'!F11+E11 -> 60 | H11: MAYO-GALKE | I11: 0
A12: GUIDER | B12: =I7 -> 0 | C12: ='24-04-14'!C12+B12 -> 53 | D12: TOUBOURO | E12: =I12 -> 0 | F12: ='24-04-14'!F12+E12 -> 10 | H12: TOUBOURO | I12: 0
A13: GAROUA | B13: =I8 -> 0 | C13: ='24-04-14'!C13+B13 -> 60 | D13: HOME | E13: =I13 -> 0 | F13: ='24-04-14'!F13+E13 -> 61 | H13: HOME | I13: 0
A15: TOTAL JOURNALIER = | C15: =SUM(B9:B13)+SUM(E9:E13) -> 0 | D15: CUMUL GENERAL = | F15: =SUM(C9:C13)+SUM(F9:F13) -> 385 | H15: JOURNEE | I15: 41754
H16: TRANSMISSION | I16: =I15+1 -> 41755
A20: Transmis le : | B20: =I16 -> 41755

Sheet 26-04-14
A1: SODECOTON
H2: TABLEAU DE SAISI
A3: PLUVIOMETRIE JOURNALIERE ET PAR PENTADE | H3: STATION | I3: RELEVES
H4: MAROUA | I4: 0
B5: JOURNEE DU : | D5: =I15 -> 41755 | H5: KAELE | I5: 0
H6: TCHATIBALI | I6: 0
A7: STATION | B7: RELEVES | D7: STATION | E7: RELEVES | H7: GUIDER | I7: 0
B8: JOURNALIER | C8: CUMUL | E8: JOURNALIER | F8: CUMUL | H8: GAROUA | I8: 0
A9: MAROUA | B9: =I4 -> 0 | C9: ='25-04-14'!C9+B9 -> 14 | D9: NGONG | E9: =I9 -> 0 | F9: ='25-04-14'!F9+E9 -> 10 | H9: NGONG | I9: 0
A10: KAELE | B10: =I5 -> 0 | C10: ='25-04-14'!C10+B10 -> 10 | D10: POLI | E10: =I10 -> 0 | F10: ='25-04-14'!F10+E10 -> 85 | H10: POLI | I10: 0
A11: TCHATIBALI | B11: =I6 -> 0 | C11: ='25-04-14'!C11+B11 -> 22 | D11: MAYO-GALKE | E11: =I11 -> 0 | F11: ='25-04-14'!F11+E11 -> 60 | H11: MAYO-GALKE | I11: 0
A12: GUIDER | B12: =I7 -> 0 | C12: ='25-04-14'!C12+B12 -> 53 | D12: TOUBOURO | E12: =I12 -> 0 | F12: ='25-04-14'!F12+E12 -> 10 | H12: TOUBOURO | I12: 0
A13: GAROUA | B13: =I8 -> 0 | C13: ='25-04-14'!C13+B13 -> 60 | D13: HOME | E13: =I13 -> 0 | F13: ='25-04-14'!F13+E13 -> 61 | H13: HOME | I13: 0
A15: TOTAL JOURNALIER = | C15: =SUM(B9:B13)+SUM(E9:E13) -> 0 | D15: CUMUL GENERAL = | F15: =SUM(C9:C13)+SUM(F9:F13) -> 385 | H15: JOURNEE | I15: 41755
H16: TRANSMISSION | I16: =I15+1 -> 41756
A20: Transmis le : | B20: =I16 -> 41756

Sheet 27-04-14
A1: SODECOTON
H2: TABLEAU DE SAISI
A3: PLUVIOMETRIE JOURNALIERE ET PAR PENTADE | H3: STATION | I3: RELEVES
H4: MAROUA | I4: 0
B5: JOURNEE DU : | D5: =I15 -> 41756 | H5: KAELE | I5: 0
H6: TCHATIBALI | I6: 0
A7: STATION | B7: RELEVES | D7: STATION | E7: RELEVES | H7: GUIDER | I7: 0
B8: JOURNALIER | C8: CUMUL | E8: JOURNALIER | F8: CUMUL | H8: GAROUA | I8: 10
A9: MAROUA | B9: =I4 -> 0 | C9: ='26-04-14'!C9+B9 -> 14 | D9: NGONG | E9: =I9 -> 50 | F9: ='26-04-14'!F9+E9 -> 60 | H9: NGONG | I9: 50
A10: KAELE | B10: =I5 -> 0 | C10: ='26-04-14'!C10+B10 -> 10 | D10: POLI | E10: =I10 -> 18 | F10: ='26-04-14'!F10+E10 -> 103 | H10: POLI | I10: 18
A11: TCHATIBALI | B11: =I6 -> 0 | C11: ='26-04-14'!C11+B11 -> 22 | D11: MAYO-GALKE | E11: =I11 -> 27 | F11: ='26-04-14'!F11+E11 -> 87 | H11: MAYO-GALKE | I11: 27
A12: GUIDER | B12: =I7 -> 0 | C12: ='26-04-14'!C12+B12 -> 53 | D12: TOUBOURO | E12: =I12 -> 13 | F12: ='26-04-14'!F12+E12 -> 23 | H12: TOUBOURO | I12: 13
A13: GAROUA | B13: =I8 -> 10 | C13: ='26-04-14'!C13+B13 -> 70 | D13: HOME | E13: =I13 -> 7 | F13: ='26-04-14'!F13+E13 -> 68 | H13: HOME | I13: 7
A15: TOTAL JOURNALIER = | C15: =SUM(B9:B13)+SUM(E9:E13) -> 125 | D15: CUMUL GENERAL = | F15: =SUM(C9:C13)+SUM(F9:F13) -> 510 | H15: JOURNEE | I15: 41756
H16: TRANSMISSION | I16: =I15+1 -> 41757
A20: Transmis le : | B20: =I16 -> 41757

Sheet 28-04-14
A1: SODECOTON
H2: TABLEAU DE SAISI
A3: PLUVIOMETRIE JOURNALIERE ET PAR PENTADE | H3: STATION | I3: RELEVES
H4: MAROUA | I4: 0
B5: JOURNEE DU : | D5: =I15 -> 41757 | H5: KAELE | I5: 0
H6: TCHATIBALI | I6: 0
A7: STATION | B7: RELEVES | D7: STATION | E7: RELEVES | H7: GUIDER | I7: 0
B8: JOURNALIER | C8: CUMUL | E8: JOURNALIER | F8: CUMUL | H8: GAROUA | I8: 0
A9: MAROUA | B9: =I4 -> 0 | C9: ='27-04-14'!C9+B9 -> 14 | D9: NGONG | E9: =I9 -> 0 | F9: ='27-04-14'!F9+E9 -> 60 | H9: NGONG | I9: 0
A10: KAELE | B10: =I5 -> 0 | C10: ='27-04-14'!C10+B10 -> 10 | D10: POLI | E10: =I10 -> 2 | F10: ='27-04-14'!F10+E10 -> 105 | H10: POLI | I10: 2
A11: TCHATIBALI | B11: =I6 -> 0 | C11: ='27-04-14'!C11+B11 -> 22 | D11: MAYO-GALKE | E11: =I11 -> 29 | F11: ='27-04-14'!F11+E11 -> 116 | H11: MAYO-GALKE | I11: 29
A12: GUIDER | B12: =I7 -> 0 | C12: ='27-04-14'!C12+B12 -> 53 | D12: TOUBOURO | E12: =I12 -> 11 | F12: ='27-04-14'!F12+E12 -> 34 | H12: TOUBOURO | I12: 11
A13: GAROUA | B13: =I8 -> 0 | C13: ='27-04-14'!C13+B13 -> 70 | D13: HOME | E13: =I13 -> 4 | F13: ='27-04-14'!F13+E13 -> 72 | H13: HOME | I13: 4
A15: TOTAL JOURNALIER = | C15: =SUM(B9:B13)+SUM(E9:E13) -> 46 | D15: CUMUL GENERAL = | F15: =SUM(C9:C13)+SUM(F9:F13) -> 556 | H15: JOURNEE | I15: 41757
H16: TRANSMISSION | I16: =I15+1 -> 41758
A20: Transmis le : | B20: =I16 -> 41758

Sheet 29-04-14
A1: SODECOTON
H2: TABLEAU DE SAISI
A3: PLUVIOMETRIE JOURNALIERE ET PAR PENTADE | H3: STATION | I3: RELEVES
H4: MAROUA | I4: 0
B5: JOURNEE DU : | D5: =I15 -> 41758 | H5: KAELE | I5: 0
H6: TCHATIBALI | I6: 0
A7: STATION | B7: RELEVES | D7: STATION | E7: RELEVES | H7: GUIDER | I7: 0
B8: JOURNALIER | C8: CUMUL | E8: JOURNALIER | F8: CUMUL | H8: GAROUA | I8: 0
A9: MAROUA | B9: =I4 -> 0 | C9: ='28-04-14'!C9+B9 -> 14 | D9: NGONG | E9: =I9 -> 0 | F9: ='28-04-14'!F9+E9 -> 60 | H9: NGONG | I9: 0
A10: KAELE | B10: =I5 -> 0 | C10: ='28-04-14'!C10+B10 -> 10 | D10: POLI | E10: =I10 -> 0 | F10: ='28-04-14'!F10+E10 -> 105 | H10: POLI | I10: 0
A11: TCHATIBALI | B11: =I6 -> 0 | C11: ='28-04-14'!C11+B11 -> 22 | D11: MAYO-GALKE | E11: =I11 -> 0 | F11: ='28-04-14'!F11+E11 -> 116 | H11: MAYO-GALKE | I11: 0
A12: GUIDER | B12: =I7 -> 0 | C12: ='28-04-14'!C12+B12 -> 53 | D12: TOUBOURO | E12: =I12 -> 0 | F12: ='28-04-14'!F12+E12 -> 34 | H12: TOUBOURO | I12: 0
A13: GAROUA | B13: =I8 -> 0 | C13: ='28-04-14'!C13+B13 -> 70 | D13: HOME | E13: =I13 -> 0 | F13: ='28-04-14'!F13+E13 -> 72 | H13: HOME | I13: 0
A15: TOTAL JOURNALIER = | C15: =SUM(B9:B13)+SUM(E9:E13) -> 0 | D15: CUMUL GENERAL = | F15: =SUM(C9:C13)+SUM(F9:F13) -> 556 | H15: JOURNEE | I15: 41758
H16: TRANSMISSION | I16: =I15+1 -> 41759
A20: Transmis le : | B20: =I16 -> 41759

Sheet 30-04-14
A1: SODECOTON
H2: TABLEAU DE SAISI
A3: PLUVIOMETRIE JOURNALIERE ET PAR PENTADE | H3: STATION | I3: RELEVES
H4: MAROUA | I4: 0
B5: JOURNEE DU : | D5: =I15 -> 41759 | H5: KAELE | I5: 0
H6: TCHATIBALI | I6: 20
A7: STATION | B7: RELEVES | D7: STATION | E7: RELEVES | H7: GUIDER | I7: 2
B8: JOURNALIER | C8: CUMUL | E8: JOURNALIER | F8: CUMUL | H8: GAROUA | I8: 0
A9: MAROUA | B9: =I4 -> 0 | C9: ='29-04-14'!C9+B9 -> 14 | D9: NGONG | E9: =I9 -> 0 | F9: ='29-04-14'!F9+E9 -> 60 | H9: NGONG | I9: 0
A10: KAELE | B10: =I5 -> 0 | C10: ='29-04-14'!C10+B10 -> 10 | D10: POLI | E10: =I10 -> 0 | F10: ='29-04-14'!F10+E10 -> 105 | H10: POLI | I10: 0
A11: TCHATIBALI | B11: =I6 -> 20 | C11: ='29-04-14'!C11+B11 -> 42 | D11: MAYO-GALKE | E11: =I11 -> 0 | F11: ='29-04-14'!F11+E11 -> 116 | H11: MAYO-GALKE | I11: 0
A12: GUIDER | B12: =I7 -> 2 | C12: ='29-04-14'!C12+B12 -> 55 | D12: TOUBOURO | E12: =I12 -> 0 | F12: ='29-04-14'!F12+E12 -> 34 | H12: TOUBOURO | I12: 0
A13: GAROUA | B13: =I8 -> 0 | C13: ='29-04-14'!C13+B13 -> 70 | D13: HOME | E13: =I13 -> 1 | F13: ='29-04-14'!F13+E13 -> 73 | H13: HOME | I13: 1
A15: TOTAL JOURNALIER = | C15: =SUM(B9:B13)+SUM(E9:E13) -> 23 | D15: CUMUL GENERAL = | F15: =SUM(C9:C13)+SUM(F9:F13) -> 579 | H15: JOURNEE | I15: 41759
H16: TRANSMISSION | I16: =I15+1 -> 41760
A20: Transmis le : | B20: =I16 -> 41760

Sheet 01-05-14
A1: SODECOTON
H2: TABLEAU DE SAISI
A3: PLUVIOMETRIE JOURNALIERE ET PAR PENTADE | H3: STATION | I3: RELEVES
H4: MAROUA | I4: 0
B5: JOURNEE DU : | D5: =I15 -> 41760 | H5: KAELE | I5: 0
H6: TCHATIBALI | I6: 0
A7: STATION | B7: RELEVES | D7: STATION | E7: RELEVES | H7: GUIDER | I7: 0
B8: JOURNALIER | C8: CUMUL | E8: JOURNALIER | F8: CUMUL | H8: GAROUA | I8: 0
A9: MAROUA | B9: =I4 -> 0 | C9: ='30-04-14'!C9+B9 -> 14 | D9: NGONG | E9: =I9 -> 0 | F9: ='30-04-14'!F9+E9 -> 60 | H9: NGONG | I9: 0
A10: KAELE | B10: =I5 -> 0 | C10: ='30-04-14'!C10+B10 -> 10 | D10: POLI | E10: =I10 -> 0 | F10: ='30-04-14'!F10+E10 -> 105 | H10: POLI | I10: 0
A11: TCHATIBALI | B11: =I6 -> 0 | C11: ='30-04-14'!C11+B11 -> 42 | D11: MAYO-GALKE | E11: =I11 -> 0 | F11: ='30-04-14'!F11+E11 -> 116 | H11: MAYO-GALKE | I11: 0
A12: GUIDER | B12: =I7 -> 0 | C12: ='30-04-14'!C12+B12 -> 55 | D12: TOUBOURO | E12: =I12 -> 0 | F12: ='30-04-14'!F12+E12 -> 34 | H12: TOUBOURO | I12: 0
A13: GAROUA | B13: =I8 -> 0 | C13: ='30-04-14'!C13+B13 -> 70 | D13: HOME | E13: =I13 -> 0 | F13: ='30-04-14'!F13+E13 -> 73 | H13: HOME | I13: 0
A15: TOTAL JOURNALIER = | C15: =SUM(B9:B13)+SUM(E9:E13) -> 0 | D15: CUMUL GENERAL = | F15: =SUM(C9:C13)+SUM(F9:F13) -> 579 | H15: JOURNEE | I15: 41760
H16: TRANSMISSION | I16: =I15+1 -> 41761
A20: Transmis le : | B20: =I16 -> 41761

Sheet 02-05-14
A1: SODECOTON
H2: TABLEAU DE SAISI
A3: PLUVIOMETRIE JOURNALIERE ET PAR PENTADE | H3: STATION | I3: RELEVES
H4: MAROUA | I4: 0
B5: JOURNEE DU : | D5: =I15 -> 41761 | H5: KAELE | I5: 0
H6: TCHATIBALI | I6: 0
A7: STATION | B7: RELEVES | D7: STATION | E7: RELEVES | H7: GUIDER | I7: 0
B8: JOURNALIER | C8: CUMUL | E8: JOURNALIER | F8: CUMUL | H8: GAROUA | I8: 0
A9: MAROUA | B9: =I4 -> 0 | C9: ='01-05-14'!C9+B9 -> 14 | D9: NGONG | E9: =I9 -> 0 | F9: ='01-05-14'!F9+E9 -> 60 | H9: NGONG | I9: 0
A10: KAELE | B10: =I5 -> 0 | C10: ='01-05-14'!C10+B10 -> 10 | D10: POLI | E10: =I10 -> 0 | F10: ='01-05-14'!F10+E10 -> 105 | H10: POLI | I10: 0
A11: TCHATIBALI | B11: =I6 -> 0 | C11: ='01-05-14'!C11+B11 -> 42 | D11: MAYO-GALKE | E11: =I11 -> 0 | F11: ='01-05-14'!F11+E11 -> 116 | H11: MAYO-GALKE | I11: 0
A12: GUIDER | B12: =I7 -> 0 | C12: ='01-05-14'!C12+B12 -> 55 | D12: TOUBOURO | E12: =I12 -> 0 | F12: ='01-05-14'!F12+E12 -> 34 | H12: TOUBOURO | I12: 0
A13: GAROUA | B13: =I8 -> 0 | C13: ='01-05-14'!C13+B13 -> 70 | D13: HOME | E13: =I13 -> 0 | F13: ='01-05-14'!F13+E13 -> 73 | H13: HOME | I13: 0
A15: TOTAL JOURNALIER = | C15: =SUM(B9:B13)+SUM(E9:E13) -> 0 | D15: CUMUL GENERAL = | F15: =SUM(C9:C13)+SUM(F9:F13) -> 579 | H15: JOURNEE | I15: 41761
H16: TRANSMISSION | I16: =I15+1 -> 41762
A20: Transmis le : | B20: =I16 -> 41762

Sheet 03-05-14
A1: SODECOTON
H2: TABLEAU DE SAISI
A3: PLUVIOMETRIE JOURNALIERE ET PAR PENTADE | H3: STATION | I3: RELEVES
H4: MAROUA | I4: 0
B5: JOURNEE DU : | D5: =I15 -> 41762 | H5: KAELE | I5: 0
H6: TCHATIBALI | I6: 0
A7: STATION | B7: RELEVES | D7: STATION | E7: RELEVES | H7: GUIDER | I7: 0
B8: JOURNALIER | C8: CUMUL | E8: JOURNALIER | F8: CUMUL | H8: GAROUA | I8: 0
A9: MAROUA | B9: =I4 -> 0 | C9: ='02-05-14'!C9+B9 -> 14 | D9: NGONG | E9: =I9 -> 0 | F9: ='02-05-14'!F9+E9 -> 60 | H9: NGONG | I9: 0
A10: KAELE | B10: =I5 -> 0 | C10: ='02-05-14'!C10+B10 -> 10 | D10: POLI | E10: =I10 -> 0 | F10: ='02-05-14'!F10+E10 -> 105 | H10: POLI | I10: 0
A11: TCHATIBALI | B11: =I6 -> 0 | C11: ='02-05-14'!C11+B11 -> 42 | D11: MAYO-GALKE | E11: =I11 -> 0 | F11: ='02-05-14'!F11+E11 -> 116 | H11: MAYO-GALKE | I11: 0
A12: GUIDER | B12: =I7 -> 0 | C12: ='02-05-14'!C12+B12 -> 55 | D12: TOUBOURO | E12: =I12 -> 0 | F12: ='02-05-14'!F12+E12 -> 34 | H12: TOUBOURO | I12: 0
A13: GAROUA | B13: =I8 -> 0 | C13: ='02-05-14'!C13+B13 -> 70 | D13: HOME | E13: =I13 -> 0 | F13: ='02-05-14'!F13+E13 -> 73 | H13: HOME | I13: 0
A15: TOTAL JOURNALIER = | C15: =SUM(B9:B13)+SUM(E9:E13) -> 0 | D15: CUMUL GENERAL = | F15: =SUM(C9:C13)+SUM(F9:F13) -> 579 | H15: JOURNEE | I15: 41762
H16: TRANSMISSION | I16: =I15+1 -> 41763
A20: Transmis le : | B20: =I16 -> 41763

Sheet 04-05-14
A1: SODECOTON
H2: TABLEAU DE SAISI
A3: PLUVIOMETRIE JOURNALIERE ET PAR PENTADE | H3: STATION | I3: RELEVES
H4: MAROUA | I4: 0
B5: JOURNEE DU : | D5: =I15 -> 41763 | H5: KAELE | I5: 0
H6: TCHATIBALI | I6: 0
A7: STATION | B7: RELEVES | D7: STATION | E7: RELEVES | H7: GUIDER | I7: 0
B8: JOURNALIER | C8: CUMUL | E8: JOURNALIER | F8: CUMUL | H8: GAROUA | I8: 0
A9: MAROUA | B9: =I4 -> 0 | C9: ='03-05-14'!C9+B9 -> 14 | D9: NGONG | E9: =I9 -> 0 | F9: ='03-05-14'!F9+E9 -> 60 | H9: NGONG | I9: 0
A10: KAELE | B10: =I5 -> 0 | C10: ='03-05-14'!C10+B10 -> 10 | D10: POLI | E10: =I10 -> 0 | F10: ='03-05-14'!F10+E10 -> 105 | H10: POLI | I10: 0
A11: TCHATIBALI | B11: =I6 -> 0 | C11: ='03-05-14'!C11+B11 -> 42 | D11: MAYO-GALKE | E11: =I11 -> 0 | F11: ='03-05-14'!F11+E11 -> 116 | H11: MAYO-GALKE | I11: 0
A12: GUIDER | B12: =I7 -> 0 | C12: ='03-05-14'!C12+B12 -> 55 | D12: TOUBOURO | E12: =I12 -> 0 | F12: ='03-05-14'!F12+E12 -> 34 | H12: TOUBOURO | I12: 0
A13: GAROUA | B13: =I8 -> 0 | C13: ='03-05-14'!C13+B13 -> 70 | D13: HOME | E13: =I13 -> 0 | F13: ='03-05-14'!F13+E13 -> 73 | H13: HOME | I13: 0
A15: TOTAL JOURNALIER = | C15: =SUM(B9:B13)+SUM(E9:E13) -> 0 | D15: CUMUL GENERAL = | F15: =SUM(C9:C13)+SUM(F9:F13) -> 579 | H15: JOURNEE | I15: 41763
H16: TRANSMISSION | I16: =I15+1 -> 41764
A20: Transmis le : | B20: =I16 -> 41764

Sheet 05-05-14
A1: SODECOTON
H2: TABLEAU DE SAISI
A3: PLUVIOMETRIE JOURNALIERE ET PAR PENTADE | H3: STATION | I3: RELEVES
H4: MAROUA | I4: 0
B5: JOURNEE DU : | D5: =I15 -> 41764 | H5: KAELE | I5: 0
H6: TCHATIBALI | I6: 0
A7: STATION | B7: RELEVES | D7: STATION | E7: RELEVES | H7: GUIDER | I7: 0
B8: JOURNALIER | C8: CUMUL | E8: JOURNALIER | F8: CUMUL | H8: GAROUA | I8: 0
A9: MAROUA | B9: =I4 -> 0 | C9: ='04-05-14'!C9+B9 -> 14 | D9: NGONG | E9: =I9 -> 0 | F9: ='04-05-14'!F9+E9 -> 60 | H9: NGONG | I9: 0
A10: KAELE | B10: =I5 -> 0 | C10: ='04-05-14'!C10+B10 -> 10 | D10: POLI | E10: =I10 -> 0 | F10: ='04-05-14'!F10+E10 -> 105 | H10: POLI | I10: 0
A11: TCHATIBALI | B11: =I6 -> 0 | C11: ='04-05-14'!C11+B11 -> 42 | D11: MAYO-GALKE | E11: =I11 -> 0 | F11: ='04-05-14'!F11+E11 -> 116 | H11: MAYO-GALKE | I11: 0
A12: GUIDER | B12: =I7 -> 0 | C12: ='04-05-14'!C12+B12 -> 55 | D12: TOUBOURO | E12: =I12 -> 0 | F12: ='04-05-14'!F12+E12 -> 34 | H12: TOUBOURO | I12: 0
A13: GAROUA | B13: =I8 -> 0 | C13: ='04-05-14'!C13+B13 -> 70 | D13: HOME | E13: =I13 -> 0 | F13: ='04-05-14'!F13+E13 -> 73 | H13: HOME | I13: 0
A15: TOTAL JOURNALIER = | C15: =SUM(B9:B13)+SUM(E9:E13) -> 0 | D15: CUMUL GENERAL = | F15: =SUM(C9:C13)+SUM(F9:F13) -> 579 | H15: JOURNEE | I15: 41764
H16: TRANSMISSION | I16: =I15+1 -> 41765
A20: Transmis le : | B20: =I16 -> 41765

Sheet 06-05-14
A1: SODECOTON
H2: TABLEAU DE SAISI
A3: PLUVIOMETRIE JOURNALIERE ET PAR PENTADE | H3: STATION | I3: RELEVES
H4: MAROUA | I4: 0
B5: JOURNEE DU : | D5: =I15 -> 41765 | H5: KAELE | I5: 0
H6: TCHATIBALI | I6: 0
A7: STATION | B7: RELEVES | D7: STATION | E7: RELEVES | H7: GUIDER | I7: 0
B8: JOURNALIER | C8: CUMUL | E8: JOURNALIER | F8: CUMUL | H8: GAROUA | I8: 0
A9: MAROUA | B9: =I4 -> 0 | C9: ='05-05-14'!C9+B9 -> 14 | D9: NGONG | E9: =I9 -> 0 | F9: ='05-05-14'!F9+E9 -> 60 | H9: NGONG | I9: 0
A10: KAELE | B10: =I5 -> 0 | C10: ='05-05-14'!C10+B10 -> 10 | D10: POLI | E10: =I10 -> 0 | F10: ='05-05-14'!F10+E10 -> 105 | H10: POLI | I10: 0
A11: TCHATIBALI | B11: =I6 -> 0 | C11: ='05-05-14'!C11+B11 -> 42 | D11: MAYO-GALKE | E11: =I11 -> 0 | F11: ='05-05-14'!F11+E11 -> 116 | H11: MAYO-GALKE | I11: 0
A12: GUIDER | B12: =I7 -> 0 | C12: ='05-05-14'!C12+B12 -> 55 | D12: TOUBOURO | E12: =I12 -> 0 | F12: ='05-05-14'!F12+E12 -> 34 | H12: TOUBOURO | I12: 0
A13: GAROUA | B13: =I8 -> 0 | C13: ='05-05-14'!C13+B13 -> 70 | D13: HOME | E13: =I13 -> 0 | F13: ='05-05-14'!F13+E13 -> 73 | H13: HOME | I13: 0
A15: TOTAL JOURNALIER = | C15: =SUM(B9:B13)+SUM(E9:E13) -> 0 | D15: CUMUL GENERAL = | F15: =SUM(C9:C13)+SUM(F9:F13) -> 579 | H15: JOURNEE | I15: 41765
H16: TRANSMISSION | I16: =I15+1 -> 41766
A20: Transmis le : | B20: =I16 -> 41766

Sheet 07-05-14
A1: SODECOTON
H2: TABLEAU DE SAISI
A3: PLUVIOMETRIE JOURNALIERE ET PAR PENTADE | H3: STATION | I3: RELEVES
H4: MAROUA | I4: 0
B5: JOURNEE DU : | D5: =I15 -> 41766 | H5: KAELE | I5: 0
H6: TCHATIBALI | I6: 0
A7: STATION | B7: RELEVES | D7: STATION | E7: RELEVES | H7: GUIDER | I7: 0
B8: JOURNALIER | C8: CUMUL | E8: JOURNALIER | F8: CUMUL | H8: GAROUA | I8: 0
A9: MAROUA | B9: =I4 -> 0 | C9: ='06-05-14'!C9+B9 -> 14 | D9: NGONG | E9: =I9 -> 0 | F9: ='06-05-14'!F9+E9 -> 60 | H9: NGONG | I9: 0
A10: KAELE | B10: =I5 -> 0 | C10: ='06-05-14'!C10+B10 -> 10 | D10: POLI | E10: =I10 -> 0 | F10: ='06-05-14'!F10+E10 -> 105 | H10: POLI | I10: 0
A11: TCHATIBALI | B11: =I6 -> 0 | C11: ='06-05-14'!C11+B11 -> 42 | D11: MAYO-GALKE | E11: =I11 -> 0 | F11: ='06-05-14'!F11+E11 -> 116 | H11: MAYO-GALKE | I11: 0
A12: GUIDER | B12: =I7 -> 0 | C12: ='06-05-14'!C12+B12 -> 55 | D12: TOUBOURO | E12: =I12 -> 0 | F12: ='06-05-14'!F12+E12 -> 34 | H12: TOUBOURO | I12: 0
A13: GAROUA | B13: =I8 -> 0 | C13: ='06-05-14'!C13+B13 -> 70 | D13: HOME | E13: =I13 -> 0 | F13: ='06-05-14'!F13+E13 -> 73 | H13: HOME | I13: 0
A15: TOTAL JOURNALIER = | C15: =SUM(B9:B13)+SUM(E9:E13) -> 0 | D15: CUMUL GENERAL = | F15: =SUM(C9:C13)+SUM(F9:F13) -> 579 | H15: JOURNEE | I15: 41766
H16: TRANSMISSION | I16: =I15+1 -> 41767
A20: Transmis le : | B20: =I16 -> 41767

Sheet 08-05-14
A1: SODECOTON
H2: TABLEAU DE SAISI
A3: PLUVIOMETRIE JOURNALIERE ET PAR PENTADE | H3: STATION | I3: RELEVES
H4: MAROUA | I4: 0
B5: JOURNEE DU : | D5: =I15 -> 41767 | H5: KAELE | I5: 0
H6: TCHATIBALI | I6: 0
A7: STATION | B7: RELEVES | D7: STATION | E7: RELEVES | H7: GUIDER | I7: 0
B8: JOURNALIER | C8: CUMUL | E8: JOURNALIER | F8: CUMUL | H8: GAROUA | I8: 0
A9: MAROUA | B9: =I4 -> 0 | C9: ='07-05-14'!C9+B9 -> 14 | D9: NGONG | E9: =I9 -> 0 | F9: ='07-05-14'!F9+E9 -> 60 | H9: NGONG | I9: 0
A10: KAELE | B10: =I5 -> 0 | C10: ='07-05-14'!C10+B10 -> 10 | D10: POLI | E10: =I10 -> 0 | F10: ='07-05-14'!F10+E10 -> 105 | H10: POLI | I10: 0
A11: TCHATIBALI | B11: =I6 -> 0 | C11: ='07-05-14'!C11+B11 -> 42 | D11: MAYO-GALKE | E11: =I11 -> 0 | F11: ='07-05-14'!F11+E11 -> 116 | H11: MAYO-GALKE | I11: 0
A12: GUIDER | B12: =I7 -> 0 | C12: ='07-05-14'!C12+B12 -> 55 | D12: TOUBOURO | E12: =I12 -> 0 | F12: ='07-05-14'!F12+E12 -> 34 | H12: TOUBOURO | I12: 0
A13: GAROUA | B13: =I8 -> 0 | C13: ='07-05-14'!C13+B13 -> 70 | D13: HOME | E13: =I13 -> 0 | F13: ='07-05-14'!F13+E13 -> 73 | H13: HOME | I13: 0
A15: TOTAL JOURNALIER = | C15: =SUM(B9:B13)+SUM(E9:E13) -> 0 | D15: CUMUL GENERAL = | F15: =SUM(C9:C13)+SUM(F9:F13) -> 579 | H15: JOURNEE | I15: 41767
H16: TRANSMISSION | I16: =I15+1 -> 41768
A20: Transmis le : | B20: =I16 -> 41768

Sheet 09-05-14
A1: SODECOTON
H2: TABLEAU DE SAISI
A3: PLUVIOMETRIE JOURNALIERE ET PAR PENTADE | H3: STATION | I3: RELEVES
H4: MAROUA | I4: 0
B5: JOURNEE DU : | D5: =I15 -> 41768 | H5: KAELE | I5: 0
H6: TCHATIBALI | I6: 0
A7: STATION | B7: RELEVES | D7: STATION | E7: RELEVES | H7: GUIDER | I7: 0
B8: JOURNALIER | C8: CUMUL | E8: JOURNALIER | F8: CUMUL | H8: GAROUA | I8: 0
A9: MAROUA | B9: =I4 -> 0 | C9: ='08-05-14'!C9+B9 -> 14 | D9: NGONG | E9: =I9 -> 0 | F9: ='08-05-14'!F9+E9 -> 60 | H9: NGONG | I9: 0
A10: KAELE | B10: =I5 -> 0 | C10: ='08-05-14'!C10+B10 -> 10 | D10: POLI | E10: =I10 -> 0 | F10: ='08-05-14'!F10+E10 -> 105 | H10: POLI | I10: 0
A11: TCHATIBALI | B11: =I6 -> 0 | C11: ='08-05-14'!C11+B11 -> 42 | D11: MAYO-GALKE | E11: =I11 -> 0 | F11: ='08-05-14'!F11+E11 -> 116 | H11: MAYO-GALKE | I11: 0
A12: GUIDER | B12: =I7 -> 0 | C12: ='08-05-14'!C12+B12 -> 55 | D12: TOUBOURO | E12: =I12 -> 0 | F12: ='08-05-14'!F12+E12 -> 34 | H12: TOUBOURO | I12: 0
A13: GAROUA | B13: =I8 -> 0 | C13: ='08-05-14'!C13+B13 -> 70 | D13: HOME | E13: =I13 -> 0 | F13: ='08-05-14'!F13+E13 -> 73 | H13: HOME | I13: 0
A15: TOTAL JOURNALIER = | C15: =SUM(B9:B13)+SUM(E9:E13) -> 0 | D15: CUMUL GENERAL = | F15: =SUM(C9:C13)+SUM(F9:F13) -> 579 | H15: JOURNEE | I15: 41768
H16: TRANSMISSION | I16: =I15+1 -> 41769
